2022-12-30 13:45:50,585 - [INFO]    django.utils.autoreload: Watching for file changes with StatReloader
2022-12-30 13:51:03,418 - [INFO]    django.channels.server: [mHTTP GET /bankgateways/sample-payment/ 200 [1.76, 172.20.0.1:39598][0m
2022-12-30 13:51:16,689 - [ERROR]    django.request: Internal Server Error: /bankgateways/sample-payment/
Traceback (most recent call last):
  File "/usr/local/lib/python3.10/site-packages/asgiref/sync.py", line 472, in thread_handler
    raise exc_info[1]
  File "/usr/local/lib/python3.10/site-packages/django/core/handlers/exception.py", line 42, in inner
    response = await get_response(request)
  File "/usr/local/lib/python3.10/site-packages/django/core/handlers/base.py", line 253, in _get_response_async
    response = await wrapped_callback(
  File "/usr/local/lib/python3.10/site-packages/asgiref/sync.py", line 435, in __call__
    ret = await asyncio.wait_for(future, timeout=None)
  File "/usr/local/lib/python3.10/asyncio/tasks.py", line 408, in wait_for
    return await fut
  File "/usr/local/lib/python3.10/site-packages/asgiref/current_thread_executor.py", line 22, in run
    result = self.fn(*self.args, **self.kwargs)
  File "/usr/local/lib/python3.10/site-packages/asgiref/sync.py", line 476, in thread_handler
    return func(*args, **kwargs)
  File "/usr/local/lib/python3.10/site-packages/azbankgateways/views/samples.py", line 45, in sample_payment_view
    raise e
  File "/usr/local/lib/python3.10/site-packages/azbankgateways/views/samples.py", line 27, in sample_payment_view
    bank = factory.auto_create()
  File "/usr/local/lib/python3.10/site-packages/azbankgateways/bankfactories.py", line 67, in auto_create
    raise BankGatewayAutoConnectionFailed()
azbankgateways.exceptions.exceptions.BankGatewayAutoConnectionFailed
2022-12-30 13:51:16,962 - [ERROR]    django.channels.server: [35;1mHTTP POST /bankgateways/sample-payment/ 500 [0.50, 172.20.0.1:36148][0m
2022-12-30 14:01:31,576 - [INFO]    django.utils.autoreload: /usr/src/app/conf/settings.py changed, reloading.
2022-12-30 14:01:46,439 - [INFO]    django.utils.autoreload: Watching for file changes with StatReloader
2022-12-30 14:03:00,920 - [INFO]    django.channels.server: [32mHTTP POST /bankgateways/sample-payment/ 302 [2.90, 172.20.0.1:39326][0m
2022-12-30 14:03:09,257 - [INFO]    django.channels.server: [mHTTP GET /bankgateways/sample-payment/ 200 [0.62, 172.20.0.1:55902][0m
2022-12-30 14:03:21,421 - [INFO]    django.channels.server: [32mHTTP POST /bankgateways/sample-payment/ 302 [7.45, 172.20.0.1:55910][0m
2022-12-30 14:11:33,932 - [INFO]    django.channels.server: [mHTTP GET /bankgateways/go-to-bank-gateway/ 200 [0.25, 172.20.0.1:37960][0m
2022-12-30 14:11:35,951 - [INFO]    django.channels.server: [mHTTP GET /bankgateways/go-to-bank-gateway/?csrfmiddlewaretoken=eaIrN2su0XaWKWrGGbpIuHWXOrBgO0bw9bHAnZ0yhQ5KxDd7aUjrPy3gWYNh06WZ 200 [0.31, 172.20.0.1:37972][0m
2022-12-30 14:11:39,203 - [INFO]    django.channels.server: [mHTTP GET /bankgateways/go-to-bank-gateway/?csrfmiddlewaretoken=Z8of4A5sXFuRmYpvRtESX21lCDCctXVlU9noExDweypF9FbWlcyBiT8EKaOdF3GO&csrfmiddlewaretoken=eaIrN2su0XaWKWrGGbpIuHWXOrBgO0bw9bHAnZ0yhQ5KxDd7aUjrPy3gWYNh06WZ 200 [0.27, 172.20.0.1:33568][0m
2022-12-30 14:11:40,776 - [INFO]    django.channels.server: [mHTTP GET /bankgateways/go-to-bank-gateway/?csrfmiddlewaretoken=RElDPdfpsTSiIempKNH3cJspAneEw82uMFkMpaNtJMN6vV8QewBMxAzIIUqFIeNX&csrfmiddlewaretoken=eaIrN2su0XaWKWrGGbpIuHWXOrBgO0bw9bHAnZ0yhQ5KxDd7aUjrPy3gWYNh06WZ 200 [0.24, 172.20.0.1:33572][0m
2022-12-30 14:11:46,368 - [INFO]    django.channels.server: [mHTTP GET /bankgateways/sample-payment/ 200 [0.39, 172.20.0.1:33574][0m
2022-12-30 14:11:53,095 - [INFO]    django.channels.server: [32mHTTP POST /bankgateways/sample-payment/ 302 [2.80, 172.20.0.1:33770][0m
2022-12-30 14:33:40,750 - [WARNING]    django.request: Not Found: /google.com
2022-12-30 14:34:09,179 - [WARNING]    django.request: Not Found: /in_placedashboard
2022-12-30 14:36:35,756 - [INFO]    django.channels.server: [mHTTP GET /bankgateways/sample-payment/ 200 [4.48, 172.20.0.1:46178][0m
2022-12-30 14:36:41,955 - [INFO]    django.channels.server: [mHTTP GET /bankgateways/sample-payment/ 200 [0.21, 172.20.0.1:46770][0m
2022-12-30 14:36:42,933 - [INFO]    django.channels.server: [mHTTP GET /static/debug_toolbar/css/toolbar.css 200 [0.74, 172.20.0.1:46770][0m
2022-12-30 14:36:42,966 - [INFO]    django.channels.server: [mHTTP GET /static/debug_toolbar/js/toolbar.js 200 [0.77, 172.20.0.1:46782][0m
2022-12-30 14:36:42,990 - [INFO]    django.channels.server: [mHTTP GET /static/debug_toolbar/js/toolbar.js 200 [0.00, 172.20.0.1:46792][0m
2022-12-30 14:36:43,204 - [INFO]    django.channels.server: [mHTTP GET /static/debug_toolbar/js/utils.js 200 [0.04, 172.20.0.1:46770][0m
2022-12-30 14:36:43,235 - [INFO]    django.channels.server: [mHTTP GET /static/debug_toolbar/js/utils.js 200 [0.01, 172.20.0.1:46792][0m
2022-12-30 14:36:43,523 - [WARNING]    django.request: Not Found: /sw.js
2022-12-30 14:36:43,527 - [WARNING]    django.channels.server: [33mHTTP GET /sw.js 404 [0.36, 172.20.0.1:46782][0m
2022-12-30 14:36:44,443 - [WARNING]    django.request: Not Found: /sw.js
2022-12-30 14:36:44,446 - [WARNING]    django.channels.server: [33mHTTP GET /sw.js 404 [0.31, 172.20.0.1:46770][0m
2022-12-30 14:36:44,774 - [INFO]    django.channels.server: [mHTTP GET /static/debug_toolbar/css/print.css 200 [0.06, 172.20.0.1:46808][0m
2022-12-30 14:36:46,781 - [WARNING]    django.request: Not Found: /sw.js
2022-12-30 14:36:46,788 - [WARNING]    django.channels.server: [33mHTTP GET /sw.js 404 [0.31, 172.20.0.1:46808][0m
2022-12-30 14:36:47,349 - [INFO]    django.channels.server: [32mHTTP POST /bankgateways/sample-payment/ 302 [2.66, 172.20.0.1:46806][0m
2022-12-30 14:36:47,925 - [INFO]    django.channels.server: [mHTTP GET /bankgateways/go-to-bank-gateway/?url=https%3A%2F%2Fidpay.ir%2Fp%2Fws-sandbox%2F2aa63ba59af7a068714e1529cb04e5b2&method=GET 200 [0.53, 172.20.0.1:46806][0m
2022-12-30 14:36:48,579 - [WARNING]    django.request: Not Found: /favicon.ico
2022-12-30 14:36:48,584 - [WARNING]    django.channels.server: [33mHTTP GET /favicon.ico 404 [0.30, 172.20.0.1:46806][0m
2022-12-30 14:36:48,863 - [WARNING]    django.request: Not Found: /sw.js
2022-12-30 14:36:48,981 - [WARNING]    django.channels.server: [33mHTTP GET /sw.js 404 [0.50, 172.20.0.1:44562][0m
2022-12-30 15:12:17,850 - [INFO]    django.utils.autoreload: /usr/src/app/conf/settings.py changed, reloading.
2022-12-30 15:12:43,308 - [INFO]    django.utils.autoreload: Watching for file changes with StatReloader
2022-12-30 15:13:09,804 - [WARNING]    django.request: Not Found: /sw.js
2022-12-30 15:13:09,810 - [WARNING]    django.channels.server: [33mHTTP GET /sw.js 404 [0.43, 172.20.0.1:40738][0m
2022-12-30 15:13:10,688 - [INFO]    django.channels.server: [mHTTP GET /bankgateways/sample-payment/ 200 [2.78, 172.20.0.1:59702][0m
2022-12-30 15:13:10,998 - [INFO]    django.channels.server: [mHTTP GET /static/debug_toolbar/css/toolbar.css 200 [0.02, 172.20.0.1:59702][0m
2022-12-30 15:13:11,008 - [INFO]    django.channels.server: [mHTTP GET /static/debug_toolbar/js/toolbar.js 200 [0.03, 172.20.0.1:40744][0m
2022-12-30 15:13:11,107 - [INFO]    django.channels.server: [mHTTP GET /static/debug_toolbar/js/toolbar.js 200 [0.01, 172.20.0.1:40756][0m
2022-12-30 15:13:11,278 - [INFO]    django.channels.server: [mHTTP GET /static/debug_toolbar/js/utils.js 200 [0.00, 172.20.0.1:40744][0m
2022-12-30 15:13:11,296 - [INFO]    django.channels.server: [mHTTP GET /static/debug_toolbar/js/utils.js 200 [0.00, 172.20.0.1:40756][0m
2022-12-30 15:13:13,812 - [INFO]    django.channels.server: [mHTTP GET /static/debug_toolbar/css/print.css 200 [0.01, 172.20.0.1:59702][0m
2022-12-30 15:13:14,119 - [WARNING]    django.request: Not Found: /sw.js
2022-12-30 15:13:14,124 - [WARNING]    django.channels.server: [33mHTTP GET /sw.js 404 [0.42, 172.20.0.1:40744][0m
2022-12-30 15:13:15,241 - [WARNING]    django.request: Not Found: /sw.js
2022-12-30 15:13:15,247 - [WARNING]    django.channels.server: [33mHTTP GET /sw.js 404 [0.29, 172.20.0.1:59702][0m
2022-12-30 15:13:21,408 - [INFO]    django.channels.server: [mHTTP GET /bankgateways/sample-payment/ 200 [0.49, 172.20.0.1:58842][0m
2022-12-30 15:13:31,568 - [INFO]    django.channels.server: [32mHTTP POST /bankgateways/sample-payment/ 302 [2.17, 172.20.0.1:43212][0m
2022-12-30 15:13:43,482 - [INFO]    django.channels.server: [mHTTP GET /bankgateways/sample-payment/ 200 [0.22, 172.20.0.1:47924][0m
2022-12-30 15:23:25,760 - [INFO]    django.channels.server: [mHTTP GET /bankgateways/sample-payment/ 200 [0.47, 172.20.0.1:32982][0m
2022-12-30 15:23:30,831 - [INFO]    django.channels.server: [32mHTTP POST /bankgateways/sample-payment/ 302 [2.19, 172.20.0.1:60416][0m
2022-12-30 15:23:31,233 - [INFO]    django.channels.server: [mHTTP GET /bankgateways/go-to-bank-gateway/?url=https%3A%2F%2Fidpay.ir%2Fp%2Fws-sandbox%2F6c6b5aa54e2bfb9c70187a906049e96d&method=GET 200 [0.35, 172.20.0.1:60430][0m
2022-12-30 15:23:54,339 - [INFO]    django.channels.server: [mHTTP GET /bankgateways/sample-payment/ 200 [0.22, 172.20.0.1:40344][0m
2022-12-30 15:23:56,492 - [INFO]    django.channels.server: [mHTTP GET /bankgateways/sample-payment/ 200 [0.23, 172.20.0.1:40354][0m
2022-12-30 15:24:23,789 - [INFO]    django.channels.server: [32mHTTP POST /bankgateways/sample-payment/ 302 [1.88, 172.20.0.1:35376][0m
2022-12-30 15:24:24,148 - [INFO]    django.channels.server: [mHTTP GET /bankgateways/go-to-bank-gateway/?url=https%3A%2F%2Fidpay.ir%2Fp%2Fws-sandbox%2F0c67ceeea5c242b25e73651510191f5b&method=GET 200 [0.19, 172.20.0.1:35386][0m
2022-12-30 15:24:28,618 - [INFO]    django.channels.server: [mHTTP GET /bankgateways/sample-payment/ 200 [0.23, 172.20.0.1:44182][0m
2022-12-30 15:24:34,116 - [INFO]    django.channels.server: [mHTTP GET /bankgateways/sample-payment/ 200 [0.31, 172.20.0.1:44194][0m
2022-12-30 15:24:34,309 - [INFO]    django.channels.server: [mHTTP GET /static/debug_toolbar/css/toolbar.css 200 [0.00, 172.20.0.1:44194][0m
2022-12-30 15:24:34,347 - [INFO]    django.channels.server: [mHTTP GET /static/debug_toolbar/js/toolbar.js 200 [0.03, 172.20.0.1:44210][0m
2022-12-30 15:24:34,881 - [INFO]    django.channels.server: [mHTTP GET /static/debug_toolbar/js/utils.js 200 [0.01, 172.20.0.1:44210][0m
2022-12-30 15:24:34,941 - [INFO]    django.channels.server: [mHTTP GET /static/debug_toolbar/css/print.css 200 [0.00, 172.20.0.1:44210][0m
2022-12-30 15:24:36,008 - [WARNING]    django.request: Not Found: /sw.js
2022-12-30 15:24:36,014 - [WARNING]    django.channels.server: [33mHTTP GET /sw.js 404 [0.23, 172.20.0.1:44210][0m
2022-12-30 15:24:37,818 - [WARNING]    django.request: Not Found: /sw.js
2022-12-30 15:24:37,822 - [WARNING]    django.channels.server: [33mHTTP GET /sw.js 404 [0.22, 172.20.0.1:44218][0m
2022-12-30 15:24:38,277 - [INFO]    django.channels.server: [32mHTTP POST /bankgateways/sample-payment/ 302 [2.10, 172.20.0.1:44194][0m
2022-12-30 15:24:39,421 - [INFO]    django.channels.server: [mHTTP GET /bankgateways/go-to-bank-gateway/?url=https%3A%2F%2Fidpay.ir%2Fp%2Fws-sandbox%2F05d0d3d41b52825487a2e48a47d98242&method=GET 200 [0.19, 172.20.0.1:44194][0m
2022-12-30 15:24:40,624 - [WARNING]    django.request: Not Found: /sw.js
2022-12-30 15:24:40,628 - [WARNING]    django.channels.server: [33mHTTP GET /sw.js 404 [0.39, 172.20.0.1:44194][0m
2022-12-30 15:24:41,685 - [WARNING]    django.request: Not Found: /sw.js
2022-12-30 15:24:41,690 - [WARNING]    django.channels.server: [33mHTTP GET /sw.js 404 [0.28, 172.20.0.1:38842][0m
2022-12-30 15:24:49,131 - [INFO]    django.channels.server: [mHTTP GET /bankgateways/sample-payment/ 200 [0.20, 172.20.0.1:41422][0m
2022-12-30 15:24:50,279 - [WARNING]    django.request: Not Found: /sw.js
2022-12-30 15:24:50,284 - [WARNING]    django.channels.server: [33mHTTP GET /sw.js 404 [0.26, 172.20.0.1:41422][0m
2022-12-30 15:24:51,766 - [WARNING]    django.request: Not Found: /sw.js
2022-12-30 15:24:51,772 - [WARNING]    django.channels.server: [33mHTTP GET /sw.js 404 [0.27, 172.20.0.1:41430][0m
2022-12-30 15:37:51,915 - [INFO]    django.channels.server: [mHTTP GET /bankgateways/sample-payment/ 200 [0.85, 172.20.0.1:35832][0m
2022-12-30 15:40:10,886 - [INFO]    django.channels.server: [32mHTTP POST /bankgateways/sample-payment/ 302 [2.48, 172.20.0.1:59044][0m
2022-12-30 15:40:11,150 - [INFO]    django.channels.server: [mHTTP GET /bankgateways/go-to-bank-gateway/?url=https%3A%2F%2Fidpay.ir%2Fp%2Fws-sandbox%2Fb5b725f39579d3a2b1885b6eeee8f79a&method=GET 200 [0.24, 172.20.0.1:59048][0m
2022-12-30 15:40:37,010 - [INFO]    django.channels.server: [32mHTTP POST /bankgateways/callback/?bank_type=IDPAY&identifier=1 302 [1.14, 172.20.0.1:54572][0m
2022-12-30 15:40:38,337 - [INFO]    django.channels.server: [mHTTP GET /bankgateways/sample-result/?tc=6416629667051087 200 [0.39, 172.20.0.1:54582][0m
2022-12-30 15:43:41,311 - [INFO]    django.utils.autoreload: /usr/src/app/conf/settings.py changed, reloading.
2022-12-30 15:44:13,366 - [INFO]    django.utils.autoreload: Watching for file changes with StatReloader
2022-12-30 15:44:36,383 - [INFO]    django.channels.server: [mHTTP GET /bankgateways/sample-payment/ 200 [0.75, 172.20.0.1:38374][0m
2022-12-30 15:44:40,039 - [ERROR]    django.request: Internal Server Error: /bankgateways/sample-payment/
Traceback (most recent call last):
  File "/usr/local/lib/python3.10/site-packages/asgiref/sync.py", line 472, in thread_handler
    raise exc_info[1]
  File "/usr/local/lib/python3.10/site-packages/django/core/handlers/exception.py", line 42, in inner
    response = await get_response(request)
  File "/usr/local/lib/python3.10/site-packages/django/core/handlers/base.py", line 253, in _get_response_async
    response = await wrapped_callback(
  File "/usr/local/lib/python3.10/site-packages/asgiref/sync.py", line 435, in __call__
    ret = await asyncio.wait_for(future, timeout=None)
  File "/usr/local/lib/python3.10/asyncio/tasks.py", line 408, in wait_for
    return await fut
  File "/usr/local/lib/python3.10/site-packages/asgiref/current_thread_executor.py", line 22, in run
    result = self.fn(*self.args, **self.kwargs)
  File "/usr/local/lib/python3.10/site-packages/asgiref/sync.py", line 476, in thread_handler
    return func(*args, **kwargs)
  File "/usr/local/lib/python3.10/site-packages/azbankgateways/views/samples.py", line 45, in sample_payment_view
    raise e
  File "/usr/local/lib/python3.10/site-packages/azbankgateways/views/samples.py", line 27, in sample_payment_view
    bank = factory.auto_create()
  File "/usr/local/lib/python3.10/site-packages/azbankgateways/bankfactories.py", line 67, in auto_create
    raise BankGatewayAutoConnectionFailed()
azbankgateways.exceptions.exceptions.BankGatewayAutoConnectionFailed
2022-12-30 15:44:40,242 - [ERROR]    django.channels.server: [35;1mHTTP POST /bankgateways/sample-payment/ 500 [0.45, 172.20.0.1:37974][0m
2022-12-30 16:17:15,577 - [INFO]    django.utils.autoreload: /usr/src/app/conf/settings.py changed, reloading.
2022-12-30 16:18:02,154 - [INFO]    django.utils.autoreload: Watching for file changes with StatReloader
2022-12-30 16:23:19,054 - [INFO]    django.utils.autoreload: /usr/src/app/conf/settings.py changed, reloading.
2022-12-30 16:23:23,030 - [INFO]    django.utils.autoreload: Watching for file changes with StatReloader
2022-12-30 16:24:14,439 - [ERROR]    django.request: Internal Server Error: /bankgateways/sample-payment/
Traceback (most recent call last):
  File "/usr/local/lib/python3.10/site-packages/asgiref/sync.py", line 472, in thread_handler
    raise exc_info[1]
  File "/usr/local/lib/python3.10/site-packages/django/core/handlers/exception.py", line 42, in inner
    response = await get_response(request)
  File "/usr/local/lib/python3.10/site-packages/django/core/handlers/base.py", line 253, in _get_response_async
    response = await wrapped_callback(
  File "/usr/local/lib/python3.10/site-packages/asgiref/sync.py", line 435, in __call__
    ret = await asyncio.wait_for(future, timeout=None)
  File "/usr/local/lib/python3.10/asyncio/tasks.py", line 408, in wait_for
    return await fut
  File "/usr/local/lib/python3.10/site-packages/asgiref/current_thread_executor.py", line 22, in run
    result = self.fn(*self.args, **self.kwargs)
  File "/usr/local/lib/python3.10/site-packages/asgiref/sync.py", line 476, in thread_handler
    return func(*args, **kwargs)
  File "/usr/local/lib/python3.10/site-packages/azbankgateways/views/samples.py", line 45, in sample_payment_view
    raise e
  File "/usr/local/lib/python3.10/site-packages/azbankgateways/views/samples.py", line 27, in sample_payment_view
    bank = factory.auto_create()
  File "/usr/local/lib/python3.10/site-packages/azbankgateways/bankfactories.py", line 67, in auto_create
    raise BankGatewayAutoConnectionFailed()
azbankgateways.exceptions.exceptions.BankGatewayAutoConnectionFailed
2022-12-30 16:24:14,874 - [ERROR]    django.channels.server: [35;1mHTTP POST /bankgateways/sample-payment/ 500 [1.45, 172.20.0.1:45116][0m
2022-12-30 16:25:35,654 - [INFO]    django.utils.autoreload: /usr/src/app/conf/settings.py changed, reloading.
2022-12-30 16:25:38,441 - [INFO]    django.utils.autoreload: Watching for file changes with StatReloader
2022-12-30 16:25:42,116 - [ERROR]    django.request: Internal Server Error: /bankgateways/sample-payment/
Traceback (most recent call last):
  File "/usr/local/lib/python3.10/site-packages/asgiref/sync.py", line 472, in thread_handler
    raise exc_info[1]
  File "/usr/local/lib/python3.10/site-packages/django/core/handlers/exception.py", line 42, in inner
    response = await get_response(request)
  File "/usr/local/lib/python3.10/site-packages/django/core/handlers/base.py", line 253, in _get_response_async
    response = await wrapped_callback(
  File "/usr/local/lib/python3.10/site-packages/asgiref/sync.py", line 435, in __call__
    ret = await asyncio.wait_for(future, timeout=None)
  File "/usr/local/lib/python3.10/asyncio/tasks.py", line 408, in wait_for
    return await fut
  File "/usr/local/lib/python3.10/site-packages/asgiref/current_thread_executor.py", line 22, in run
    result = self.fn(*self.args, **self.kwargs)
  File "/usr/local/lib/python3.10/site-packages/asgiref/sync.py", line 476, in thread_handler
    return func(*args, **kwargs)
  File "/usr/local/lib/python3.10/site-packages/azbankgateways/views/samples.py", line 45, in sample_payment_view
    raise e
  File "/usr/local/lib/python3.10/site-packages/azbankgateways/views/samples.py", line 27, in sample_payment_view
    bank = factory.auto_create()
  File "/usr/local/lib/python3.10/site-packages/azbankgateways/bankfactories.py", line 67, in auto_create
    raise BankGatewayAutoConnectionFailed()
azbankgateways.exceptions.exceptions.BankGatewayAutoConnectionFailed
2022-12-30 16:25:42,324 - [ERROR]    django.channels.server: [35;1mHTTP POST /bankgateways/sample-payment/ 500 [0.69, 172.20.0.1:60482][0m
2022-12-30 16:25:48,777 - [INFO]    django.channels.server: [mHTTP GET /bankgateways/sample-payment/ 200 [1.38, 172.20.0.1:60490][0m
2022-12-30 16:25:50,220 - [INFO]    django.channels.server: [mHTTP GET /bankgateways/sample-payment/ 200 [0.20, 172.20.0.1:33744][0m
2022-12-30 16:25:53,233 - [ERROR]    django.request: Internal Server Error: /bankgateways/sample-payment/
Traceback (most recent call last):
  File "/usr/local/lib/python3.10/site-packages/asgiref/sync.py", line 472, in thread_handler
    raise exc_info[1]
  File "/usr/local/lib/python3.10/site-packages/django/core/handlers/exception.py", line 42, in inner
    response = await get_response(request)
  File "/usr/local/lib/python3.10/site-packages/django/core/handlers/base.py", line 253, in _get_response_async
    response = await wrapped_callback(
  File "/usr/local/lib/python3.10/site-packages/asgiref/sync.py", line 435, in __call__
    ret = await asyncio.wait_for(future, timeout=None)
  File "/usr/local/lib/python3.10/asyncio/tasks.py", line 408, in wait_for
    return await fut
  File "/usr/local/lib/python3.10/site-packages/asgiref/current_thread_executor.py", line 22, in run
    result = self.fn(*self.args, **self.kwargs)
  File "/usr/local/lib/python3.10/site-packages/asgiref/sync.py", line 476, in thread_handler
    return func(*args, **kwargs)
  File "/usr/local/lib/python3.10/site-packages/azbankgateways/views/samples.py", line 45, in sample_payment_view
    raise e
  File "/usr/local/lib/python3.10/site-packages/azbankgateways/views/samples.py", line 27, in sample_payment_view
    bank = factory.auto_create()
  File "/usr/local/lib/python3.10/site-packages/azbankgateways/bankfactories.py", line 67, in auto_create
    raise BankGatewayAutoConnectionFailed()
azbankgateways.exceptions.exceptions.BankGatewayAutoConnectionFailed
2022-12-30 16:25:53,604 - [ERROR]    django.channels.server: [35;1mHTTP POST /bankgateways/sample-payment/ 500 [0.87, 172.20.0.1:33748][0m
2022-12-31 04:47:15,265 - [INFO]    django.utils.autoreload: Watching for file changes with StatReloader
2022-12-31 05:00:34,293 - [INFO]    django.channels.server: [mHTTP GET / 200 [8.13, 172.20.0.1:45036][0m
2022-12-31 05:01:06,593 - [INFO]    django.channels.server: [mHTTP GET / 200 [0.20, 172.20.0.1:52794][0m
2022-12-31 05:01:10,393 - [WARNING]    django.request: Not Found: /sw.js
2022-12-31 05:01:10,397 - [WARNING]    django.channels.server: [33mHTTP GET /sw.js 404 [0.57, 172.20.0.1:52796][0m
2022-12-31 05:01:13,689 - [INFO]    django.channels.server: [mHTTP GET / 200 [0.21, 172.20.0.1:52798][0m
2022-12-31 05:01:14,676 - [WARNING]    django.request: Not Found: /sw.js
2022-12-31 05:01:14,681 - [WARNING]    django.channels.server: [33mHTTP GET /sw.js 404 [0.19, 172.20.0.1:52806][0m
2022-12-31 05:01:23,027 - [INFO]    django.channels.server: [mHTTP GET /static/assets/css/nucleo-icons.css 200 [0.84, 172.20.0.1:52798][0m
2022-12-31 05:01:23,047 - [INFO]    django.channels.server: [mHTTP GET /static/assets/css/nucleo-svg.css 200 [0.86, 172.20.0.1:52794][0m
2022-12-31 05:01:23,118 - [INFO]    django.channels.server: [mHTTP GET /static/assets/css/material-kit.css 200 [0.92, 172.20.0.1:56528][0m
2022-12-31 05:01:23,207 - [INFO]    django.channels.server: [mHTTP GET /static/assets/css/badge.css 200 [1.01, 172.20.0.1:56532][0m
2022-12-31 05:01:23,303 - [INFO]    django.channels.server: [mHTTP GET /static/assets/css/autocomplete.css 200 [1.11, 172.20.0.1:56534][0m
2022-12-31 05:01:23,381 - [INFO]    django.channels.server: [mHTTP GET /static/assets/js/core/popper.min.js 200 [1.18, 172.20.0.1:56542][0m
2022-12-31 05:01:23,460 - [INFO]    django.channels.server: [mHTTP GET /static/assets/js/core/bootstrap.min.js 200 [0.43, 172.20.0.1:52798][0m
2022-12-31 05:01:23,538 - [INFO]    django.channels.server: [mHTTP GET /static/assets/js/plugins/perfect-scrollbar.min.js 200 [0.49, 172.20.0.1:52794][0m
2022-12-31 05:01:23,619 - [INFO]    django.channels.server: [mHTTP GET /static/assets/js/material-kit.min.js 200 [0.49, 172.20.0.1:56528][0m
2022-12-31 05:01:23,672 - [INFO]    django.channels.server: [mHTTP GET /static/assets/js/plugins/parallax.min.js 200 [0.45, 172.20.0.1:56532][0m
2022-12-31 05:01:23,768 - [ERROR]    django.channels.server: [35;1mHTTP GET /static/assets/js/plugins/choices.min.js 500 [0.31, 172.20.0.1:52798][0m
2022-12-31 05:01:23,791 - [INFO]    django.channels.server: [mHTTP GET /static/assets/js/autocomplete.js 200 [0.48, 172.20.0.1:56534][0m
2022-12-31 05:01:23,820 - [INFO]    django.channels.server: [mHTTP GET /static/assets/js/plugins/countup.min.js 200 [0.42, 172.20.0.1:56542][0m
2022-12-31 05:01:23,862 - [INFO]    django.channels.server: [mHTTP GET /static/assets/js/plugins/prism.min.js 200 [0.32, 172.20.0.1:52794][0m
2022-12-31 05:01:23,910 - [INFO]    django.channels.server: [mHTTP GET /static/assets/js/plugins/highlight.min.js 200 [0.28, 172.20.0.1:56528][0m
2022-12-31 05:01:23,945 - [INFO]    django.channels.server: [mHTTP GET /static/assets/js/plugins/rellax.min.js 200 [0.26, 172.20.0.1:56532][0m
2022-12-31 05:01:23,984 - [INFO]    django.channels.server: [mHTTP GET /static/assets/js/plugins/tilt.min.js 200 [0.21, 172.20.0.1:52798][0m
2022-12-31 05:01:24,017 - [INFO]    django.channels.server: [mHTTP GET /static/assets/js/core/jquery.min.js 200 [0.22, 172.20.0.1:56534][0m
2022-12-31 05:01:24,083 - [INFO]    django.channels.server: [mHTTP GET /static/debug_toolbar/js/toolbar.js 200 [0.21, 172.20.0.1:52794][0m
2022-12-31 05:01:24,778 - [ERROR]    django.channels.server: [35;1mHTTP GET /static/debug_toolbar/css/toolbar.css 500 [0.96, 172.20.0.1:56542][0m
2022-12-31 05:01:24,840 - [INFO]    django.channels.server: [mHTTP GET /static/assets/img/down-arrow-dark.svg 200 [0.05, 172.20.0.1:56528][0m
2022-12-31 05:01:24,902 - [INFO]    django.channels.server: [mHTTP GET /static/assets/img/logo-ct-dark.png 200 [0.11, 172.20.0.1:56534][0m
2022-12-31 05:01:25,012 - [WARNING]    django.request: Not Found: /sw.js
2022-12-31 05:01:25,020 - [WARNING]    django.channels.server: [33mHTTP GET /sw.js 404 [0.23, 172.20.0.1:56532][0m
2022-12-31 05:01:28,166 - [INFO]    django.channels.server: [mHTTP GET /static/debug_toolbar/js/utils.js 200 [0.05, 172.20.0.1:56528][0m
2022-12-31 05:01:29,859 - [WARNING]    django.request: Not Found: /sw.js
2022-12-31 05:01:29,866 - [WARNING]    django.channels.server: [33mHTTP GET /sw.js 404 [0.19, 172.20.0.1:56528][0m
2022-12-31 05:01:41,234 - [WARNING]    django.request: Not Found: /sw.js
2022-12-31 05:01:41,237 - [WARNING]    django.channels.server: [33mHTTP GET /sw.js 404 [0.20, 172.20.0.1:56534][0m
2022-12-31 05:01:42,342 - [INFO]    django.channels.server: [mHTTP GET /static/assets/img/bg2.jpg 200 [0.08, 172.20.0.1:56542][0m
2022-12-31 05:01:43,498 - [WARNING]    django.request: Not Found: /sw.js
2022-12-31 05:01:43,502 - [WARNING]    django.channels.server: [33mHTTP GET /sw.js 404 [0.23, 172.20.0.1:52798][0m
2022-12-31 05:01:43,672 - [INFO]    django.channels.server: [mHTTP GET /static/assets/js/plugins/choices.min.js 200 [1.03, 172.20.0.1:56542][0m
2022-12-31 05:01:47,715 - [INFO]    django.channels.server: [mHTTP GET /static/assets/img/apple-icon.png 200 [0.05, 172.20.0.1:56542][0m
2022-12-31 05:01:47,771 - [INFO]    django.channels.server: [mHTTP GET /static/assets/img/favicon.png 200 [0.11, 172.20.0.1:52794][0m
2022-12-31 05:01:48,866 - [WARNING]    django.request: Not Found: /sw.js
2022-12-31 05:01:48,872 - [WARNING]    django.channels.server: [33mHTTP GET /sw.js 404 [0.19, 172.20.0.1:56542][0m
2022-12-31 05:01:51,465 - [WARNING]    django.request: Not Found: /sw.js
2022-12-31 05:01:51,471 - [WARNING]    django.channels.server: [33mHTTP GET /sw.js 404 [0.21, 172.20.0.1:52794][0m
2022-12-31 05:01:52,648 - [WARNING]    django.request: Not Found: /sw.js
2022-12-31 05:01:52,653 - [WARNING]    django.channels.server: [33mHTTP GET /sw.js 404 [0.21, 172.20.0.1:37604][0m
2022-12-31 05:01:53,414 - [INFO]    django.channels.server: [mHTTP GET /static/debug_toolbar/css/print.css 200 [0.03, 172.20.0.1:37614][0m
2022-12-31 05:01:53,459 - [INFO]    django.channels.server: [mHTTP GET /static/debug_toolbar/css/toolbar.css 200 [0.07, 172.20.0.1:37628][0m
2022-12-31 05:01:54,487 - [WARNING]    django.request: Not Found: /sw.js
2022-12-31 05:01:54,496 - [WARNING]    django.channels.server: [33mHTTP GET /sw.js 404 [0.19, 172.20.0.1:37628][0m
2022-12-31 05:02:04,986 - [WARNING]    django.request: Not Found: /sw.js
2022-12-31 05:02:04,990 - [WARNING]    django.channels.server: [33mHTTP GET /sw.js 404 [0.26, 172.20.0.1:37614][0m
2022-12-31 05:02:20,315 - [INFO]    django.channels.server: [mHTTP GET / 200 [0.23, 172.20.0.1:38890][0m
2022-12-31 05:03:44,300 - [INFO]    django.channels.server: [mHTTP GET / 200 [1.29, 172.20.0.1:56178][0m
2022-12-31 05:14:31,281 - [INFO]    django.utils.autoreload: Watching for file changes with StatReloader
2022-12-31 05:41:59,709 - [INFO]    django.channels.server: [mHTTP GET / 200 [3.55, 172.20.0.1:39766][0m
2022-12-31 05:42:14,177 - [WARNING]    django.request: Not Found: /cart
2022-12-31 05:42:14,180 - [WARNING]    django.channels.server: [33mHTTP GET /cart 404 [0.38, 172.20.0.1:52884][0m
2022-12-31 05:42:21,524 - [INFO]    django.channels.server: [mHTTP GET / 200 [0.56, 172.20.0.1:58582][0m
2022-12-31 05:42:23,581 - [INFO]    django.channels.server: [mHTTP GET /static/assets/css/nucleo-icons.css 200 [0.06, 172.20.0.1:58582][0m
2022-12-31 05:42:23,634 - [INFO]    django.channels.server: [mHTTP GET /static/assets/css/nucleo-svg.css 200 [0.09, 172.20.0.1:58590][0m
2022-12-31 05:42:23,816 - [INFO]    django.channels.server: [mHTTP GET /static/assets/css/badge.css 200 [0.27, 172.20.0.1:58604][0m
2022-12-31 05:42:23,876 - [INFO]    django.channels.server: [mHTTP GET /static/assets/css/autocomplete.css 200 [0.32, 172.20.0.1:58612][0m
2022-12-31 05:42:24,024 - [INFO]    django.channels.server: [mHTTP GET /static/assets/js/core/popper.min.js 200 [0.47, 172.20.0.1:58628][0m
2022-12-31 05:42:24,125 - [INFO]    django.channels.server: [mHTTP GET /static/assets/js/plugins/perfect-scrollbar.min.js 200 [0.54, 172.20.0.1:58582][0m
2022-12-31 05:42:24,229 - [INFO]    django.channels.server: [mHTTP GET /static/assets/js/material-kit.min.js 200 [0.49, 172.20.0.1:58590][0m
2022-12-31 05:42:24,256 - [INFO]    django.channels.server: [mHTTP GET /static/assets/js/core/bootstrap.min.js 200 [0.48, 172.20.0.1:58644][0m
2022-12-31 05:42:24,281 - [INFO]    django.channels.server: [mHTTP GET /static/assets/js/plugins/parallax.min.js 200 [0.46, 172.20.0.1:58604][0m
2022-12-31 05:42:24,295 - [INFO]    django.channels.server: [mHTTP GET /static/assets/js/autocomplete.js 200 [0.41, 172.20.0.1:58612][0m
2022-12-31 05:42:24,351 - [INFO]    django.channels.server: [mHTTP GET /static/assets/js/plugins/countup.min.js 200 [0.32, 172.20.0.1:58628][0m
2022-12-31 05:42:24,490 - [INFO]    django.channels.server: [mHTTP GET /static/assets/js/plugins/choices.min.js 200 [0.36, 172.20.0.1:58582][0m
2022-12-31 05:42:24,560 - [INFO]    django.channels.server: [mHTTP GET /static/assets/js/plugins/prism.min.js 200 [0.32, 172.20.0.1:58590][0m
2022-12-31 05:42:24,642 - [INFO]    django.channels.server: [mHTTP GET /static/assets/js/plugins/highlight.min.js 200 [0.38, 172.20.0.1:58644][0m
2022-12-31 05:42:24,688 - [INFO]    django.channels.server: [mHTTP GET /static/assets/js/plugins/rellax.min.js 200 [0.40, 172.20.0.1:58604][0m
2022-12-31 05:42:24,783 - [INFO]    django.channels.server: [mHTTP GET /static/assets/js/plugins/tilt.min.js 200 [0.48, 172.20.0.1:58612][0m
2022-12-31 05:42:24,828 - [INFO]    django.channels.server: [mHTTP GET /static/assets/js/core/jquery.min.js 200 [0.47, 172.20.0.1:58628][0m
2022-12-31 05:42:24,881 - [INFO]    django.channels.server: [mHTTP GET /static/debug_toolbar/css/toolbar.css 200 [0.39, 172.20.0.1:58582][0m
2022-12-31 05:42:24,926 - [INFO]    django.channels.server: [mHTTP GET /static/debug_toolbar/js/toolbar.js 200 [0.36, 172.20.0.1:58590][0m
2022-12-31 05:42:25,008 - [INFO]    django.channels.server: [mHTTP GET /static/assets/img/down-arrow-dark.svg 200 [0.12, 172.20.0.1:58628][0m
2022-12-31 05:42:25,033 - [INFO]    django.channels.server: [mHTTP GET /static/assets/img/logo-ct-dark.png 200 [0.15, 172.20.0.1:58644][0m
2022-12-31 05:42:28,003 - [INFO]    django.channels.server: [mHTTP GET /static/debug_toolbar/js/utils.js 200 [0.03, 172.20.0.1:58644][0m
2022-12-31 05:42:28,202 - [WARNING]    django.request: Not Found: /sw.js
2022-12-31 05:42:28,210 - [WARNING]    django.channels.server: [33mHTTP GET /sw.js 404 [0.31, 172.20.0.1:58628][0m
2022-12-31 05:42:31,503 - [INFO]    django.channels.server: [mHTTP GET /static/debug_toolbar/css/print.css 200 [0.05, 172.20.0.1:58612][0m
2022-12-31 05:42:32,604 - [WARNING]    django.request: Not Found: /sw.js
2022-12-31 05:42:32,609 - [WARNING]    django.channels.server: [33mHTTP GET /sw.js 404 [0.30, 172.20.0.1:58612][0m
2022-12-31 05:42:33,125 - [INFO]    django.channels.server: [mHTTP GET /static/assets/img/apple-icon.png 200 [0.02, 172.20.0.1:58590][0m
2022-12-31 05:42:33,237 - [INFO]    django.channels.server: [mHTTP GET /static/assets/img/favicon.png 200 [0.13, 172.20.0.1:58604][0m
2022-12-31 05:42:34,057 - [WARNING]    django.request: Not Found: /sw.js
2022-12-31 05:42:34,060 - [WARNING]    django.channels.server: [33mHTTP GET /sw.js 404 [0.22, 172.20.0.1:58590][0m
2022-12-31 05:42:37,023 - [INFO]    django.channels.server: [32mHTTP GET /delivery/cart 301 [0.19, 172.20.0.1:52974][0m
2022-12-31 05:42:41,795 - [WARNING]    django.request: Not Found: /cart
2022-12-31 05:42:41,802 - [WARNING]    django.channels.server: [33mHTTP GET /cart 404 [0.26, 172.20.0.1:52986][0m
2022-12-31 05:43:02,465 - [WARNING]    django.request: Not Found: /cart
2022-12-31 05:43:02,468 - [WARNING]    django.channels.server: [33mHTTP GET /cart 404 [0.18, 172.20.0.1:50204][0m
2022-12-31 05:43:27,889 - [INFO]    django.channels.server: [mHTTP GET /delivery/cart/ 200 [0.22, 172.20.0.1:58220][0m
2022-12-31 05:43:33,777 - [INFO]    django.channels.server: [mHTTP GET /delivery/cart/ 200 [0.18, 172.20.0.1:58232][0m
2022-12-31 05:44:26,410 - [INFO]    django.channels.server: [mHTTP GET / 200 [0.23, 172.20.0.1:56200][0m
2022-12-31 05:44:26,828 - [INFO]    django.channels.server: [mHTTP GET /static/assets/js/core/popper.min.js 200 [0.00, 172.20.0.1:56200][0m
2022-12-31 05:44:27,964 - [WARNING]    django.request: Not Found: /sw.js
2022-12-31 05:44:27,971 - [WARNING]    django.channels.server: [33mHTTP GET /sw.js 404 [0.27, 172.20.0.1:56252][0m
2022-12-31 05:44:28,675 - [WARNING]    django.request: Not Found: /sw.js
2022-12-31 05:44:28,680 - [WARNING]    django.channels.server: [33mHTTP GET /sw.js 404 [0.33, 172.20.0.1:56268][0m
2022-12-31 05:44:30,642 - [WARNING]    django.request: Not Found: /sw.js
2022-12-31 05:44:30,646 - [WARNING]    django.channels.server: [33mHTTP GET /sw.js 404 [0.25, 172.20.0.1:56270][0m
2022-12-31 05:44:32,787 - [INFO]    django.channels.server: [mHTTP GET /bankgateways/sample-payment/ 200 [0.39, 172.20.0.1:56272][0m
2022-12-31 05:44:33,652 - [WARNING]    django.request: Not Found: /sw.js
2022-12-31 05:44:33,655 - [WARNING]    django.channels.server: [33mHTTP GET /sw.js 404 [0.32, 172.20.0.1:56284][0m
2022-12-31 05:44:35,082 - [WARNING]    django.request: Not Found: /sw.js
2022-12-31 05:44:35,088 - [WARNING]    django.channels.server: [33mHTTP GET /sw.js 404 [0.23, 172.20.0.1:39476][0m
2022-12-31 05:44:39,569 - [WARNING]    django.request: Not Found: /sw.js
2022-12-31 05:44:39,573 - [WARNING]    django.channels.server: [33mHTTP GET /sw.js 404 [0.26, 172.20.0.1:39500][0m
2022-12-31 05:44:39,661 - [ERROR]    django.request: Internal Server Error: /bankgateways/sample-payment/
Traceback (most recent call last):
  File "/usr/local/lib/python3.10/site-packages/asgiref/sync.py", line 472, in thread_handler
    raise exc_info[1]
  File "/usr/local/lib/python3.10/site-packages/django/core/handlers/exception.py", line 42, in inner
    response = await get_response(request)
  File "/usr/local/lib/python3.10/site-packages/django/core/handlers/base.py", line 253, in _get_response_async
    response = await wrapped_callback(
  File "/usr/local/lib/python3.10/site-packages/asgiref/sync.py", line 435, in __call__
    ret = await asyncio.wait_for(future, timeout=None)
  File "/usr/local/lib/python3.10/asyncio/tasks.py", line 408, in wait_for
    return await fut
  File "/usr/local/lib/python3.10/site-packages/asgiref/current_thread_executor.py", line 22, in run
    result = self.fn(*self.args, **self.kwargs)
  File "/usr/local/lib/python3.10/site-packages/asgiref/sync.py", line 476, in thread_handler
    return func(*args, **kwargs)
  File "/usr/local/lib/python3.10/site-packages/azbankgateways/views/samples.py", line 45, in sample_payment_view
    raise e
  File "/usr/local/lib/python3.10/site-packages/azbankgateways/views/samples.py", line 27, in sample_payment_view
    bank = factory.auto_create()
  File "/usr/local/lib/python3.10/site-packages/azbankgateways/bankfactories.py", line 67, in auto_create
    raise BankGatewayAutoConnectionFailed()
azbankgateways.exceptions.exceptions.BankGatewayAutoConnectionFailed
2022-12-31 05:44:39,954 - [ERROR]    django.channels.server: [35;1mHTTP POST /bankgateways/sample-payment/ 500 [2.43, 172.20.0.1:39486][0m
2022-12-31 05:44:41,448 - [WARNING]    django.request: Not Found: /sw.js
2022-12-31 05:44:41,451 - [WARNING]    django.channels.server: [33mHTTP GET /sw.js 404 [0.22, 172.20.0.1:39486][0m
2022-12-31 05:44:48,795 - [INFO]    django.utils.autoreload: /usr/src/app/apps/delivery/views.py changed, reloading.
2022-12-31 05:44:59,321 - [INFO]    django.utils.autoreload: Watching for file changes with StatReloader
2022-12-31 05:46:22,114 - [WARNING]    django.request: Not Found: /sw.js
2022-12-31 05:46:22,118 - [WARNING]    django.channels.server: [33mHTTP GET /sw.js 404 [1.40, 172.20.0.1:47220][0m
2022-12-31 05:49:25,655 - [WARNING]    django.request: Not Found: /sw.js
2022-12-31 05:49:25,663 - [WARNING]    django.channels.server: [33mHTTP GET /sw.js 404 [0.36, 172.20.0.1:34878][0m
2022-12-31 05:49:27,095 - [ERROR]    django.request: Internal Server Error: /bankgateways/sample-payment/
Traceback (most recent call last):
  File "/usr/local/lib/python3.10/site-packages/asgiref/sync.py", line 472, in thread_handler
    raise exc_info[1]
  File "/usr/local/lib/python3.10/site-packages/django/core/handlers/exception.py", line 42, in inner
    response = await get_response(request)
  File "/usr/local/lib/python3.10/site-packages/django/core/handlers/base.py", line 253, in _get_response_async
    response = await wrapped_callback(
  File "/usr/local/lib/python3.10/site-packages/asgiref/sync.py", line 435, in __call__
    ret = await asyncio.wait_for(future, timeout=None)
  File "/usr/local/lib/python3.10/asyncio/tasks.py", line 408, in wait_for
    return await fut
  File "/usr/local/lib/python3.10/site-packages/asgiref/current_thread_executor.py", line 22, in run
    result = self.fn(*self.args, **self.kwargs)
  File "/usr/local/lib/python3.10/site-packages/asgiref/sync.py", line 476, in thread_handler
    return func(*args, **kwargs)
  File "/usr/local/lib/python3.10/site-packages/azbankgateways/views/samples.py", line 45, in sample_payment_view
    raise e
  File "/usr/local/lib/python3.10/site-packages/azbankgateways/views/samples.py", line 27, in sample_payment_view
    bank = factory.auto_create()
  File "/usr/local/lib/python3.10/site-packages/azbankgateways/bankfactories.py", line 67, in auto_create
    raise BankGatewayAutoConnectionFailed()
azbankgateways.exceptions.exceptions.BankGatewayAutoConnectionFailed
2022-12-31 05:49:27,335 - [ERROR]    django.channels.server: [35;1mHTTP POST /bankgateways/sample-payment/ 500 [2.22, 172.20.0.1:34876][0m
2022-12-31 05:49:28,910 - [WARNING]    django.request: Not Found: /sw.js
2022-12-31 05:49:28,914 - [WARNING]    django.channels.server: [33mHTTP GET /sw.js 404 [0.22, 172.20.0.1:34876][0m
2022-12-31 05:51:36,854 - [WARNING]    django.request: Not Found: /sw.js
2022-12-31 05:51:37,229 - [WARNING]    django.channels.server: [33mHTTP GET /sw.js 404 [5.16, 172.20.0.1:48516][0m
2022-12-31 05:51:37,813 - [INFO]    django.channels.server: [mHTTP GET / 200 [7.13, 172.20.0.1:48502][0m
2022-12-31 05:51:39,531 - [WARNING]    django.request: Not Found: /sw.js
2022-12-31 05:51:39,537 - [WARNING]    django.channels.server: [33mHTTP GET /sw.js 404 [0.28, 172.20.0.1:59690][0m
2022-12-31 05:51:41,500 - [WARNING]    django.request: Not Found: /sw.js
2022-12-31 05:51:41,505 - [WARNING]    django.channels.server: [33mHTTP GET /sw.js 404 [0.28, 172.20.0.1:59736][0m
2022-12-31 05:51:42,041 - [WARNING]    django.request: Not Found: /sw.js
2022-12-31 05:51:42,045 - [WARNING]    django.channels.server: [33mHTTP GET /sw.js 404 [0.19, 172.20.0.1:59752][0m
2022-12-31 06:00:33,843 - [INFO]    django.utils.autoreload: Watching for file changes with StatReloader
2022-12-31 15:45:59,996 - [INFO]    django.utils.autoreload: Watching for file changes with StatReloader
2023-01-01 01:20:51,647 - [INFO]    django.utils.autoreload: Watching for file changes with StatReloader
2023-01-01 01:21:02,446 - [WARNING]    django.request: Not Found: /sw.js
2023-01-01 01:21:02,452 - [WARNING]    django.channels.server: [33mHTTP GET /sw.js 404 [0.67, 172.20.0.1:60012][0m
2023-01-01 01:21:02,752 - [INFO]    django.channels.server: [mHTTP GET / 200 [2.30, 172.20.0.1:60010][0m
2023-01-01 01:21:03,533 - [INFO]    django.channels.server: [mHTTP GET /static/assets/css/nucleo-icons.css 200 [0.28, 172.20.0.1:60010][0m
2023-01-01 01:21:03,906 - [INFO]    django.channels.server: [mHTTP GET /static/assets/css/nucleo-svg.css 200 [0.01, 172.20.0.1:60022][0m
2023-01-01 01:21:03,955 - [INFO]    django.channels.server: [mHTTP GET /static/assets/css/badge.css 200 [0.04, 172.20.0.1:60022][0m
2023-01-01 01:21:03,995 - [INFO]    django.channels.server: [mHTTP GET /static/assets/css/autocomplete.css 200 [0.07, 172.20.0.1:60010][0m
2023-01-01 01:21:04,018 - [INFO]    django.channels.server: [mHTTP GET /static/assets/js/core/popper.min.js 200 [0.10, 172.20.0.1:60026][0m
2023-01-01 01:21:04,128 - [INFO]    django.channels.server: [mHTTP GET /static/assets/js/core/bootstrap.min.js 200 [0.20, 172.20.0.1:60030][0m
2023-01-01 01:21:04,242 - [INFO]    django.channels.server: [mHTTP GET /static/assets/js/plugins/perfect-scrollbar.min.js 200 [0.32, 172.20.0.1:60040][0m
2023-01-01 01:21:04,268 - [INFO]    django.channels.server: [mHTTP GET /static/assets/js/material-kit.min.js 200 [0.34, 172.20.0.1:60056][0m
2023-01-01 01:21:04,353 - [INFO]    django.channels.server: [mHTTP GET /static/assets/js/plugins/parallax.min.js 200 [0.39, 172.20.0.1:60022][0m
2023-01-01 01:21:04,726 - [INFO]    django.channels.server: [mHTTP GET /static/assets/js/plugins/countup.min.js 200 [0.02, 172.20.0.1:60030][0m
2023-01-01 01:21:04,799 - [INFO]    django.channels.server: [mHTTP GET /static/assets/js/plugins/prism.min.js 200 [0.09, 172.20.0.1:60026][0m
2023-01-01 01:21:04,870 - [INFO]    django.channels.server: [mHTTP GET /static/assets/js/plugins/highlight.min.js 200 [0.15, 172.20.0.1:60040][0m
2023-01-01 01:21:04,916 - [INFO]    django.channels.server: [mHTTP GET /static/assets/js/plugins/rellax.min.js 200 [0.19, 172.20.0.1:60056][0m
2023-01-01 01:21:04,966 - [INFO]    django.channels.server: [mHTTP GET /static/assets/js/plugins/tilt.min.js 200 [0.24, 172.20.0.1:60022][0m
2023-01-01 01:21:04,999 - [INFO]    django.channels.server: [mHTTP GET /static/assets/js/core/jquery.min.js 200 [0.27, 172.20.0.1:60010][0m
2023-01-01 01:21:05,030 - [INFO]    django.channels.server: [mHTTP GET /static/debug_toolbar/css/toolbar.css 200 [0.29, 172.20.0.1:60030][0m
2023-01-01 01:21:05,285 - [INFO]    django.channels.server: [36mHTTP GET /static/debug_toolbar/js/toolbar.js 304 [0.01, 172.20.0.1:60030][0m
2023-01-01 01:21:05,493 - [WARNING]    django.request: Not Found: /sw.js
2023-01-01 01:21:05,499 - [WARNING]    django.channels.server: [33mHTTP GET /sw.js 404 [0.22, 172.20.0.1:60040][0m
2023-01-01 01:21:05,506 - [INFO]    django.channels.server: [36mHTTP GET /static/debug_toolbar/js/utils.js 304 [0.01, 172.20.0.1:60030][0m
2023-01-01 01:21:06,608 - [WARNING]    django.request: Not Found: /sw.js
2023-01-01 01:21:06,612 - [WARNING]    django.channels.server: [33mHTTP GET /sw.js 404 [0.19, 172.20.0.1:60030][0m
2023-01-01 01:21:08,620 - [WARNING]    django.request: Not Found: /sw.js
2023-01-01 01:21:08,625 - [WARNING]    django.channels.server: [33mHTTP GET /sw.js 404 [0.22, 172.20.0.1:60026][0m
2023-01-01 01:21:08,769 - [INFO]    django.channels.server: [mHTTP GET /static/debug_toolbar/css/print.css 200 [0.04, 172.20.0.1:60022][0m
2023-01-01 01:21:09,534 - [WARNING]    django.request: Not Found: /sw.js
2023-01-01 01:21:09,537 - [WARNING]    django.channels.server: [33mHTTP GET /sw.js 404 [0.20, 172.20.0.1:60022][0m
2023-01-01 01:21:10,830 - [INFO]    django.channels.server: [mHTTP GET /static/assets/img/apple-icon.png 200 [0.05, 172.20.0.1:60056][0m
2023-01-01 01:21:10,857 - [INFO]    django.channels.server: [mHTTP GET /static/assets/img/favicon.png 200 [0.08, 172.20.0.1:60010][0m
2023-01-01 01:21:11,154 - [WARNING]    django.request: Not Found: /sw.js
2023-01-01 01:21:11,158 - [WARNING]    django.channels.server: [33mHTTP GET /sw.js 404 [0.28, 172.20.0.1:60056][0m
2023-01-01 01:24:09,542 - [WARNING]    django.request: Not Found: /sw.js
2023-01-01 01:24:09,549 - [WARNING]    django.channels.server: [33mHTTP GET /sw.js 404 [0.25, 172.20.0.1:43662][0m
2023-01-01 01:24:10,442 - [INFO]    django.channels.server: [mHTTP GET /in_place/ 200 [2.17, 172.20.0.1:43658][0m
2023-01-01 01:24:10,701 - [INFO]    django.channels.server: [mHTTP GET /static/dash_assets/css/material-dashboard.css 200 [0.04, 172.20.0.1:43658][0m
2023-01-01 01:24:10,721 - [INFO]    django.channels.server: [mHTTP GET /static/dash_assets/js/core/jquery.min.js 200 [0.04, 172.20.0.1:43670][0m
2023-01-01 01:24:10,869 - [INFO]    django.channels.server: [mHTTP GET /static/dash_assets/img/sidebar-4.jpg 200 [0.16, 172.20.0.1:43692][0m
2023-01-01 01:24:10,948 - [INFO]    django.channels.server: [mHTTP GET /static/dash_assets/img/sidebar-3.jpg 200 [0.24, 172.20.0.1:43680][0m
2023-01-01 01:24:11,023 - [INFO]    django.channels.server: [mHTTP GET /static/dash_assets/img/sidebar-2.jpg 200 [0.31, 172.20.0.1:43674][0m
2023-01-01 01:24:11,085 - [INFO]    django.channels.server: [mHTTP GET /static/dash_assets/img/sidebar-1.jpg 200 [0.38, 172.20.0.1:43698][0m
2023-01-01 01:24:11,095 - [INFO]    django.channels.server: [mHTTP GET /static/dash_assets/js/core/popper.min.js 200 [0.27, 172.20.0.1:43670][0m
2023-01-01 01:24:11,127 - [INFO]    django.channels.server: [mHTTP GET /static/dash_assets/js/core/bootstrap-material-design.min.js 200 [0.30, 172.20.0.1:43658][0m
2023-01-01 01:24:11,138 - [INFO]    django.channels.server: [mHTTP GET /static/dash_assets/js/plugins/perfect-scrollbar.jquery.min.js 200 [0.26, 172.20.0.1:43692][0m
2023-01-01 01:24:11,161 - [INFO]    django.channels.server: [mHTTP GET /static/dash_assets/js/plugins/chartist.min.js 200 [0.20, 172.20.0.1:43680][0m
2023-01-01 01:24:11,177 - [INFO]    django.channels.server: [mHTTP GET /static/dash_assets/js/plugins/bootstrap-notify.js 200 [0.14, 172.20.0.1:43674][0m
2023-01-01 01:24:11,212 - [INFO]    django.channels.server: [mHTTP GET /static/dash_assets/js/material-dashboard.js 200 [0.12, 172.20.0.1:43698][0m
2023-01-01 01:24:11,866 - [WARNING]    django.request: Not Found: /sw.js
2023-01-01 01:24:11,870 - [WARNING]    django.channels.server: [33mHTTP GET /sw.js 404 [0.20, 172.20.0.1:43674][0m
2023-01-01 01:24:15,914 - [WARNING]    django.request: Not Found: /sw.js
2023-01-01 01:24:15,917 - [WARNING]    django.channels.server: [33mHTTP GET /sw.js 404 [0.18, 172.20.0.1:43692][0m
2023-01-01 01:24:24,247 - [WARNING]    django.request: Not Found: /sw.js
2023-01-01 01:24:24,251 - [WARNING]    django.channels.server: [33mHTTP GET /sw.js 404 [0.28, 172.20.0.1:43680][0m
2023-01-01 01:24:25,782 - [INFO]    django.channels.server: WebSocket HANDSHAKING /ws/dinein/delivered/ [172.20.0.1:52438]
2023-01-01 01:24:26,375 - [INFO]    django.channels.server: WebSocket CONNECT /ws/dinein/delivered/ [172.20.0.1:52438]
2023-01-01 01:24:26,426 - [INFO]    django.channels.server: WebSocket HANDSHAKING /ws/dinein/new_item/ [172.20.0.1:52448]
2023-01-01 01:24:26,460 - [INFO]    django.channels.server: WebSocket CONNECT /ws/dinein/new_item/ [172.20.0.1:52448]
2023-01-01 01:24:26,908 - [WARNING]    django.request: Not Found: /sw.js
2023-01-01 01:24:26,911 - [WARNING]    django.channels.server: [33mHTTP GET /sw.js 404 [0.20, 172.20.0.1:43698][0m
2023-01-01 01:24:28,297 - [WARNING]    django.request: Not Found: /sw.js
2023-01-01 01:24:28,300 - [WARNING]    django.channels.server: [33mHTTP GET /sw.js 404 [0.23, 172.20.0.1:43670][0m
2023-01-01 02:14:15,445 - [WARNING]    django.request: Not Found: /v1/request
2023-01-01 02:14:50,551 - [WARNING]    django.request: Not Found: /v1/request
2023-01-01 02:36:39,355 - [INFO]    django.channels.server: WebSocket DISCONNECT /ws/dinein/new_item/ [172.20.0.1:52448]
2023-01-01 02:36:39,465 - [INFO]    django.channels.server: WebSocket DISCONNECT /ws/dinein/delivered/ [172.20.0.1:52438]
2023-01-01 02:36:45,433 - [INFO]    django.channels.server: [mHTTP GET /bankgateways/sample-payment/ 200 [4.78, 172.20.0.1:47952][0m
2023-01-01 02:36:45,460 - [WARNING]    django.request: Not Found: /sw.js
2023-01-01 02:36:45,466 - [WARNING]    django.channels.server: [33mHTTP GET /sw.js 404 [3.05, 172.20.0.1:47962][0m
2023-01-01 02:36:57,860 - [WARNING]    django.request: Not Found: /sw.js
2023-01-01 02:36:57,863 - [WARNING]    django.channels.server: [33mHTTP GET /sw.js 404 [0.20, 172.20.0.1:47952][0m
2023-01-01 02:37:02,320 - [WARNING]    django.request: Not Found: /sw.js
2023-01-01 02:37:02,328 - [WARNING]    django.channels.server: [33mHTTP GET /sw.js 404 [0.23, 172.20.0.1:39486][0m
2023-01-01 02:37:07,511 - [WARNING]    django.request: Not Found: /sw.js
2023-01-01 02:37:07,515 - [WARNING]    django.channels.server: [33mHTTP GET /sw.js 404 [0.20, 172.20.0.1:59686][0m
2023-01-01 02:38:06,538 - [ERROR]    django.request: Internal Server Error: /bankgateways/sample-payment/
Traceback (most recent call last):
  File "/usr/local/lib/python3.10/site-packages/asgiref/sync.py", line 472, in thread_handler
    raise exc_info[1]
  File "/usr/local/lib/python3.10/site-packages/django/core/handlers/exception.py", line 42, in inner
    response = await get_response(request)
  File "/usr/local/lib/python3.10/site-packages/django/core/handlers/base.py", line 253, in _get_response_async
    response = await wrapped_callback(
  File "/usr/local/lib/python3.10/site-packages/asgiref/sync.py", line 435, in __call__
    ret = await asyncio.wait_for(future, timeout=None)
  File "/usr/local/lib/python3.10/asyncio/tasks.py", line 408, in wait_for
    return await fut
  File "/usr/local/lib/python3.10/site-packages/asgiref/current_thread_executor.py", line 22, in run
    result = self.fn(*self.args, **self.kwargs)
  File "/usr/local/lib/python3.10/site-packages/asgiref/sync.py", line 476, in thread_handler
    return func(*args, **kwargs)
  File "/usr/local/lib/python3.10/site-packages/azbankgateways/views/samples.py", line 45, in sample_payment_view
    raise e
  File "/usr/local/lib/python3.10/site-packages/azbankgateways/views/samples.py", line 27, in sample_payment_view
    bank = factory.auto_create()
  File "/usr/local/lib/python3.10/site-packages/azbankgateways/bankfactories.py", line 59, in auto_create
    raise BankGatewayAutoConnectionFailed()
azbankgateways.exceptions.exceptions.BankGatewayAutoConnectionFailed
2023-01-01 02:38:06,896 - [ERROR]    django.channels.server: [35;1mHTTP POST /bankgateways/sample-payment/ 500 [1.53, 172.20.0.1:39092][0m
2023-01-01 02:38:07,047 - [WARNING]    django.request: Not Found: /sw.js
2023-01-01 02:38:07,050 - [WARNING]    django.channels.server: [33mHTTP GET /sw.js 404 [0.60, 172.20.0.1:39094][0m
2023-01-01 02:38:08,339 - [WARNING]    django.request: Not Found: /sw.js
2023-01-01 02:38:08,342 - [WARNING]    django.channels.server: [33mHTTP GET /sw.js 404 [0.25, 172.20.0.1:39092][0m
2023-01-01 02:38:09,810 - [WARNING]    django.request: Not Found: /sw.js
2023-01-01 02:38:09,817 - [WARNING]    django.channels.server: [33mHTTP GET /sw.js 404 [0.22, 172.20.0.1:39096][0m
2023-01-01 02:39:55,245 - [INFO]    django.channels.server: [mHTTP GET /bankgateways/sample-payment/ 200 [0.24, 172.20.0.1:41998][0m
2023-01-01 02:39:58,122 - [ERROR]    django.request: Internal Server Error: /bankgateways/sample-payment/
Traceback (most recent call last):
  File "/usr/local/lib/python3.10/site-packages/asgiref/sync.py", line 472, in thread_handler
    raise exc_info[1]
  File "/usr/local/lib/python3.10/site-packages/django/core/handlers/exception.py", line 42, in inner
    response = await get_response(request)
  File "/usr/local/lib/python3.10/site-packages/django/core/handlers/base.py", line 253, in _get_response_async
    response = await wrapped_callback(
  File "/usr/local/lib/python3.10/site-packages/asgiref/sync.py", line 435, in __call__
    ret = await asyncio.wait_for(future, timeout=None)
  File "/usr/local/lib/python3.10/asyncio/tasks.py", line 408, in wait_for
    return await fut
  File "/usr/local/lib/python3.10/site-packages/asgiref/current_thread_executor.py", line 22, in run
    result = self.fn(*self.args, **self.kwargs)
  File "/usr/local/lib/python3.10/site-packages/asgiref/sync.py", line 476, in thread_handler
    return func(*args, **kwargs)
  File "/usr/local/lib/python3.10/site-packages/azbankgateways/views/samples.py", line 45, in sample_payment_view
    raise e
  File "/usr/local/lib/python3.10/site-packages/azbankgateways/views/samples.py", line 27, in sample_payment_view
    bank = factory.auto_create()
  File "/usr/local/lib/python3.10/site-packages/azbankgateways/bankfactories.py", line 59, in auto_create
    raise BankGatewayAutoConnectionFailed()
azbankgateways.exceptions.exceptions.BankGatewayAutoConnectionFailed
2023-01-01 02:39:58,386 - [ERROR]    django.channels.server: [35;1mHTTP POST /bankgateways/sample-payment/ 500 [0.68, 172.20.0.1:56880][0m
2023-01-01 02:49:37,328 - [INFO]    django.utils.autoreload: Watching for file changes with StatReloader
2023-01-01 03:25:55,957 - [INFO]    django.utils.autoreload: Watching for file changes with StatReloader
2023-01-01 03:27:04,540 - [INFO]    django.utils.autoreload: /usr/local/lib/python3.10/site-packages/azbankgateways/bankfactories.py changed, reloading.
2023-01-01 03:27:07,715 - [INFO]    django.utils.autoreload: Watching for file changes with StatReloader
2023-01-01 03:37:04,779 - [INFO]    django.utils.autoreload: /usr/local/lib/python3.10/site-packages/azbankgateways/bankfactories.py changed, reloading.
2023-01-01 03:37:12,891 - [INFO]    django.utils.autoreload: Watching for file changes with StatReloader
2023-01-01 03:37:52,691 - [INFO]    django.utils.autoreload: /usr/local/lib/python3.10/site-packages/azbankgateways/bankfactories.py changed, reloading.
2023-01-01 03:37:54,751 - [INFO]    django.utils.autoreload: Watching for file changes with StatReloader
2023-01-01 03:38:17,868 - [INFO]    django.channels.server: [32mHTTP POST /bankgateways/sample-payment/ 302 [7.60, 172.25.0.1:47810][0m
2023-01-01 03:38:18,587 - [INFO]    django.channels.server: [mHTTP GET /bankgateways/go-to-bank-gateway/?url=https%3A%2F%2Fgateway.zibal.ir%2Fstart%2F3112340293&method=GET 200 [0.66, 172.25.0.1:33272][0m
2023-01-01 03:39:22,982 - [INFO]    django.channels.server: [32mHTTP GET /bankgateways/callback/?bank_type=ZIBAL&identifier=1&success=1&status=2&trackId=3112340293&orderId=6233908092178938 302 [0.93, 172.25.0.1:36308][0m
2023-01-01 03:39:23,319 - [INFO]    django.channels.server: [mHTTP GET /bankgateways/sample-result/?tc=6233908092178938 200 [0.30, 172.25.0.1:36312][0m
2023-01-01 03:39:28,432 - [INFO]    django.channels.server: [mHTTP GET /bankgateways/sample-payment/ 200 [0.33, 172.25.0.1:34176][0m
2023-01-01 03:39:39,723 - [INFO]    django.channels.server: [32mHTTP GET /bankgateways/callback/?bank_type=ZIBAL&identifier=1&success=1&status=1&trackId=3112340293&orderId=6233908092178938 302 [0.24, 172.25.0.1:49028][0m
2023-01-01 03:39:39,972 - [INFO]    django.channels.server: [mHTTP GET /bankgateways/sample-result/?tc=6233908092178938 200 [0.22, 172.25.0.1:49030][0m
2023-01-01 03:41:15,974 - [INFO]    django.channels.server: [mHTTP GET / 200 [0.73, 172.25.0.1:55926][0m
2023-01-01 11:05:12,286 - [INFO]    django.utils.autoreload: Watching for file changes with StatReloader
2023-01-01 12:38:22,216 - [INFO]    django.utils.autoreload: /usr/src/app/apps/delivery/forms.py changed, reloading.
2023-01-01 12:39:15,446 - [INFO]    django.utils.autoreload: Watching for file changes with StatReloader
2023-01-01 12:39:50,031 - [INFO]    django.utils.autoreload: /usr/src/app/apps/delivery/forms.py changed, reloading.
2023-01-01 12:39:54,269 - [INFO]    django.utils.autoreload: Watching for file changes with StatReloader
2023-01-01 12:40:02,182 - [INFO]    django.utils.autoreload: /usr/src/app/apps/delivery/forms.py changed, reloading.
2023-01-01 12:40:05,212 - [INFO]    django.utils.autoreload: Watching for file changes with StatReloader
2023-01-01 12:41:41,111 - [INFO]    django.utils.autoreload: /usr/src/app/apps/delivery/forms.py changed, reloading.
2023-01-01 12:41:44,208 - [INFO]    django.utils.autoreload: Watching for file changes with StatReloader
2023-01-01 12:57:56,486 - [INFO]    django.utils.autoreload: /usr/src/app/apps/restaurants/models.py changed, reloading.
2023-01-01 12:58:11,419 - [INFO]    django.utils.autoreload: Watching for file changes with StatReloader
2023-01-01 12:58:27,194 - [INFO]    django.utils.autoreload: /usr/src/app/apps/restaurants/models.py changed, reloading.
2023-01-01 12:58:30,514 - [INFO]    django.utils.autoreload: Watching for file changes with StatReloader
2023-01-01 12:58:35,448 - [INFO]    django.utils.autoreload: /usr/src/app/apps/restaurants/models.py changed, reloading.
2023-01-01 12:58:37,934 - [INFO]    django.utils.autoreload: Watching for file changes with StatReloader
2023-01-01 12:59:22,708 - [INFO]    django.utils.autoreload: /usr/src/app/apps/restaurants/models.py changed, reloading.
2023-01-01 12:59:25,762 - [INFO]    django.utils.autoreload: Watching for file changes with StatReloader
2023-01-01 13:04:14,832 - [INFO]    django.channels.server: [mHTTP GET / 200 [3.20, 172.25.0.1:50638][0m
2023-01-01 13:04:51,406 - [INFO]    django.channels.server: [mHTTP GET / 200 [0.23, 172.25.0.1:43324][0m
2023-01-01 13:05:38,103 - [INFO]    django.channels.server: [mHTTP GET / 200 [0.18, 172.25.0.1:41226][0m
2023-01-01 13:05:40,187 - [INFO]    django.channels.server: [mHTTP GET / 200 [0.27, 172.25.0.1:41230][0m
2023-01-01 13:07:04,578 - [INFO]    django.channels.server: [mHTTP GET / 200 [0.61, 172.25.0.1:55366][0m
2023-01-01 13:07:27,704 - [INFO]    django.channels.server: [mHTTP GET /restaurants/?lat=36.3030338&lon=59.6255339 200 [4.00, 172.25.0.1:48204][0m
2023-01-01 13:07:44,480 - [ERROR]    django.request: Internal Server Error: /restaurants/243556bc-a529-40a3-bc7e-7d63f54a4527/
Traceback (most recent call last):
  File "/usr/local/lib/python3.10/site-packages/asgiref/sync.py", line 472, in thread_handler
    raise exc_info[1]
  File "/usr/local/lib/python3.10/site-packages/django/core/handlers/exception.py", line 42, in inner
    response = await get_response(request)
  File "/usr/local/lib/python3.10/site-packages/django/core/handlers/base.py", line 253, in _get_response_async
    response = await wrapped_callback(
  File "/usr/src/app/apps/restaurants/views.py", line 146, in get
    reviews = await sync_to_async(Review.objects.filter)(
  File "/usr/local/lib/python3.10/site-packages/asgiref/sync.py", line 435, in __call__
    ret = await asyncio.wait_for(future, timeout=None)
  File "/usr/local/lib/python3.10/asyncio/tasks.py", line 408, in wait_for
    return await fut
  File "/usr/local/lib/python3.10/site-packages/asgiref/current_thread_executor.py", line 22, in run
    result = self.fn(*self.args, **self.kwargs)
  File "/usr/local/lib/python3.10/site-packages/asgiref/sync.py", line 476, in thread_handler
    return func(*args, **kwargs)
  File "/usr/local/lib/python3.10/site-packages/django/db/models/manager.py", line 85, in manager_method
    return getattr(self.get_queryset(), name)(*args, **kwargs)
  File "/usr/local/lib/python3.10/site-packages/django/db/models/query.py", line 1420, in filter
    return self._filter_or_exclude(False, args, kwargs)
  File "/usr/local/lib/python3.10/site-packages/django/db/models/query.py", line 1438, in _filter_or_exclude
    clone._filter_or_exclude_inplace(negate, args, kwargs)
  File "/usr/local/lib/python3.10/site-packages/django/db/models/query.py", line 1445, in _filter_or_exclude_inplace
    self._query.add_q(Q(*args, **kwargs))
  File "/usr/local/lib/python3.10/site-packages/django/db/models/sql/query.py", line 1532, in add_q
    clause, _ = self._add_q(q_object, self.used_aliases)
  File "/usr/local/lib/python3.10/site-packages/django/db/models/sql/query.py", line 1562, in _add_q
    child_clause, needed_inner = self.build_filter(
  File "/usr/local/lib/python3.10/site-packages/django/db/models/sql/query.py", line 1445, in build_filter
    self.check_related_objects(join_info.final_field, value, join_info.opts)
  File "/usr/local/lib/python3.10/site-packages/django/db/models/sql/query.py", line 1256, in check_related_objects
    self.check_query_object_type(value, opts, field)
  File "/usr/local/lib/python3.10/site-packages/django/db/models/sql/query.py", line 1233, in check_query_object_type
    raise ValueError(
ValueError: Cannot query "Test": Must be "Item" instance.
2023-01-01 13:07:44,727 - [ERROR]    django.channels.server: [35;1mHTTP GET /restaurants/243556bc-a529-40a3-bc7e-7d63f54a4527/ 500 [0.75, 172.25.0.1:35630][0m
2023-01-01 13:10:22,070 - [INFO]    django.utils.autoreload: /usr/src/app/apps/restaurants/views.py changed, reloading.
2023-01-01 13:10:34,179 - [INFO]    django.utils.autoreload: Watching for file changes with StatReloader
2023-01-01 13:10:45,188 - [INFO]    django.channels.server: [mHTTP GET /restaurants/243556bc-a529-40a3-bc7e-7d63f54a4527/ 200 [1.11, 172.25.0.1:60388][0m
2023-01-01 13:11:05,928 - [ERROR]    django.request: Internal Server Error: /delivery/cart/add/
Traceback (most recent call last):
  File "/usr/local/lib/python3.10/site-packages/asgiref/sync.py", line 472, in thread_handler
    raise exc_info[1]
  File "/usr/local/lib/python3.10/site-packages/django/core/handlers/exception.py", line 42, in inner
    response = await get_response(request)
  File "/usr/local/lib/python3.10/site-packages/django/core/handlers/base.py", line 253, in _get_response_async
    response = await wrapped_callback(
  File "/usr/local/lib/python3.10/site-packages/asgiref/sync.py", line 435, in __call__
    ret = await asyncio.wait_for(future, timeout=None)
  File "/usr/local/lib/python3.10/asyncio/tasks.py", line 408, in wait_for
    return await fut
  File "/usr/local/lib/python3.10/site-packages/asgiref/current_thread_executor.py", line 22, in run
    result = self.fn(*self.args, **self.kwargs)
  File "/usr/local/lib/python3.10/site-packages/asgiref/sync.py", line 476, in thread_handler
    return func(*args, **kwargs)
  File "/usr/local/lib/python3.10/site-packages/django/views/generic/base.py", line 103, in view
    return self.dispatch(request, *args, **kwargs)
  File "/usr/local/lib/python3.10/site-packages/django/views/generic/base.py", line 142, in dispatch
    return handler(request, *args, **kwargs)
  File "/usr/src/app/apps/delivery/views.py", line 31, in post
    cart, _ = DeliveryCart.objects.get_or_create(user=self.request.user,
  File "/usr/local/lib/python3.10/site-packages/django/db/models/manager.py", line 85, in manager_method
    return getattr(self.get_queryset(), name)(*args, **kwargs)
  File "/usr/local/lib/python3.10/site-packages/django/db/models/query.py", line 928, in get_or_create
    return self.get(**kwargs), False
  File "/usr/local/lib/python3.10/site-packages/django/db/models/query.py", line 636, in get
    clone = self._chain() if self.query.combinator else self.filter(*args, **kwargs)
  File "/usr/local/lib/python3.10/site-packages/django/db/models/query.py", line 1420, in filter
    return self._filter_or_exclude(False, args, kwargs)
  File "/usr/local/lib/python3.10/site-packages/django/db/models/query.py", line 1438, in _filter_or_exclude
    clone._filter_or_exclude_inplace(negate, args, kwargs)
  File "/usr/local/lib/python3.10/site-packages/django/db/models/query.py", line 1445, in _filter_or_exclude_inplace
    self._query.add_q(Q(*args, **kwargs))
  File "/usr/local/lib/python3.10/site-packages/django/db/models/sql/query.py", line 1532, in add_q
    clause, _ = self._add_q(q_object, self.used_aliases)
  File "/usr/local/lib/python3.10/site-packages/django/db/models/sql/query.py", line 1562, in _add_q
    child_clause, needed_inner = self.build_filter(
  File "/usr/local/lib/python3.10/site-packages/django/db/models/sql/query.py", line 1407, in build_filter
    lookups, parts, reffed_expression = self.solve_lookup_type(arg)
  File "/usr/local/lib/python3.10/site-packages/django/db/models/sql/query.py", line 1217, in solve_lookup_type
    _, field, _, lookup_parts = self.names_to_path(lookup_splitted, self.get_meta())
  File "/usr/local/lib/python3.10/site-packages/django/db/models/sql/query.py", line 1709, in names_to_path
    raise FieldError(
django.core.exceptions.FieldError: Cannot resolve keyword 'paid' into field. Choices are: cart_items, discounts, id, user, user_address, user_address_id, user_id
2023-01-01 13:11:06,149 - [ERROR]    django.channels.server: [35;1mHTTP POST /delivery/cart/add/ 500 [0.34, 172.25.0.1:50232][0m
2023-01-01 13:14:27,646 - [INFO]    django.utils.autoreload: /usr/src/app/apps/delivery/views.py changed, reloading.
2023-01-01 13:14:30,126 - [INFO]    django.utils.autoreload: Watching for file changes with StatReloader
2023-01-01 13:16:32,671 - [INFO]    django.utils.autoreload: /usr/src/app/apps/restaurants/models.py changed, reloading.
2023-01-01 13:16:36,162 - [INFO]    django.utils.autoreload: Watching for file changes with StatReloader
2023-01-01 13:16:53,791 - [INFO]    django.channels.server: [mHTTP POST /delivery/cart/add/ 200 [1.34, 172.25.0.1:43218][0m
2023-01-01 13:17:04,105 - [INFO]    django.channels.server: [mHTTP GET /delivery/cart/ 200 [1.42, 172.25.0.1:47756][0m
2023-01-01 13:17:55,452 - [INFO]    django.channels.server: [mHTTP POST /delivery/cart/ 200 [0.29, 172.25.0.1:54506][0m
2023-01-01 13:45:14,349 - [INFO]    django.channels.server: [mHTTP GET /in_place/menu/ 200 [3.10, 172.25.0.1:45818][0m
2023-01-01 13:45:39,896 - [INFO]    django.channels.server: [32mHTTP POST /in_place/menu/itemvar/create 302 [0.78, 172.25.0.1:43926][0m
2023-01-01 13:45:40,479 - [INFO]    django.channels.server: [mHTTP GET /in_place/menu/ 200 [0.50, 172.25.0.1:43938][0m
2023-01-01 13:46:06,461 - [INFO]    django.channels.server: [mHTTP GET /restaurants/243556bc-a529-40a3-bc7e-7d63f54a4527/ 200 [0.89, 172.25.0.1:59816][0m
2023-01-01 13:46:15,627 - [INFO]    django.channels.server: [mHTTP POST /delivery/cart/add/ 200 [0.35, 172.25.0.1:37218][0m
2023-01-01 14:21:24,188 - [INFO]    django.utils.autoreload: /usr/src/app/apps/delivery/views.py changed, reloading.
2023-01-01 14:22:00,158 - [INFO]    django.utils.autoreload: Watching for file changes with StatReloader
2023-01-01 14:28:25,596 - [INFO]    django.utils.autoreload: /usr/src/app/apps/delivery/views.py changed, reloading.
2023-01-01 14:28:28,209 - [INFO]    django.utils.autoreload: Watching for file changes with StatReloader
2023-01-01 14:31:35,935 - [INFO]    django.utils.autoreload: /usr/src/app/apps/delivery/views.py changed, reloading.
2023-01-01 14:31:39,078 - [INFO]    django.utils.autoreload: Watching for file changes with StatReloader
2023-01-01 14:33:04,798 - [INFO]    django.utils.autoreload: /usr/src/app/apps/delivery/views.py changed, reloading.
2023-01-01 14:33:07,574 - [INFO]    django.utils.autoreload: Watching for file changes with StatReloader
2023-01-01 14:33:30,302 - [INFO]    django.utils.autoreload: /usr/src/app/apps/delivery/urls.py changed, reloading.
2023-01-01 14:33:32,486 - [INFO]    django.utils.autoreload: Watching for file changes with StatReloader
2023-01-01 14:38:25,950 - [INFO]    django.utils.autoreload: /usr/src/app/apps/delivery/urls.py changed, reloading.
2023-01-01 14:38:28,444 - [INFO]    django.utils.autoreload: Watching for file changes with StatReloader
2023-01-01 14:39:08,879 - [INFO]    django.channels.server: [mHTTP GET /delivery/cart/ 200 [8.07, 172.25.0.1:44028][0m
2023-01-01 14:40:29,228 - [ERROR]    django.request: Internal Server Error: /delivery/cart/
Traceback (most recent call last):
  File "/usr/local/lib/python3.10/site-packages/django/template/base.py", line 505, in parse
    compile_func = self.tags[command]
KeyError: 'delivery:purchase'

During handling of the above exception, another exception occurred:

Traceback (most recent call last):
  File "/usr/local/lib/python3.10/site-packages/asgiref/sync.py", line 472, in thread_handler
    raise exc_info[1]
  File "/usr/local/lib/python3.10/site-packages/django/core/handlers/exception.py", line 42, in inner
    response = await get_response(request)
  File "/usr/local/lib/python3.10/site-packages/django/core/handlers/base.py", line 253, in _get_response_async
    response = await wrapped_callback(
  File "/usr/local/lib/python3.10/site-packages/asgiref/sync.py", line 435, in __call__
    ret = await asyncio.wait_for(future, timeout=None)
  File "/usr/local/lib/python3.10/asyncio/tasks.py", line 408, in wait_for
    return await fut
  File "/usr/local/lib/python3.10/site-packages/asgiref/current_thread_executor.py", line 22, in run
    result = self.fn(*self.args, **self.kwargs)
  File "/usr/local/lib/python3.10/site-packages/asgiref/sync.py", line 476, in thread_handler
    return func(*args, **kwargs)
  File "/usr/local/lib/python3.10/site-packages/django/views/generic/base.py", line 103, in view
    return self.dispatch(request, *args, **kwargs)
  File "/usr/local/lib/python3.10/site-packages/django/views/generic/base.py", line 142, in dispatch
    return handler(request, *args, **kwargs)
  File "/usr/src/app/apps/delivery/views.py", line 62, in get
    return render(self.request, self.template_name, self.context)
  File "/usr/local/lib/python3.10/site-packages/django/shortcuts.py", line 24, in render
    content = loader.render_to_string(template_name, context, request, using=using)
  File "/usr/local/lib/python3.10/site-packages/django/template/loader.py", line 61, in render_to_string
    template = get_template(template_name, using=using)
  File "/usr/local/lib/python3.10/site-packages/django/template/loader.py", line 15, in get_template
    return engine.get_template(template_name)
  File "/usr/local/lib/python3.10/site-packages/django/template/backends/django.py", line 34, in get_template
    return Template(self.engine.get_template(template_name), self)
  File "/usr/local/lib/python3.10/site-packages/django/template/engine.py", line 175, in get_template
    template, origin = self.find_template(template_name)
  File "/usr/local/lib/python3.10/site-packages/django/template/engine.py", line 157, in find_template
    template = loader.get_template(name, skip=skip)
  File "/usr/local/lib/python3.10/site-packages/django/template/loaders/cached.py", line 57, in get_template
    template = super().get_template(template_name, skip)
  File "/usr/local/lib/python3.10/site-packages/django/template/loaders/base.py", line 28, in get_template
    return Template(
  File "/usr/local/lib/python3.10/site-packages/django/template/base.py", line 154, in __init__
    self.nodelist = self.compile_nodelist()
  File "/usr/local/lib/python3.10/site-packages/django/template/base.py", line 200, in compile_nodelist
    return parser.parse()
  File "/usr/local/lib/python3.10/site-packages/django/template/base.py", line 513, in parse
    raise self.error(token, e)
  File "/usr/local/lib/python3.10/site-packages/django/template/base.py", line 511, in parse
    compiled_result = compile_func(self, token)
  File "/usr/local/lib/python3.10/site-packages/django/template/loader_tags.py", line 293, in do_extends
    nodelist = parser.parse()
  File "/usr/local/lib/python3.10/site-packages/django/template/base.py", line 513, in parse
    raise self.error(token, e)
  File "/usr/local/lib/python3.10/site-packages/django/template/base.py", line 511, in parse
    compiled_result = compile_func(self, token)
  File "/usr/local/lib/python3.10/site-packages/django/template/loader_tags.py", line 232, in do_block
    nodelist = parser.parse(("endblock",))
  File "/usr/local/lib/python3.10/site-packages/django/template/base.py", line 507, in parse
    self.invalid_block_tag(token, command, parse_until)
  File "/usr/local/lib/python3.10/site-packages/django/template/base.py", line 558, in invalid_block_tag
    raise self.error(
django.template.exceptions.TemplateSyntaxError: Invalid block tag on line 135: 'delivery:purchase', expected 'endblock'. Did you forget to register or load this tag?
2023-01-01 14:40:29,463 - [ERROR]    django.channels.server: [35;1mHTTP GET /delivery/cart/ 500 [0.45, 172.25.0.1:52910][0m
2023-01-01 14:40:41,686 - [INFO]    django.channels.server: [mHTTP GET /delivery/cart/ 200 [0.41, 172.25.0.1:54720][0m
2023-01-01 14:41:00,577 - [ERROR]    django.request: Internal Server Error: /delivery/cart/purchase/
Traceback (most recent call last):
  File "/usr/local/lib/python3.10/site-packages/asgiref/sync.py", line 472, in thread_handler
    raise exc_info[1]
  File "/usr/local/lib/python3.10/site-packages/django/core/handlers/exception.py", line 42, in inner
    response = await get_response(request)
  File "/usr/local/lib/python3.10/site-packages/django/core/handlers/base.py", line 253, in _get_response_async
    response = await wrapped_callback(
  File "/usr/local/lib/python3.10/site-packages/asgiref/sync.py", line 435, in __call__
    ret = await asyncio.wait_for(future, timeout=None)
  File "/usr/local/lib/python3.10/asyncio/tasks.py", line 408, in wait_for
    return await fut
  File "/usr/local/lib/python3.10/site-packages/asgiref/current_thread_executor.py", line 22, in run
    result = self.fn(*self.args, **self.kwargs)
  File "/usr/local/lib/python3.10/site-packages/asgiref/sync.py", line 476, in thread_handler
    return func(*args, **kwargs)
  File "/usr/local/lib/python3.10/site-packages/django/views/generic/base.py", line 103, in view
    return self.dispatch(request, *args, **kwargs)
  File "/usr/local/lib/python3.10/site-packages/django/contrib/auth/mixins.py", line 73, in dispatch
    return super().dispatch(request, *args, **kwargs)
  File "/usr/local/lib/python3.10/site-packages/django/views/generic/base.py", line 142, in dispatch
    return handler(request, *args, **kwargs)
  File "/usr/src/app/apps/delivery/views.py", line 150, in post
    bank.set_client_callback_url(reverse("delivery:home"))
  File "/usr/local/lib/python3.10/site-packages/django/urls/base.py", line 88, in reverse
    return resolver._reverse_with_prefix(view, prefix, *args, **kwargs)
  File "/usr/local/lib/python3.10/site-packages/django/urls/resolvers.py", line 803, in _reverse_with_prefix
    raise NoReverseMatch(msg)
django.urls.exceptions.NoReverseMatch: Reverse for 'home' not found. 'home' is not a valid view function or pattern name.
2023-01-01 14:41:00,787 - [ERROR]    django.channels.server: [35;1mHTTP POST /delivery/cart/purchase/ 500 [1.55, 172.25.0.1:54848][0m
2023-01-01 14:41:44,132 - [INFO]    django.utils.autoreload: /usr/src/app/apps/delivery/views.py changed, reloading.
2023-01-01 14:41:47,515 - [INFO]    django.utils.autoreload: Watching for file changes with StatReloader
2023-01-01 14:41:56,085 - [ERROR]    django.request: Internal Server Error: /delivery/cart/purchase/
Traceback (most recent call last):
  File "/usr/local/lib/python3.10/site-packages/asgiref/sync.py", line 472, in thread_handler
    raise exc_info[1]
  File "/usr/local/lib/python3.10/site-packages/django/core/handlers/exception.py", line 42, in inner
    response = await get_response(request)
  File "/usr/local/lib/python3.10/site-packages/django/core/handlers/base.py", line 253, in _get_response_async
    response = await wrapped_callback(
  File "/usr/local/lib/python3.10/site-packages/asgiref/sync.py", line 435, in __call__
    ret = await asyncio.wait_for(future, timeout=None)
  File "/usr/local/lib/python3.10/asyncio/tasks.py", line 408, in wait_for
    return await fut
  File "/usr/local/lib/python3.10/site-packages/asgiref/current_thread_executor.py", line 22, in run
    result = self.fn(*self.args, **self.kwargs)
  File "/usr/local/lib/python3.10/site-packages/asgiref/sync.py", line 476, in thread_handler
    return func(*args, **kwargs)
  File "/usr/local/lib/python3.10/site-packages/django/views/generic/base.py", line 103, in view
    return self.dispatch(request, *args, **kwargs)
  File "/usr/local/lib/python3.10/site-packages/django/contrib/auth/mixins.py", line 73, in dispatch
    return super().dispatch(request, *args, **kwargs)
  File "/usr/local/lib/python3.10/site-packages/django/views/generic/base.py", line 142, in dispatch
    return handler(request, *args, **kwargs)
  File "/usr/src/app/apps/delivery/views.py", line 150, in post
    bank.set_client_callback_url(reverse("delivery:home"))
  File "/usr/local/lib/python3.10/site-packages/django/urls/base.py", line 88, in reverse
    return resolver._reverse_with_prefix(view, prefix, *args, **kwargs)
  File "/usr/local/lib/python3.10/site-packages/django/urls/resolvers.py", line 803, in _reverse_with_prefix
    raise NoReverseMatch(msg)
django.urls.exceptions.NoReverseMatch: Reverse for 'home' not found. 'home' is not a valid view function or pattern name.
2023-01-01 14:41:56,414 - [ERROR]    django.channels.server: [35;1mHTTP POST /delivery/cart/purchase/ 500 [6.20, 172.25.0.1:57318][0m
2023-01-01 14:43:15,033 - [INFO]    django.utils.autoreload: /usr/src/app/apps/delivery/views.py changed, reloading.
2023-01-01 14:43:17,688 - [INFO]    django.utils.autoreload: Watching for file changes with StatReloader
2023-01-01 14:43:27,833 - [ERROR]    django.request: Internal Server Error: /delivery/cart/purchase/
Traceback (most recent call last):
  File "/usr/local/lib/python3.10/site-packages/asgiref/sync.py", line 472, in thread_handler
    raise exc_info[1]
  File "/usr/local/lib/python3.10/site-packages/django/core/handlers/exception.py", line 42, in inner
    response = await get_response(request)
  File "/usr/local/lib/python3.10/site-packages/django/core/handlers/base.py", line 253, in _get_response_async
    response = await wrapped_callback(
  File "/usr/local/lib/python3.10/site-packages/asgiref/sync.py", line 435, in __call__
    ret = await asyncio.wait_for(future, timeout=None)
  File "/usr/local/lib/python3.10/asyncio/tasks.py", line 408, in wait_for
    return await fut
  File "/usr/local/lib/python3.10/site-packages/asgiref/current_thread_executor.py", line 22, in run
    result = self.fn(*self.args, **self.kwargs)
  File "/usr/local/lib/python3.10/site-packages/asgiref/sync.py", line 476, in thread_handler
    return func(*args, **kwargs)
  File "/usr/local/lib/python3.10/site-packages/django/views/generic/base.py", line 103, in view
    return self.dispatch(request, *args, **kwargs)
  File "/usr/local/lib/python3.10/site-packages/django/contrib/auth/mixins.py", line 73, in dispatch
    return super().dispatch(request, *args, **kwargs)
  File "/usr/local/lib/python3.10/site-packages/django/views/generic/base.py", line 142, in dispatch
    return handler(request, *args, **kwargs)
  File "/usr/src/app/apps/delivery/views.py", line 154, in post
    grouped = group_delivery_items(order_items)
  File "/usr/src/app/apps/delivery/utils.py", line 20, in group_delivery_items
    grouped = [(Restaurant.objects.get(id=k), [*g])
  File "/usr/src/app/apps/delivery/utils.py", line 20, in <listcomp>
    grouped = [(Restaurant.objects.get(id=k), [*g])
AttributeError: 'dict' object has no attribute 'restaurant'
2023-01-01 14:43:28,235 - [ERROR]    django.channels.server: [35;1mHTTP POST /delivery/cart/purchase/ 500 [7.11, 172.25.0.1:37236][0m
2023-01-01 14:43:43,064 - [INFO]    django.utils.autoreload: /usr/src/app/apps/delivery/utils.py changed, reloading.
2023-01-01 14:43:45,627 - [INFO]    django.utils.autoreload: Watching for file changes with StatReloader
2023-01-01 14:43:48,995 - [INFO]    django.utils.autoreload: /usr/src/app/apps/delivery/utils.py changed, reloading.
2023-01-01 14:43:51,393 - [INFO]    django.utils.autoreload: Watching for file changes with StatReloader
2023-01-01 14:44:32,318 - [ERROR]    django.request: Internal Server Error: /delivery/cart/purchase/
Traceback (most recent call last):
  File "/usr/local/lib/python3.10/site-packages/django/db/backends/utils.py", line 89, in _execute
    return self.cursor.execute(sql, params)
psycopg2.errors.UndefinedColumn: column "user_payment_id" of relation "restaurants_order" does not exist
LINE 1: ...e", "restaurant_id", "timestamp", "order_number", "user_paym...
                                                             ^


The above exception was the direct cause of the following exception:

Traceback (most recent call last):
  File "/usr/local/lib/python3.10/site-packages/asgiref/sync.py", line 472, in thread_handler
    raise exc_info[1]
  File "/usr/local/lib/python3.10/site-packages/django/core/handlers/exception.py", line 42, in inner
    response = await get_response(request)
  File "/usr/local/lib/python3.10/site-packages/django/core/handlers/base.py", line 253, in _get_response_async
    response = await wrapped_callback(
  File "/usr/local/lib/python3.10/site-packages/asgiref/sync.py", line 435, in __call__
    ret = await asyncio.wait_for(future, timeout=None)
  File "/usr/local/lib/python3.10/asyncio/tasks.py", line 408, in wait_for
    return await fut
  File "/usr/local/lib/python3.10/site-packages/asgiref/current_thread_executor.py", line 22, in run
    result = self.fn(*self.args, **self.kwargs)
  File "/usr/local/lib/python3.10/site-packages/asgiref/sync.py", line 476, in thread_handler
    return func(*args, **kwargs)
  File "/usr/local/lib/python3.10/site-packages/django/views/generic/base.py", line 103, in view
    return self.dispatch(request, *args, **kwargs)
  File "/usr/local/lib/python3.10/site-packages/django/contrib/auth/mixins.py", line 73, in dispatch
    return super().dispatch(request, *args, **kwargs)
  File "/usr/local/lib/python3.10/site-packages/django/views/generic/base.py", line 142, in dispatch
    return handler(request, *args, **kwargs)
  File "/usr/src/app/apps/delivery/views.py", line 157, in post
    order = Order.objects.create(restaurant=restaurant,
  File "/usr/local/lib/python3.10/site-packages/django/db/models/manager.py", line 85, in manager_method
    return getattr(self.get_queryset(), name)(*args, **kwargs)
  File "/usr/local/lib/python3.10/site-packages/django/db/models/query.py", line 671, in create
    obj.save(force_insert=True, using=self.db)
  File "/usr/src/app/apps/restaurants/models.py", line 474, in save
    super().save(*args, **kwargs)
  File "/usr/local/lib/python3.10/site-packages/django/db/models/base.py", line 831, in save
    self.save_base(
  File "/usr/local/lib/python3.10/site-packages/django/db/models/base.py", line 882, in save_base
    updated = self._save_table(
  File "/usr/local/lib/python3.10/site-packages/django/db/models/base.py", line 1025, in _save_table
    results = self._do_insert(
  File "/usr/local/lib/python3.10/site-packages/django/db/models/base.py", line 1066, in _do_insert
    return manager._insert(
  File "/usr/local/lib/python3.10/site-packages/django/db/models/manager.py", line 85, in manager_method
    return getattr(self.get_queryset(), name)(*args, **kwargs)
  File "/usr/local/lib/python3.10/site-packages/django/db/models/query.py", line 1790, in _insert
    return query.get_compiler(using=using).execute_sql(returning_fields)
  File "/usr/local/lib/python3.10/site-packages/django/db/models/sql/compiler.py", line 1657, in execute_sql
    cursor.execute(sql, params)
  File "/usr/local/lib/python3.10/site-packages/debug_toolbar/panels/sql/tracking.py", line 230, in execute
    return self._record(self.cursor.execute, sql, params)
  File "/usr/local/lib/python3.10/site-packages/debug_toolbar/panels/sql/tracking.py", line 154, in _record
    return method(sql, params)
  File "/usr/local/lib/python3.10/site-packages/django/db/backends/utils.py", line 103, in execute
    return super().execute(sql, params)
  File "/usr/local/lib/python3.10/site-packages/django/db/backends/utils.py", line 67, in execute
    return self._execute_with_wrappers(
  File "/usr/local/lib/python3.10/site-packages/django/db/backends/utils.py", line 80, in _execute_with_wrappers
    return executor(sql, params, many, context)
  File "/usr/local/lib/python3.10/site-packages/django/db/backends/utils.py", line 84, in _execute
    with self.db.wrap_database_errors:
  File "/usr/local/lib/python3.10/site-packages/django/db/utils.py", line 91, in __exit__
    raise dj_exc_value.with_traceback(traceback) from exc_value
  File "/usr/local/lib/python3.10/site-packages/django/db/backends/utils.py", line 89, in _execute
    return self.cursor.execute(sql, params)
django.db.utils.ProgrammingError: column "user_payment_id" of relation "restaurants_order" does not exist
LINE 1: ...e", "restaurant_id", "timestamp", "order_number", "user_paym...
                                                             ^

2023-01-01 14:44:32,684 - [ERROR]    django.channels.server: [35;1mHTTP POST /delivery/cart/purchase/ 500 [2.98, 172.25.0.1:56928][0m
2023-01-01 14:47:37,636 - [WARNING]    django.request: Method Not Allowed (GET): /delivery/cart/purchase/
2023-01-01 14:47:37,819 - [WARNING]    django.request: Method Not Allowed: /delivery/cart/purchase/
2023-01-01 14:47:37,825 - [WARNING]    django.channels.server: [31;1mHTTP GET /delivery/cart/purchase/ 405 [0.22, 172.25.0.1:47790][0m
2023-01-01 14:47:56,598 - [ERROR]    django.request: Internal Server Error: /delivery/cart/purchase/
Traceback (most recent call last):
  File "/usr/local/lib/python3.10/site-packages/urllib3/connection.py", line 174, in _new_conn
    conn = connection.create_connection(
  File "/usr/local/lib/python3.10/site-packages/urllib3/util/connection.py", line 72, in create_connection
    for res in socket.getaddrinfo(host, port, family, socket.SOCK_STREAM):
  File "/usr/local/lib/python3.10/socket.py", line 955, in getaddrinfo
    for res in _socket.getaddrinfo(host, port, family, type, proto, flags):
socket.gaierror: [Errno -2] Name or service not known

During handling of the above exception, another exception occurred:

Traceback (most recent call last):
  File "/usr/local/lib/python3.10/site-packages/elasticsearch/connection/http_urllib3.py", line 255, in perform_request
    response = self.pool.urlopen(
  File "/usr/local/lib/python3.10/site-packages/urllib3/connectionpool.py", line 785, in urlopen
    retries = retries.increment(
  File "/usr/local/lib/python3.10/site-packages/urllib3/util/retry.py", line 525, in increment
    raise six.reraise(type(error), error, _stacktrace)
  File "/usr/local/lib/python3.10/site-packages/urllib3/packages/six.py", line 770, in reraise
    raise value
  File "/usr/local/lib/python3.10/site-packages/urllib3/connectionpool.py", line 703, in urlopen
    httplib_response = self._make_request(
  File "/usr/local/lib/python3.10/site-packages/urllib3/connectionpool.py", line 398, in _make_request
    conn.request(method, url, **httplib_request_kw)
  File "/usr/local/lib/python3.10/site-packages/urllib3/connection.py", line 239, in request
    super(HTTPConnection, self).request(method, url, body=body, headers=headers)
  File "/usr/local/lib/python3.10/http/client.py", line 1282, in request
    self._send_request(method, url, body, headers, encode_chunked)
  File "/usr/local/lib/python3.10/http/client.py", line 1328, in _send_request
    self.endheaders(body, encode_chunked=encode_chunked)
  File "/usr/local/lib/python3.10/http/client.py", line 1277, in endheaders
    self._send_output(message_body, encode_chunked=encode_chunked)
  File "/usr/local/lib/python3.10/http/client.py", line 1037, in _send_output
    self.send(msg)
  File "/usr/local/lib/python3.10/http/client.py", line 975, in send
    self.connect()
  File "/usr/local/lib/python3.10/site-packages/urllib3/connection.py", line 205, in connect
    conn = self._new_conn()
  File "/usr/local/lib/python3.10/site-packages/urllib3/connection.py", line 186, in _new_conn
    raise NewConnectionError(
urllib3.exceptions.NewConnectionError: <urllib3.connection.HTTPConnection object at 0x7f5d344a1e70>: Failed to establish a new connection: [Errno -2] Name or service not known

During handling of the above exception, another exception occurred:

Traceback (most recent call last):
  File "/usr/local/lib/python3.10/site-packages/asgiref/sync.py", line 472, in thread_handler
    raise exc_info[1]
  File "/usr/local/lib/python3.10/site-packages/django/core/handlers/exception.py", line 42, in inner
    response = await get_response(request)
  File "/usr/local/lib/python3.10/site-packages/django/core/handlers/base.py", line 253, in _get_response_async
    response = await wrapped_callback(
  File "/usr/local/lib/python3.10/site-packages/asgiref/sync.py", line 435, in __call__
    ret = await asyncio.wait_for(future, timeout=None)
  File "/usr/local/lib/python3.10/asyncio/tasks.py", line 408, in wait_for
    return await fut
  File "/usr/local/lib/python3.10/site-packages/asgiref/current_thread_executor.py", line 22, in run
    result = self.fn(*self.args, **self.kwargs)
  File "/usr/local/lib/python3.10/site-packages/asgiref/sync.py", line 476, in thread_handler
    return func(*args, **kwargs)
  File "/usr/local/lib/python3.10/site-packages/django/views/generic/base.py", line 103, in view
    return self.dispatch(request, *args, **kwargs)
  File "/usr/local/lib/python3.10/site-packages/django/contrib/auth/mixins.py", line 73, in dispatch
    return super().dispatch(request, *args, **kwargs)
  File "/usr/local/lib/python3.10/site-packages/django/views/generic/base.py", line 142, in dispatch
    return handler(request, *args, **kwargs)
  File "/usr/src/app/apps/delivery/views.py", line 157, in post
    order = Order.objects.create(restaurant=restaurant,
  File "/usr/local/lib/python3.10/site-packages/django/db/models/manager.py", line 85, in manager_method
    return getattr(self.get_queryset(), name)(*args, **kwargs)
  File "/usr/local/lib/python3.10/site-packages/django/db/models/query.py", line 671, in create
    obj.save(force_insert=True, using=self.db)
  File "/usr/src/app/apps/restaurants/models.py", line 474, in save
    super().save(*args, **kwargs)
  File "/usr/local/lib/python3.10/site-packages/django/db/models/base.py", line 831, in save
    self.save_base(
  File "/usr/local/lib/python3.10/site-packages/django/db/models/base.py", line 897, in save_base
    post_save.send(
  File "/usr/local/lib/python3.10/site-packages/django/dispatch/dispatcher.py", line 176, in send
    return [
  File "/usr/local/lib/python3.10/site-packages/django/dispatch/dispatcher.py", line 177, in <listcomp>
    (receiver, receiver(signal=self, sender=sender, **named))
  File "/usr/local/lib/python3.10/site-packages/django_elasticsearch_dsl/signals.py", line 58, in handle_save
    registry.update(instance)
  File "/usr/local/lib/python3.10/site-packages/django_elasticsearch_dsl/registries.py", line 141, in update
    doc().update(instance, **kwargs)
  File "/usr/local/lib/python3.10/site-packages/django_elasticsearch_dsl/documents.py", line 225, in update
    return self._bulk(
  File "/usr/local/lib/python3.10/site-packages/django_elasticsearch_dsl/documents.py", line 202, in _bulk
    return self.bulk(*args, **kwargs)
  File "/usr/local/lib/python3.10/site-packages/django_elasticsearch_dsl/documents.py", line 151, in bulk
    response = bulk(client=self._get_connection(), actions=actions, **kwargs)
  File "/usr/local/lib/python3.10/site-packages/elasticsearch/helpers/actions.py", line 410, in bulk
    for ok, item in streaming_bulk(
  File "/usr/local/lib/python3.10/site-packages/elasticsearch/helpers/actions.py", line 329, in streaming_bulk
    for data, (ok, info) in zip(
  File "/usr/local/lib/python3.10/site-packages/elasticsearch/helpers/actions.py", line 256, in _process_bulk_chunk
    for item in gen:
  File "/usr/local/lib/python3.10/site-packages/elasticsearch/helpers/actions.py", line 195, in _process_bulk_chunk_error
    raise error
  File "/usr/local/lib/python3.10/site-packages/elasticsearch/helpers/actions.py", line 240, in _process_bulk_chunk
    resp = client.bulk(*args, body="\n".join(bulk_actions) + "\n", **kwargs)
  File "/usr/local/lib/python3.10/site-packages/elasticsearch/client/utils.py", line 347, in _wrapped
    return func(*args, params=params, headers=headers, **kwargs)
  File "/usr/local/lib/python3.10/site-packages/elasticsearch/client/__init__.py", line 472, in bulk
    return self.transport.perform_request(
  File "/usr/local/lib/python3.10/site-packages/elasticsearch/transport.py", line 417, in perform_request
    self._do_verify_elasticsearch(headers=headers, timeout=timeout)
  File "/usr/local/lib/python3.10/site-packages/elasticsearch/transport.py", line 606, in _do_verify_elasticsearch
    raise error
  File "/usr/local/lib/python3.10/site-packages/elasticsearch/transport.py", line 569, in _do_verify_elasticsearch
    _, info_headers, info_response = conn.perform_request(
  File "/usr/local/lib/python3.10/site-packages/elasticsearch/connection/http_urllib3.py", line 280, in perform_request
    raise ConnectionError("N/A", str(e), e)
elasticsearch.exceptions.ConnectionError: ConnectionError(<urllib3.connection.HTTPConnection object at 0x7f5d344a1e70>: Failed to establish a new connection: [Errno -2] Name or service not known) caused by: NewConnectionError(<urllib3.connection.HTTPConnection object at 0x7f5d344a1e70>: Failed to establish a new connection: [Errno -2] Name or service not known)
2023-01-01 14:47:57,056 - [ERROR]    django.channels.server: [35;1mHTTP POST /delivery/cart/purchase/ 500 [2.82, 172.25.0.1:58496][0m
2023-01-01 14:49:16,317 - [ERROR]    django.request: Internal Server Error: /delivery/cart/purchase/
Traceback (most recent call last):
  File "/usr/local/lib/python3.10/site-packages/urllib3/connection.py", line 174, in _new_conn
    conn = connection.create_connection(
  File "/usr/local/lib/python3.10/site-packages/urllib3/util/connection.py", line 72, in create_connection
    for res in socket.getaddrinfo(host, port, family, socket.SOCK_STREAM):
  File "/usr/local/lib/python3.10/socket.py", line 955, in getaddrinfo
    for res in _socket.getaddrinfo(host, port, family, type, proto, flags):
socket.gaierror: [Errno -2] Name or service not known

During handling of the above exception, another exception occurred:

Traceback (most recent call last):
  File "/usr/local/lib/python3.10/site-packages/elasticsearch/connection/http_urllib3.py", line 255, in perform_request
    response = self.pool.urlopen(
  File "/usr/local/lib/python3.10/site-packages/urllib3/connectionpool.py", line 785, in urlopen
    retries = retries.increment(
  File "/usr/local/lib/python3.10/site-packages/urllib3/util/retry.py", line 525, in increment
    raise six.reraise(type(error), error, _stacktrace)
  File "/usr/local/lib/python3.10/site-packages/urllib3/packages/six.py", line 770, in reraise
    raise value
  File "/usr/local/lib/python3.10/site-packages/urllib3/connectionpool.py", line 703, in urlopen
    httplib_response = self._make_request(
  File "/usr/local/lib/python3.10/site-packages/urllib3/connectionpool.py", line 398, in _make_request
    conn.request(method, url, **httplib_request_kw)
  File "/usr/local/lib/python3.10/site-packages/urllib3/connection.py", line 239, in request
    super(HTTPConnection, self).request(method, url, body=body, headers=headers)
  File "/usr/local/lib/python3.10/http/client.py", line 1282, in request
    self._send_request(method, url, body, headers, encode_chunked)
  File "/usr/local/lib/python3.10/http/client.py", line 1328, in _send_request
    self.endheaders(body, encode_chunked=encode_chunked)
  File "/usr/local/lib/python3.10/http/client.py", line 1277, in endheaders
    self._send_output(message_body, encode_chunked=encode_chunked)
  File "/usr/local/lib/python3.10/http/client.py", line 1037, in _send_output
    self.send(msg)
  File "/usr/local/lib/python3.10/http/client.py", line 975, in send
    self.connect()
  File "/usr/local/lib/python3.10/site-packages/urllib3/connection.py", line 205, in connect
    conn = self._new_conn()
  File "/usr/local/lib/python3.10/site-packages/urllib3/connection.py", line 186, in _new_conn
    raise NewConnectionError(
urllib3.exceptions.NewConnectionError: <urllib3.connection.HTTPConnection object at 0x7f5d2eee5f90>: Failed to establish a new connection: [Errno -2] Name or service not known

During handling of the above exception, another exception occurred:

Traceback (most recent call last):
  File "/usr/local/lib/python3.10/site-packages/asgiref/sync.py", line 472, in thread_handler
    raise exc_info[1]
  File "/usr/local/lib/python3.10/site-packages/django/core/handlers/exception.py", line 42, in inner
    response = await get_response(request)
  File "/usr/local/lib/python3.10/site-packages/django/core/handlers/base.py", line 253, in _get_response_async
    response = await wrapped_callback(
  File "/usr/local/lib/python3.10/site-packages/asgiref/sync.py", line 435, in __call__
    ret = await asyncio.wait_for(future, timeout=None)
  File "/usr/local/lib/python3.10/asyncio/tasks.py", line 408, in wait_for
    return await fut
  File "/usr/local/lib/python3.10/site-packages/asgiref/current_thread_executor.py", line 22, in run
    result = self.fn(*self.args, **self.kwargs)
  File "/usr/local/lib/python3.10/site-packages/asgiref/sync.py", line 476, in thread_handler
    return func(*args, **kwargs)
  File "/usr/local/lib/python3.10/site-packages/django/views/generic/base.py", line 103, in view
    return self.dispatch(request, *args, **kwargs)
  File "/usr/local/lib/python3.10/site-packages/django/contrib/auth/mixins.py", line 73, in dispatch
    return super().dispatch(request, *args, **kwargs)
  File "/usr/local/lib/python3.10/site-packages/django/views/generic/base.py", line 142, in dispatch
    return handler(request, *args, **kwargs)
  File "/usr/src/app/apps/delivery/views.py", line 157, in post
    order = Order.objects.create(restaurant=restaurant,
  File "/usr/local/lib/python3.10/site-packages/django/db/models/manager.py", line 85, in manager_method
    return getattr(self.get_queryset(), name)(*args, **kwargs)
  File "/usr/local/lib/python3.10/site-packages/django/db/models/query.py", line 671, in create
    obj.save(force_insert=True, using=self.db)
  File "/usr/src/app/apps/restaurants/models.py", line 474, in save
    super().save(*args, **kwargs)
  File "/usr/local/lib/python3.10/site-packages/django/db/models/base.py", line 831, in save
    self.save_base(
  File "/usr/local/lib/python3.10/site-packages/django/db/models/base.py", line 897, in save_base
    post_save.send(
  File "/usr/local/lib/python3.10/site-packages/django/dispatch/dispatcher.py", line 176, in send
    return [
  File "/usr/local/lib/python3.10/site-packages/django/dispatch/dispatcher.py", line 177, in <listcomp>
    (receiver, receiver(signal=self, sender=sender, **named))
  File "/usr/local/lib/python3.10/site-packages/django_elasticsearch_dsl/signals.py", line 58, in handle_save
    registry.update(instance)
  File "/usr/local/lib/python3.10/site-packages/django_elasticsearch_dsl/registries.py", line 141, in update
    doc().update(instance, **kwargs)
  File "/usr/local/lib/python3.10/site-packages/django_elasticsearch_dsl/documents.py", line 225, in update
    return self._bulk(
  File "/usr/local/lib/python3.10/site-packages/django_elasticsearch_dsl/documents.py", line 202, in _bulk
    return self.bulk(*args, **kwargs)
  File "/usr/local/lib/python3.10/site-packages/django_elasticsearch_dsl/documents.py", line 151, in bulk
    response = bulk(client=self._get_connection(), actions=actions, **kwargs)
  File "/usr/local/lib/python3.10/site-packages/elasticsearch/helpers/actions.py", line 410, in bulk
    for ok, item in streaming_bulk(
  File "/usr/local/lib/python3.10/site-packages/elasticsearch/helpers/actions.py", line 329, in streaming_bulk
    for data, (ok, info) in zip(
  File "/usr/local/lib/python3.10/site-packages/elasticsearch/helpers/actions.py", line 256, in _process_bulk_chunk
    for item in gen:
  File "/usr/local/lib/python3.10/site-packages/elasticsearch/helpers/actions.py", line 195, in _process_bulk_chunk_error
    raise error
  File "/usr/local/lib/python3.10/site-packages/elasticsearch/helpers/actions.py", line 240, in _process_bulk_chunk
    resp = client.bulk(*args, body="\n".join(bulk_actions) + "\n", **kwargs)
  File "/usr/local/lib/python3.10/site-packages/elasticsearch/client/utils.py", line 347, in _wrapped
    return func(*args, params=params, headers=headers, **kwargs)
  File "/usr/local/lib/python3.10/site-packages/elasticsearch/client/__init__.py", line 472, in bulk
    return self.transport.perform_request(
  File "/usr/local/lib/python3.10/site-packages/elasticsearch/transport.py", line 417, in perform_request
    self._do_verify_elasticsearch(headers=headers, timeout=timeout)
  File "/usr/local/lib/python3.10/site-packages/elasticsearch/transport.py", line 606, in _do_verify_elasticsearch
    raise error
  File "/usr/local/lib/python3.10/site-packages/elasticsearch/transport.py", line 569, in _do_verify_elasticsearch
    _, info_headers, info_response = conn.perform_request(
  File "/usr/local/lib/python3.10/site-packages/elasticsearch/connection/http_urllib3.py", line 280, in perform_request
    raise ConnectionError("N/A", str(e), e)
elasticsearch.exceptions.ConnectionError: ConnectionError(<urllib3.connection.HTTPConnection object at 0x7f5d2eee5f90>: Failed to establish a new connection: [Errno -2] Name or service not known) caused by: NewConnectionError(<urllib3.connection.HTTPConnection object at 0x7f5d2eee5f90>: Failed to establish a new connection: [Errno -2] Name or service not known)
2023-01-01 14:49:16,640 - [ERROR]    django.channels.server: [35;1mHTTP POST /delivery/cart/purchase/ 500 [2.39, 172.25.0.1:34610][0m
