2022-12-30 13:45:50,585 - [INFO]    django.utils.autoreload: Watching for file changes with StatReloader
2022-12-30 13:51:03,418 - [INFO]    django.channels.server: [mHTTP GET /bankgateways/sample-payment/ 200 [1.76, 172.20.0.1:39598][0m
2022-12-30 13:51:16,689 - [ERROR]    django.request: Internal Server Error: /bankgateways/sample-payment/
Traceback (most recent call last):
  File "/usr/local/lib/python3.10/site-packages/asgiref/sync.py", line 472, in thread_handler
    raise exc_info[1]
  File "/usr/local/lib/python3.10/site-packages/django/core/handlers/exception.py", line 42, in inner
    response = await get_response(request)
  File "/usr/local/lib/python3.10/site-packages/django/core/handlers/base.py", line 253, in _get_response_async
    response = await wrapped_callback(
  File "/usr/local/lib/python3.10/site-packages/asgiref/sync.py", line 435, in __call__
    ret = await asyncio.wait_for(future, timeout=None)
  File "/usr/local/lib/python3.10/asyncio/tasks.py", line 408, in wait_for
    return await fut
  File "/usr/local/lib/python3.10/site-packages/asgiref/current_thread_executor.py", line 22, in run
    result = self.fn(*self.args, **self.kwargs)
  File "/usr/local/lib/python3.10/site-packages/asgiref/sync.py", line 476, in thread_handler
    return func(*args, **kwargs)
  File "/usr/local/lib/python3.10/site-packages/azbankgateways/views/samples.py", line 45, in sample_payment_view
    raise e
  File "/usr/local/lib/python3.10/site-packages/azbankgateways/views/samples.py", line 27, in sample_payment_view
    bank = factory.auto_create()
  File "/usr/local/lib/python3.10/site-packages/azbankgateways/bankfactories.py", line 67, in auto_create
    raise BankGatewayAutoConnectionFailed()
azbankgateways.exceptions.exceptions.BankGatewayAutoConnectionFailed
2022-12-30 13:51:16,962 - [ERROR]    django.channels.server: [35;1mHTTP POST /bankgateways/sample-payment/ 500 [0.50, 172.20.0.1:36148][0m
2022-12-30 14:01:31,576 - [INFO]    django.utils.autoreload: /usr/src/app/conf/settings.py changed, reloading.
2022-12-30 14:01:46,439 - [INFO]    django.utils.autoreload: Watching for file changes with StatReloader
2022-12-30 14:03:00,920 - [INFO]    django.channels.server: [32mHTTP POST /bankgateways/sample-payment/ 302 [2.90, 172.20.0.1:39326][0m
2022-12-30 14:03:09,257 - [INFO]    django.channels.server: [mHTTP GET /bankgateways/sample-payment/ 200 [0.62, 172.20.0.1:55902][0m
2022-12-30 14:03:21,421 - [INFO]    django.channels.server: [32mHTTP POST /bankgateways/sample-payment/ 302 [7.45, 172.20.0.1:55910][0m
2022-12-30 14:11:33,932 - [INFO]    django.channels.server: [mHTTP GET /bankgateways/go-to-bank-gateway/ 200 [0.25, 172.20.0.1:37960][0m
2022-12-30 14:11:35,951 - [INFO]    django.channels.server: [mHTTP GET /bankgateways/go-to-bank-gateway/?csrfmiddlewaretoken=eaIrN2su0XaWKWrGGbpIuHWXOrBgO0bw9bHAnZ0yhQ5KxDd7aUjrPy3gWYNh06WZ 200 [0.31, 172.20.0.1:37972][0m
2022-12-30 14:11:39,203 - [INFO]    django.channels.server: [mHTTP GET /bankgateways/go-to-bank-gateway/?csrfmiddlewaretoken=Z8of4A5sXFuRmYpvRtESX21lCDCctXVlU9noExDweypF9FbWlcyBiT8EKaOdF3GO&csrfmiddlewaretoken=eaIrN2su0XaWKWrGGbpIuHWXOrBgO0bw9bHAnZ0yhQ5KxDd7aUjrPy3gWYNh06WZ 200 [0.27, 172.20.0.1:33568][0m
2022-12-30 14:11:40,776 - [INFO]    django.channels.server: [mHTTP GET /bankgateways/go-to-bank-gateway/?csrfmiddlewaretoken=RElDPdfpsTSiIempKNH3cJspAneEw82uMFkMpaNtJMN6vV8QewBMxAzIIUqFIeNX&csrfmiddlewaretoken=eaIrN2su0XaWKWrGGbpIuHWXOrBgO0bw9bHAnZ0yhQ5KxDd7aUjrPy3gWYNh06WZ 200 [0.24, 172.20.0.1:33572][0m
2022-12-30 14:11:46,368 - [INFO]    django.channels.server: [mHTTP GET /bankgateways/sample-payment/ 200 [0.39, 172.20.0.1:33574][0m
2022-12-30 14:11:53,095 - [INFO]    django.channels.server: [32mHTTP POST /bankgateways/sample-payment/ 302 [2.80, 172.20.0.1:33770][0m
2022-12-30 14:33:40,750 - [WARNING]    django.request: Not Found: /google.com
2022-12-30 14:34:09,179 - [WARNING]    django.request: Not Found: /in_placedashboard
2022-12-30 14:36:35,756 - [INFO]    django.channels.server: [mHTTP GET /bankgateways/sample-payment/ 200 [4.48, 172.20.0.1:46178][0m
2022-12-30 14:36:41,955 - [INFO]    django.channels.server: [mHTTP GET /bankgateways/sample-payment/ 200 [0.21, 172.20.0.1:46770][0m
2022-12-30 14:36:42,933 - [INFO]    django.channels.server: [mHTTP GET /static/debug_toolbar/css/toolbar.css 200 [0.74, 172.20.0.1:46770][0m
2022-12-30 14:36:42,966 - [INFO]    django.channels.server: [mHTTP GET /static/debug_toolbar/js/toolbar.js 200 [0.77, 172.20.0.1:46782][0m
2022-12-30 14:36:42,990 - [INFO]    django.channels.server: [mHTTP GET /static/debug_toolbar/js/toolbar.js 200 [0.00, 172.20.0.1:46792][0m
2022-12-30 14:36:43,204 - [INFO]    django.channels.server: [mHTTP GET /static/debug_toolbar/js/utils.js 200 [0.04, 172.20.0.1:46770][0m
2022-12-30 14:36:43,235 - [INFO]    django.channels.server: [mHTTP GET /static/debug_toolbar/js/utils.js 200 [0.01, 172.20.0.1:46792][0m
2022-12-30 14:36:43,523 - [WARNING]    django.request: Not Found: /sw.js
2022-12-30 14:36:43,527 - [WARNING]    django.channels.server: [33mHTTP GET /sw.js 404 [0.36, 172.20.0.1:46782][0m
2022-12-30 14:36:44,443 - [WARNING]    django.request: Not Found: /sw.js
2022-12-30 14:36:44,446 - [WARNING]    django.channels.server: [33mHTTP GET /sw.js 404 [0.31, 172.20.0.1:46770][0m
2022-12-30 14:36:44,774 - [INFO]    django.channels.server: [mHTTP GET /static/debug_toolbar/css/print.css 200 [0.06, 172.20.0.1:46808][0m
2022-12-30 14:36:46,781 - [WARNING]    django.request: Not Found: /sw.js
2022-12-30 14:36:46,788 - [WARNING]    django.channels.server: [33mHTTP GET /sw.js 404 [0.31, 172.20.0.1:46808][0m
2022-12-30 14:36:47,349 - [INFO]    django.channels.server: [32mHTTP POST /bankgateways/sample-payment/ 302 [2.66, 172.20.0.1:46806][0m
2022-12-30 14:36:47,925 - [INFO]    django.channels.server: [mHTTP GET /bankgateways/go-to-bank-gateway/?url=https%3A%2F%2Fidpay.ir%2Fp%2Fws-sandbox%2F2aa63ba59af7a068714e1529cb04e5b2&method=GET 200 [0.53, 172.20.0.1:46806][0m
2022-12-30 14:36:48,579 - [WARNING]    django.request: Not Found: /favicon.ico
2022-12-30 14:36:48,584 - [WARNING]    django.channels.server: [33mHTTP GET /favicon.ico 404 [0.30, 172.20.0.1:46806][0m
2022-12-30 14:36:48,863 - [WARNING]    django.request: Not Found: /sw.js
2022-12-30 14:36:48,981 - [WARNING]    django.channels.server: [33mHTTP GET /sw.js 404 [0.50, 172.20.0.1:44562][0m
2022-12-30 15:12:17,850 - [INFO]    django.utils.autoreload: /usr/src/app/conf/settings.py changed, reloading.
2022-12-30 15:12:43,308 - [INFO]    django.utils.autoreload: Watching for file changes with StatReloader
2022-12-30 15:13:09,804 - [WARNING]    django.request: Not Found: /sw.js
2022-12-30 15:13:09,810 - [WARNING]    django.channels.server: [33mHTTP GET /sw.js 404 [0.43, 172.20.0.1:40738][0m
2022-12-30 15:13:10,688 - [INFO]    django.channels.server: [mHTTP GET /bankgateways/sample-payment/ 200 [2.78, 172.20.0.1:59702][0m
2022-12-30 15:13:10,998 - [INFO]    django.channels.server: [mHTTP GET /static/debug_toolbar/css/toolbar.css 200 [0.02, 172.20.0.1:59702][0m
2022-12-30 15:13:11,008 - [INFO]    django.channels.server: [mHTTP GET /static/debug_toolbar/js/toolbar.js 200 [0.03, 172.20.0.1:40744][0m
2022-12-30 15:13:11,107 - [INFO]    django.channels.server: [mHTTP GET /static/debug_toolbar/js/toolbar.js 200 [0.01, 172.20.0.1:40756][0m
2022-12-30 15:13:11,278 - [INFO]    django.channels.server: [mHTTP GET /static/debug_toolbar/js/utils.js 200 [0.00, 172.20.0.1:40744][0m
2022-12-30 15:13:11,296 - [INFO]    django.channels.server: [mHTTP GET /static/debug_toolbar/js/utils.js 200 [0.00, 172.20.0.1:40756][0m
2022-12-30 15:13:13,812 - [INFO]    django.channels.server: [mHTTP GET /static/debug_toolbar/css/print.css 200 [0.01, 172.20.0.1:59702][0m
2022-12-30 15:13:14,119 - [WARNING]    django.request: Not Found: /sw.js
2022-12-30 15:13:14,124 - [WARNING]    django.channels.server: [33mHTTP GET /sw.js 404 [0.42, 172.20.0.1:40744][0m
2022-12-30 15:13:15,241 - [WARNING]    django.request: Not Found: /sw.js
2022-12-30 15:13:15,247 - [WARNING]    django.channels.server: [33mHTTP GET /sw.js 404 [0.29, 172.20.0.1:59702][0m
2022-12-30 15:13:21,408 - [INFO]    django.channels.server: [mHTTP GET /bankgateways/sample-payment/ 200 [0.49, 172.20.0.1:58842][0m
2022-12-30 15:13:31,568 - [INFO]    django.channels.server: [32mHTTP POST /bankgateways/sample-payment/ 302 [2.17, 172.20.0.1:43212][0m
2022-12-30 15:13:43,482 - [INFO]    django.channels.server: [mHTTP GET /bankgateways/sample-payment/ 200 [0.22, 172.20.0.1:47924][0m
2022-12-30 15:23:25,760 - [INFO]    django.channels.server: [mHTTP GET /bankgateways/sample-payment/ 200 [0.47, 172.20.0.1:32982][0m
2022-12-30 15:23:30,831 - [INFO]    django.channels.server: [32mHTTP POST /bankgateways/sample-payment/ 302 [2.19, 172.20.0.1:60416][0m
2022-12-30 15:23:31,233 - [INFO]    django.channels.server: [mHTTP GET /bankgateways/go-to-bank-gateway/?url=https%3A%2F%2Fidpay.ir%2Fp%2Fws-sandbox%2F6c6b5aa54e2bfb9c70187a906049e96d&method=GET 200 [0.35, 172.20.0.1:60430][0m
2022-12-30 15:23:54,339 - [INFO]    django.channels.server: [mHTTP GET /bankgateways/sample-payment/ 200 [0.22, 172.20.0.1:40344][0m
2022-12-30 15:23:56,492 - [INFO]    django.channels.server: [mHTTP GET /bankgateways/sample-payment/ 200 [0.23, 172.20.0.1:40354][0m
2022-12-30 15:24:23,789 - [INFO]    django.channels.server: [32mHTTP POST /bankgateways/sample-payment/ 302 [1.88, 172.20.0.1:35376][0m
2022-12-30 15:24:24,148 - [INFO]    django.channels.server: [mHTTP GET /bankgateways/go-to-bank-gateway/?url=https%3A%2F%2Fidpay.ir%2Fp%2Fws-sandbox%2F0c67ceeea5c242b25e73651510191f5b&method=GET 200 [0.19, 172.20.0.1:35386][0m
2022-12-30 15:24:28,618 - [INFO]    django.channels.server: [mHTTP GET /bankgateways/sample-payment/ 200 [0.23, 172.20.0.1:44182][0m
2022-12-30 15:24:34,116 - [INFO]    django.channels.server: [mHTTP GET /bankgateways/sample-payment/ 200 [0.31, 172.20.0.1:44194][0m
2022-12-30 15:24:34,309 - [INFO]    django.channels.server: [mHTTP GET /static/debug_toolbar/css/toolbar.css 200 [0.00, 172.20.0.1:44194][0m
2022-12-30 15:24:34,347 - [INFO]    django.channels.server: [mHTTP GET /static/debug_toolbar/js/toolbar.js 200 [0.03, 172.20.0.1:44210][0m
2022-12-30 15:24:34,881 - [INFO]    django.channels.server: [mHTTP GET /static/debug_toolbar/js/utils.js 200 [0.01, 172.20.0.1:44210][0m
2022-12-30 15:24:34,941 - [INFO]    django.channels.server: [mHTTP GET /static/debug_toolbar/css/print.css 200 [0.00, 172.20.0.1:44210][0m
2022-12-30 15:24:36,008 - [WARNING]    django.request: Not Found: /sw.js
2022-12-30 15:24:36,014 - [WARNING]    django.channels.server: [33mHTTP GET /sw.js 404 [0.23, 172.20.0.1:44210][0m
2022-12-30 15:24:37,818 - [WARNING]    django.request: Not Found: /sw.js
2022-12-30 15:24:37,822 - [WARNING]    django.channels.server: [33mHTTP GET /sw.js 404 [0.22, 172.20.0.1:44218][0m
2022-12-30 15:24:38,277 - [INFO]    django.channels.server: [32mHTTP POST /bankgateways/sample-payment/ 302 [2.10, 172.20.0.1:44194][0m
2022-12-30 15:24:39,421 - [INFO]    django.channels.server: [mHTTP GET /bankgateways/go-to-bank-gateway/?url=https%3A%2F%2Fidpay.ir%2Fp%2Fws-sandbox%2F05d0d3d41b52825487a2e48a47d98242&method=GET 200 [0.19, 172.20.0.1:44194][0m
2022-12-30 15:24:40,624 - [WARNING]    django.request: Not Found: /sw.js
2022-12-30 15:24:40,628 - [WARNING]    django.channels.server: [33mHTTP GET /sw.js 404 [0.39, 172.20.0.1:44194][0m
2022-12-30 15:24:41,685 - [WARNING]    django.request: Not Found: /sw.js
2022-12-30 15:24:41,690 - [WARNING]    django.channels.server: [33mHTTP GET /sw.js 404 [0.28, 172.20.0.1:38842][0m
2022-12-30 15:24:49,131 - [INFO]    django.channels.server: [mHTTP GET /bankgateways/sample-payment/ 200 [0.20, 172.20.0.1:41422][0m
2022-12-30 15:24:50,279 - [WARNING]    django.request: Not Found: /sw.js
2022-12-30 15:24:50,284 - [WARNING]    django.channels.server: [33mHTTP GET /sw.js 404 [0.26, 172.20.0.1:41422][0m
2022-12-30 15:24:51,766 - [WARNING]    django.request: Not Found: /sw.js
2022-12-30 15:24:51,772 - [WARNING]    django.channels.server: [33mHTTP GET /sw.js 404 [0.27, 172.20.0.1:41430][0m
2022-12-30 15:37:51,915 - [INFO]    django.channels.server: [mHTTP GET /bankgateways/sample-payment/ 200 [0.85, 172.20.0.1:35832][0m
2022-12-30 15:40:10,886 - [INFO]    django.channels.server: [32mHTTP POST /bankgateways/sample-payment/ 302 [2.48, 172.20.0.1:59044][0m
2022-12-30 15:40:11,150 - [INFO]    django.channels.server: [mHTTP GET /bankgateways/go-to-bank-gateway/?url=https%3A%2F%2Fidpay.ir%2Fp%2Fws-sandbox%2Fb5b725f39579d3a2b1885b6eeee8f79a&method=GET 200 [0.24, 172.20.0.1:59048][0m
2022-12-30 15:40:37,010 - [INFO]    django.channels.server: [32mHTTP POST /bankgateways/callback/?bank_type=IDPAY&identifier=1 302 [1.14, 172.20.0.1:54572][0m
2022-12-30 15:40:38,337 - [INFO]    django.channels.server: [mHTTP GET /bankgateways/sample-result/?tc=6416629667051087 200 [0.39, 172.20.0.1:54582][0m
2022-12-30 15:43:41,311 - [INFO]    django.utils.autoreload: /usr/src/app/conf/settings.py changed, reloading.
2022-12-30 15:44:13,366 - [INFO]    django.utils.autoreload: Watching for file changes with StatReloader
2022-12-30 15:44:36,383 - [INFO]    django.channels.server: [mHTTP GET /bankgateways/sample-payment/ 200 [0.75, 172.20.0.1:38374][0m
2022-12-30 15:44:40,039 - [ERROR]    django.request: Internal Server Error: /bankgateways/sample-payment/
Traceback (most recent call last):
  File "/usr/local/lib/python3.10/site-packages/asgiref/sync.py", line 472, in thread_handler
    raise exc_info[1]
  File "/usr/local/lib/python3.10/site-packages/django/core/handlers/exception.py", line 42, in inner
    response = await get_response(request)
  File "/usr/local/lib/python3.10/site-packages/django/core/handlers/base.py", line 253, in _get_response_async
    response = await wrapped_callback(
  File "/usr/local/lib/python3.10/site-packages/asgiref/sync.py", line 435, in __call__
    ret = await asyncio.wait_for(future, timeout=None)
  File "/usr/local/lib/python3.10/asyncio/tasks.py", line 408, in wait_for
    return await fut
  File "/usr/local/lib/python3.10/site-packages/asgiref/current_thread_executor.py", line 22, in run
    result = self.fn(*self.args, **self.kwargs)
  File "/usr/local/lib/python3.10/site-packages/asgiref/sync.py", line 476, in thread_handler
    return func(*args, **kwargs)
  File "/usr/local/lib/python3.10/site-packages/azbankgateways/views/samples.py", line 45, in sample_payment_view
    raise e
  File "/usr/local/lib/python3.10/site-packages/azbankgateways/views/samples.py", line 27, in sample_payment_view
    bank = factory.auto_create()
  File "/usr/local/lib/python3.10/site-packages/azbankgateways/bankfactories.py", line 67, in auto_create
    raise BankGatewayAutoConnectionFailed()
azbankgateways.exceptions.exceptions.BankGatewayAutoConnectionFailed
2022-12-30 15:44:40,242 - [ERROR]    django.channels.server: [35;1mHTTP POST /bankgateways/sample-payment/ 500 [0.45, 172.20.0.1:37974][0m
2022-12-30 16:17:15,577 - [INFO]    django.utils.autoreload: /usr/src/app/conf/settings.py changed, reloading.
2022-12-30 16:18:02,154 - [INFO]    django.utils.autoreload: Watching for file changes with StatReloader
2022-12-30 16:23:19,054 - [INFO]    django.utils.autoreload: /usr/src/app/conf/settings.py changed, reloading.
2022-12-30 16:23:23,030 - [INFO]    django.utils.autoreload: Watching for file changes with StatReloader
2022-12-30 16:24:14,439 - [ERROR]    django.request: Internal Server Error: /bankgateways/sample-payment/
Traceback (most recent call last):
  File "/usr/local/lib/python3.10/site-packages/asgiref/sync.py", line 472, in thread_handler
    raise exc_info[1]
  File "/usr/local/lib/python3.10/site-packages/django/core/handlers/exception.py", line 42, in inner
    response = await get_response(request)
  File "/usr/local/lib/python3.10/site-packages/django/core/handlers/base.py", line 253, in _get_response_async
    response = await wrapped_callback(
  File "/usr/local/lib/python3.10/site-packages/asgiref/sync.py", line 435, in __call__
    ret = await asyncio.wait_for(future, timeout=None)
  File "/usr/local/lib/python3.10/asyncio/tasks.py", line 408, in wait_for
    return await fut
  File "/usr/local/lib/python3.10/site-packages/asgiref/current_thread_executor.py", line 22, in run
    result = self.fn(*self.args, **self.kwargs)
  File "/usr/local/lib/python3.10/site-packages/asgiref/sync.py", line 476, in thread_handler
    return func(*args, **kwargs)
  File "/usr/local/lib/python3.10/site-packages/azbankgateways/views/samples.py", line 45, in sample_payment_view
    raise e
  File "/usr/local/lib/python3.10/site-packages/azbankgateways/views/samples.py", line 27, in sample_payment_view
    bank = factory.auto_create()
  File "/usr/local/lib/python3.10/site-packages/azbankgateways/bankfactories.py", line 67, in auto_create
    raise BankGatewayAutoConnectionFailed()
azbankgateways.exceptions.exceptions.BankGatewayAutoConnectionFailed
2022-12-30 16:24:14,874 - [ERROR]    django.channels.server: [35;1mHTTP POST /bankgateways/sample-payment/ 500 [1.45, 172.20.0.1:45116][0m
2022-12-30 16:25:35,654 - [INFO]    django.utils.autoreload: /usr/src/app/conf/settings.py changed, reloading.
2022-12-30 16:25:38,441 - [INFO]    django.utils.autoreload: Watching for file changes with StatReloader
2022-12-30 16:25:42,116 - [ERROR]    django.request: Internal Server Error: /bankgateways/sample-payment/
Traceback (most recent call last):
  File "/usr/local/lib/python3.10/site-packages/asgiref/sync.py", line 472, in thread_handler
    raise exc_info[1]
  File "/usr/local/lib/python3.10/site-packages/django/core/handlers/exception.py", line 42, in inner
    response = await get_response(request)
  File "/usr/local/lib/python3.10/site-packages/django/core/handlers/base.py", line 253, in _get_response_async
    response = await wrapped_callback(
  File "/usr/local/lib/python3.10/site-packages/asgiref/sync.py", line 435, in __call__
    ret = await asyncio.wait_for(future, timeout=None)
  File "/usr/local/lib/python3.10/asyncio/tasks.py", line 408, in wait_for
    return await fut
  File "/usr/local/lib/python3.10/site-packages/asgiref/current_thread_executor.py", line 22, in run
    result = self.fn(*self.args, **self.kwargs)
  File "/usr/local/lib/python3.10/site-packages/asgiref/sync.py", line 476, in thread_handler
    return func(*args, **kwargs)
  File "/usr/local/lib/python3.10/site-packages/azbankgateways/views/samples.py", line 45, in sample_payment_view
    raise e
  File "/usr/local/lib/python3.10/site-packages/azbankgateways/views/samples.py", line 27, in sample_payment_view
    bank = factory.auto_create()
  File "/usr/local/lib/python3.10/site-packages/azbankgateways/bankfactories.py", line 67, in auto_create
    raise BankGatewayAutoConnectionFailed()
azbankgateways.exceptions.exceptions.BankGatewayAutoConnectionFailed
2022-12-30 16:25:42,324 - [ERROR]    django.channels.server: [35;1mHTTP POST /bankgateways/sample-payment/ 500 [0.69, 172.20.0.1:60482][0m
2022-12-30 16:25:48,777 - [INFO]    django.channels.server: [mHTTP GET /bankgateways/sample-payment/ 200 [1.38, 172.20.0.1:60490][0m
2022-12-30 16:25:50,220 - [INFO]    django.channels.server: [mHTTP GET /bankgateways/sample-payment/ 200 [0.20, 172.20.0.1:33744][0m
2022-12-30 16:25:53,233 - [ERROR]    django.request: Internal Server Error: /bankgateways/sample-payment/
Traceback (most recent call last):
  File "/usr/local/lib/python3.10/site-packages/asgiref/sync.py", line 472, in thread_handler
    raise exc_info[1]
  File "/usr/local/lib/python3.10/site-packages/django/core/handlers/exception.py", line 42, in inner
    response = await get_response(request)
  File "/usr/local/lib/python3.10/site-packages/django/core/handlers/base.py", line 253, in _get_response_async
    response = await wrapped_callback(
  File "/usr/local/lib/python3.10/site-packages/asgiref/sync.py", line 435, in __call__
    ret = await asyncio.wait_for(future, timeout=None)
  File "/usr/local/lib/python3.10/asyncio/tasks.py", line 408, in wait_for
    return await fut
  File "/usr/local/lib/python3.10/site-packages/asgiref/current_thread_executor.py", line 22, in run
    result = self.fn(*self.args, **self.kwargs)
  File "/usr/local/lib/python3.10/site-packages/asgiref/sync.py", line 476, in thread_handler
    return func(*args, **kwargs)
  File "/usr/local/lib/python3.10/site-packages/azbankgateways/views/samples.py", line 45, in sample_payment_view
    raise e
  File "/usr/local/lib/python3.10/site-packages/azbankgateways/views/samples.py", line 27, in sample_payment_view
    bank = factory.auto_create()
  File "/usr/local/lib/python3.10/site-packages/azbankgateways/bankfactories.py", line 67, in auto_create
    raise BankGatewayAutoConnectionFailed()
azbankgateways.exceptions.exceptions.BankGatewayAutoConnectionFailed
2022-12-30 16:25:53,604 - [ERROR]    django.channels.server: [35;1mHTTP POST /bankgateways/sample-payment/ 500 [0.87, 172.20.0.1:33748][0m
2022-12-31 04:47:15,265 - [INFO]    django.utils.autoreload: Watching for file changes with StatReloader
2022-12-31 05:00:34,293 - [INFO]    django.channels.server: [mHTTP GET / 200 [8.13, 172.20.0.1:45036][0m
2022-12-31 05:01:06,593 - [INFO]    django.channels.server: [mHTTP GET / 200 [0.20, 172.20.0.1:52794][0m
2022-12-31 05:01:10,393 - [WARNING]    django.request: Not Found: /sw.js
2022-12-31 05:01:10,397 - [WARNING]    django.channels.server: [33mHTTP GET /sw.js 404 [0.57, 172.20.0.1:52796][0m
2022-12-31 05:01:13,689 - [INFO]    django.channels.server: [mHTTP GET / 200 [0.21, 172.20.0.1:52798][0m
2022-12-31 05:01:14,676 - [WARNING]    django.request: Not Found: /sw.js
2022-12-31 05:01:14,681 - [WARNING]    django.channels.server: [33mHTTP GET /sw.js 404 [0.19, 172.20.0.1:52806][0m
2022-12-31 05:01:23,027 - [INFO]    django.channels.server: [mHTTP GET /static/assets/css/nucleo-icons.css 200 [0.84, 172.20.0.1:52798][0m
2022-12-31 05:01:23,047 - [INFO]    django.channels.server: [mHTTP GET /static/assets/css/nucleo-svg.css 200 [0.86, 172.20.0.1:52794][0m
2022-12-31 05:01:23,118 - [INFO]    django.channels.server: [mHTTP GET /static/assets/css/material-kit.css 200 [0.92, 172.20.0.1:56528][0m
2022-12-31 05:01:23,207 - [INFO]    django.channels.server: [mHTTP GET /static/assets/css/badge.css 200 [1.01, 172.20.0.1:56532][0m
2022-12-31 05:01:23,303 - [INFO]    django.channels.server: [mHTTP GET /static/assets/css/autocomplete.css 200 [1.11, 172.20.0.1:56534][0m
2022-12-31 05:01:23,381 - [INFO]    django.channels.server: [mHTTP GET /static/assets/js/core/popper.min.js 200 [1.18, 172.20.0.1:56542][0m
2022-12-31 05:01:23,460 - [INFO]    django.channels.server: [mHTTP GET /static/assets/js/core/bootstrap.min.js 200 [0.43, 172.20.0.1:52798][0m
2022-12-31 05:01:23,538 - [INFO]    django.channels.server: [mHTTP GET /static/assets/js/plugins/perfect-scrollbar.min.js 200 [0.49, 172.20.0.1:52794][0m
2022-12-31 05:01:23,619 - [INFO]    django.channels.server: [mHTTP GET /static/assets/js/material-kit.min.js 200 [0.49, 172.20.0.1:56528][0m
2022-12-31 05:01:23,672 - [INFO]    django.channels.server: [mHTTP GET /static/assets/js/plugins/parallax.min.js 200 [0.45, 172.20.0.1:56532][0m
2022-12-31 05:01:23,768 - [ERROR]    django.channels.server: [35;1mHTTP GET /static/assets/js/plugins/choices.min.js 500 [0.31, 172.20.0.1:52798][0m
2022-12-31 05:01:23,791 - [INFO]    django.channels.server: [mHTTP GET /static/assets/js/autocomplete.js 200 [0.48, 172.20.0.1:56534][0m
2022-12-31 05:01:23,820 - [INFO]    django.channels.server: [mHTTP GET /static/assets/js/plugins/countup.min.js 200 [0.42, 172.20.0.1:56542][0m
2022-12-31 05:01:23,862 - [INFO]    django.channels.server: [mHTTP GET /static/assets/js/plugins/prism.min.js 200 [0.32, 172.20.0.1:52794][0m
2022-12-31 05:01:23,910 - [INFO]    django.channels.server: [mHTTP GET /static/assets/js/plugins/highlight.min.js 200 [0.28, 172.20.0.1:56528][0m
2022-12-31 05:01:23,945 - [INFO]    django.channels.server: [mHTTP GET /static/assets/js/plugins/rellax.min.js 200 [0.26, 172.20.0.1:56532][0m
2022-12-31 05:01:23,984 - [INFO]    django.channels.server: [mHTTP GET /static/assets/js/plugins/tilt.min.js 200 [0.21, 172.20.0.1:52798][0m
2022-12-31 05:01:24,017 - [INFO]    django.channels.server: [mHTTP GET /static/assets/js/core/jquery.min.js 200 [0.22, 172.20.0.1:56534][0m
2022-12-31 05:01:24,083 - [INFO]    django.channels.server: [mHTTP GET /static/debug_toolbar/js/toolbar.js 200 [0.21, 172.20.0.1:52794][0m
2022-12-31 05:01:24,778 - [ERROR]    django.channels.server: [35;1mHTTP GET /static/debug_toolbar/css/toolbar.css 500 [0.96, 172.20.0.1:56542][0m
2022-12-31 05:01:24,840 - [INFO]    django.channels.server: [mHTTP GET /static/assets/img/down-arrow-dark.svg 200 [0.05, 172.20.0.1:56528][0m
2022-12-31 05:01:24,902 - [INFO]    django.channels.server: [mHTTP GET /static/assets/img/logo-ct-dark.png 200 [0.11, 172.20.0.1:56534][0m
2022-12-31 05:01:25,012 - [WARNING]    django.request: Not Found: /sw.js
2022-12-31 05:01:25,020 - [WARNING]    django.channels.server: [33mHTTP GET /sw.js 404 [0.23, 172.20.0.1:56532][0m
2022-12-31 05:01:28,166 - [INFO]    django.channels.server: [mHTTP GET /static/debug_toolbar/js/utils.js 200 [0.05, 172.20.0.1:56528][0m
2022-12-31 05:01:29,859 - [WARNING]    django.request: Not Found: /sw.js
2022-12-31 05:01:29,866 - [WARNING]    django.channels.server: [33mHTTP GET /sw.js 404 [0.19, 172.20.0.1:56528][0m
2022-12-31 05:01:41,234 - [WARNING]    django.request: Not Found: /sw.js
2022-12-31 05:01:41,237 - [WARNING]    django.channels.server: [33mHTTP GET /sw.js 404 [0.20, 172.20.0.1:56534][0m
2022-12-31 05:01:42,342 - [INFO]    django.channels.server: [mHTTP GET /static/assets/img/bg2.jpg 200 [0.08, 172.20.0.1:56542][0m
2022-12-31 05:01:43,498 - [WARNING]    django.request: Not Found: /sw.js
2022-12-31 05:01:43,502 - [WARNING]    django.channels.server: [33mHTTP GET /sw.js 404 [0.23, 172.20.0.1:52798][0m
2022-12-31 05:01:43,672 - [INFO]    django.channels.server: [mHTTP GET /static/assets/js/plugins/choices.min.js 200 [1.03, 172.20.0.1:56542][0m
2022-12-31 05:01:47,715 - [INFO]    django.channels.server: [mHTTP GET /static/assets/img/apple-icon.png 200 [0.05, 172.20.0.1:56542][0m
2022-12-31 05:01:47,771 - [INFO]    django.channels.server: [mHTTP GET /static/assets/img/favicon.png 200 [0.11, 172.20.0.1:52794][0m
2022-12-31 05:01:48,866 - [WARNING]    django.request: Not Found: /sw.js
2022-12-31 05:01:48,872 - [WARNING]    django.channels.server: [33mHTTP GET /sw.js 404 [0.19, 172.20.0.1:56542][0m
2022-12-31 05:01:51,465 - [WARNING]    django.request: Not Found: /sw.js
2022-12-31 05:01:51,471 - [WARNING]    django.channels.server: [33mHTTP GET /sw.js 404 [0.21, 172.20.0.1:52794][0m
2022-12-31 05:01:52,648 - [WARNING]    django.request: Not Found: /sw.js
2022-12-31 05:01:52,653 - [WARNING]    django.channels.server: [33mHTTP GET /sw.js 404 [0.21, 172.20.0.1:37604][0m
2022-12-31 05:01:53,414 - [INFO]    django.channels.server: [mHTTP GET /static/debug_toolbar/css/print.css 200 [0.03, 172.20.0.1:37614][0m
2022-12-31 05:01:53,459 - [INFO]    django.channels.server: [mHTTP GET /static/debug_toolbar/css/toolbar.css 200 [0.07, 172.20.0.1:37628][0m
2022-12-31 05:01:54,487 - [WARNING]    django.request: Not Found: /sw.js
2022-12-31 05:01:54,496 - [WARNING]    django.channels.server: [33mHTTP GET /sw.js 404 [0.19, 172.20.0.1:37628][0m
2022-12-31 05:02:04,986 - [WARNING]    django.request: Not Found: /sw.js
2022-12-31 05:02:04,990 - [WARNING]    django.channels.server: [33mHTTP GET /sw.js 404 [0.26, 172.20.0.1:37614][0m
2022-12-31 05:02:20,315 - [INFO]    django.channels.server: [mHTTP GET / 200 [0.23, 172.20.0.1:38890][0m
2022-12-31 05:03:44,300 - [INFO]    django.channels.server: [mHTTP GET / 200 [1.29, 172.20.0.1:56178][0m
2022-12-31 05:14:31,281 - [INFO]    django.utils.autoreload: Watching for file changes with StatReloader
2022-12-31 05:41:59,709 - [INFO]    django.channels.server: [mHTTP GET / 200 [3.55, 172.20.0.1:39766][0m
2022-12-31 05:42:14,177 - [WARNING]    django.request: Not Found: /cart
2022-12-31 05:42:14,180 - [WARNING]    django.channels.server: [33mHTTP GET /cart 404 [0.38, 172.20.0.1:52884][0m
2022-12-31 05:42:21,524 - [INFO]    django.channels.server: [mHTTP GET / 200 [0.56, 172.20.0.1:58582][0m
2022-12-31 05:42:23,581 - [INFO]    django.channels.server: [mHTTP GET /static/assets/css/nucleo-icons.css 200 [0.06, 172.20.0.1:58582][0m
2022-12-31 05:42:23,634 - [INFO]    django.channels.server: [mHTTP GET /static/assets/css/nucleo-svg.css 200 [0.09, 172.20.0.1:58590][0m
2022-12-31 05:42:23,816 - [INFO]    django.channels.server: [mHTTP GET /static/assets/css/badge.css 200 [0.27, 172.20.0.1:58604][0m
2022-12-31 05:42:23,876 - [INFO]    django.channels.server: [mHTTP GET /static/assets/css/autocomplete.css 200 [0.32, 172.20.0.1:58612][0m
2022-12-31 05:42:24,024 - [INFO]    django.channels.server: [mHTTP GET /static/assets/js/core/popper.min.js 200 [0.47, 172.20.0.1:58628][0m
2022-12-31 05:42:24,125 - [INFO]    django.channels.server: [mHTTP GET /static/assets/js/plugins/perfect-scrollbar.min.js 200 [0.54, 172.20.0.1:58582][0m
2022-12-31 05:42:24,229 - [INFO]    django.channels.server: [mHTTP GET /static/assets/js/material-kit.min.js 200 [0.49, 172.20.0.1:58590][0m
2022-12-31 05:42:24,256 - [INFO]    django.channels.server: [mHTTP GET /static/assets/js/core/bootstrap.min.js 200 [0.48, 172.20.0.1:58644][0m
2022-12-31 05:42:24,281 - [INFO]    django.channels.server: [mHTTP GET /static/assets/js/plugins/parallax.min.js 200 [0.46, 172.20.0.1:58604][0m
2022-12-31 05:42:24,295 - [INFO]    django.channels.server: [mHTTP GET /static/assets/js/autocomplete.js 200 [0.41, 172.20.0.1:58612][0m
2022-12-31 05:42:24,351 - [INFO]    django.channels.server: [mHTTP GET /static/assets/js/plugins/countup.min.js 200 [0.32, 172.20.0.1:58628][0m
2022-12-31 05:42:24,490 - [INFO]    django.channels.server: [mHTTP GET /static/assets/js/plugins/choices.min.js 200 [0.36, 172.20.0.1:58582][0m
2022-12-31 05:42:24,560 - [INFO]    django.channels.server: [mHTTP GET /static/assets/js/plugins/prism.min.js 200 [0.32, 172.20.0.1:58590][0m
2022-12-31 05:42:24,642 - [INFO]    django.channels.server: [mHTTP GET /static/assets/js/plugins/highlight.min.js 200 [0.38, 172.20.0.1:58644][0m
2022-12-31 05:42:24,688 - [INFO]    django.channels.server: [mHTTP GET /static/assets/js/plugins/rellax.min.js 200 [0.40, 172.20.0.1:58604][0m
2022-12-31 05:42:24,783 - [INFO]    django.channels.server: [mHTTP GET /static/assets/js/plugins/tilt.min.js 200 [0.48, 172.20.0.1:58612][0m
2022-12-31 05:42:24,828 - [INFO]    django.channels.server: [mHTTP GET /static/assets/js/core/jquery.min.js 200 [0.47, 172.20.0.1:58628][0m
2022-12-31 05:42:24,881 - [INFO]    django.channels.server: [mHTTP GET /static/debug_toolbar/css/toolbar.css 200 [0.39, 172.20.0.1:58582][0m
2022-12-31 05:42:24,926 - [INFO]    django.channels.server: [mHTTP GET /static/debug_toolbar/js/toolbar.js 200 [0.36, 172.20.0.1:58590][0m
2022-12-31 05:42:25,008 - [INFO]    django.channels.server: [mHTTP GET /static/assets/img/down-arrow-dark.svg 200 [0.12, 172.20.0.1:58628][0m
2022-12-31 05:42:25,033 - [INFO]    django.channels.server: [mHTTP GET /static/assets/img/logo-ct-dark.png 200 [0.15, 172.20.0.1:58644][0m
2022-12-31 05:42:28,003 - [INFO]    django.channels.server: [mHTTP GET /static/debug_toolbar/js/utils.js 200 [0.03, 172.20.0.1:58644][0m
2022-12-31 05:42:28,202 - [WARNING]    django.request: Not Found: /sw.js
2022-12-31 05:42:28,210 - [WARNING]    django.channels.server: [33mHTTP GET /sw.js 404 [0.31, 172.20.0.1:58628][0m
2022-12-31 05:42:31,503 - [INFO]    django.channels.server: [mHTTP GET /static/debug_toolbar/css/print.css 200 [0.05, 172.20.0.1:58612][0m
2022-12-31 05:42:32,604 - [WARNING]    django.request: Not Found: /sw.js
2022-12-31 05:42:32,609 - [WARNING]    django.channels.server: [33mHTTP GET /sw.js 404 [0.30, 172.20.0.1:58612][0m
2022-12-31 05:42:33,125 - [INFO]    django.channels.server: [mHTTP GET /static/assets/img/apple-icon.png 200 [0.02, 172.20.0.1:58590][0m
2022-12-31 05:42:33,237 - [INFO]    django.channels.server: [mHTTP GET /static/assets/img/favicon.png 200 [0.13, 172.20.0.1:58604][0m
2022-12-31 05:42:34,057 - [WARNING]    django.request: Not Found: /sw.js
2022-12-31 05:42:34,060 - [WARNING]    django.channels.server: [33mHTTP GET /sw.js 404 [0.22, 172.20.0.1:58590][0m
2022-12-31 05:42:37,023 - [INFO]    django.channels.server: [32mHTTP GET /delivery/cart 301 [0.19, 172.20.0.1:52974][0m
2022-12-31 05:42:41,795 - [WARNING]    django.request: Not Found: /cart
2022-12-31 05:42:41,802 - [WARNING]    django.channels.server: [33mHTTP GET /cart 404 [0.26, 172.20.0.1:52986][0m
2022-12-31 05:43:02,465 - [WARNING]    django.request: Not Found: /cart
2022-12-31 05:43:02,468 - [WARNING]    django.channels.server: [33mHTTP GET /cart 404 [0.18, 172.20.0.1:50204][0m
2022-12-31 05:43:27,889 - [INFO]    django.channels.server: [mHTTP GET /delivery/cart/ 200 [0.22, 172.20.0.1:58220][0m
2022-12-31 05:43:33,777 - [INFO]    django.channels.server: [mHTTP GET /delivery/cart/ 200 [0.18, 172.20.0.1:58232][0m
2022-12-31 05:44:26,410 - [INFO]    django.channels.server: [mHTTP GET / 200 [0.23, 172.20.0.1:56200][0m
2022-12-31 05:44:26,828 - [INFO]    django.channels.server: [mHTTP GET /static/assets/js/core/popper.min.js 200 [0.00, 172.20.0.1:56200][0m
2022-12-31 05:44:27,964 - [WARNING]    django.request: Not Found: /sw.js
2022-12-31 05:44:27,971 - [WARNING]    django.channels.server: [33mHTTP GET /sw.js 404 [0.27, 172.20.0.1:56252][0m
2022-12-31 05:44:28,675 - [WARNING]    django.request: Not Found: /sw.js
2022-12-31 05:44:28,680 - [WARNING]    django.channels.server: [33mHTTP GET /sw.js 404 [0.33, 172.20.0.1:56268][0m
2022-12-31 05:44:30,642 - [WARNING]    django.request: Not Found: /sw.js
2022-12-31 05:44:30,646 - [WARNING]    django.channels.server: [33mHTTP GET /sw.js 404 [0.25, 172.20.0.1:56270][0m
2022-12-31 05:44:32,787 - [INFO]    django.channels.server: [mHTTP GET /bankgateways/sample-payment/ 200 [0.39, 172.20.0.1:56272][0m
2022-12-31 05:44:33,652 - [WARNING]    django.request: Not Found: /sw.js
2022-12-31 05:44:33,655 - [WARNING]    django.channels.server: [33mHTTP GET /sw.js 404 [0.32, 172.20.0.1:56284][0m
2022-12-31 05:44:35,082 - [WARNING]    django.request: Not Found: /sw.js
2022-12-31 05:44:35,088 - [WARNING]    django.channels.server: [33mHTTP GET /sw.js 404 [0.23, 172.20.0.1:39476][0m
2022-12-31 05:44:39,569 - [WARNING]    django.request: Not Found: /sw.js
2022-12-31 05:44:39,573 - [WARNING]    django.channels.server: [33mHTTP GET /sw.js 404 [0.26, 172.20.0.1:39500][0m
2022-12-31 05:44:39,661 - [ERROR]    django.request: Internal Server Error: /bankgateways/sample-payment/
Traceback (most recent call last):
  File "/usr/local/lib/python3.10/site-packages/asgiref/sync.py", line 472, in thread_handler
    raise exc_info[1]
  File "/usr/local/lib/python3.10/site-packages/django/core/handlers/exception.py", line 42, in inner
    response = await get_response(request)
  File "/usr/local/lib/python3.10/site-packages/django/core/handlers/base.py", line 253, in _get_response_async
    response = await wrapped_callback(
  File "/usr/local/lib/python3.10/site-packages/asgiref/sync.py", line 435, in __call__
    ret = await asyncio.wait_for(future, timeout=None)
  File "/usr/local/lib/python3.10/asyncio/tasks.py", line 408, in wait_for
    return await fut
  File "/usr/local/lib/python3.10/site-packages/asgiref/current_thread_executor.py", line 22, in run
    result = self.fn(*self.args, **self.kwargs)
  File "/usr/local/lib/python3.10/site-packages/asgiref/sync.py", line 476, in thread_handler
    return func(*args, **kwargs)
  File "/usr/local/lib/python3.10/site-packages/azbankgateways/views/samples.py", line 45, in sample_payment_view
    raise e
  File "/usr/local/lib/python3.10/site-packages/azbankgateways/views/samples.py", line 27, in sample_payment_view
    bank = factory.auto_create()
  File "/usr/local/lib/python3.10/site-packages/azbankgateways/bankfactories.py", line 67, in auto_create
    raise BankGatewayAutoConnectionFailed()
azbankgateways.exceptions.exceptions.BankGatewayAutoConnectionFailed
2022-12-31 05:44:39,954 - [ERROR]    django.channels.server: [35;1mHTTP POST /bankgateways/sample-payment/ 500 [2.43, 172.20.0.1:39486][0m
2022-12-31 05:44:41,448 - [WARNING]    django.request: Not Found: /sw.js
2022-12-31 05:44:41,451 - [WARNING]    django.channels.server: [33mHTTP GET /sw.js 404 [0.22, 172.20.0.1:39486][0m
2022-12-31 05:44:48,795 - [INFO]    django.utils.autoreload: /usr/src/app/apps/delivery/views.py changed, reloading.
2022-12-31 05:44:59,321 - [INFO]    django.utils.autoreload: Watching for file changes with StatReloader
2022-12-31 05:46:22,114 - [WARNING]    django.request: Not Found: /sw.js
2022-12-31 05:46:22,118 - [WARNING]    django.channels.server: [33mHTTP GET /sw.js 404 [1.40, 172.20.0.1:47220][0m
2022-12-31 05:49:25,655 - [WARNING]    django.request: Not Found: /sw.js
2022-12-31 05:49:25,663 - [WARNING]    django.channels.server: [33mHTTP GET /sw.js 404 [0.36, 172.20.0.1:34878][0m
2022-12-31 05:49:27,095 - [ERROR]    django.request: Internal Server Error: /bankgateways/sample-payment/
Traceback (most recent call last):
  File "/usr/local/lib/python3.10/site-packages/asgiref/sync.py", line 472, in thread_handler
    raise exc_info[1]
  File "/usr/local/lib/python3.10/site-packages/django/core/handlers/exception.py", line 42, in inner
    response = await get_response(request)
  File "/usr/local/lib/python3.10/site-packages/django/core/handlers/base.py", line 253, in _get_response_async
    response = await wrapped_callback(
  File "/usr/local/lib/python3.10/site-packages/asgiref/sync.py", line 435, in __call__
    ret = await asyncio.wait_for(future, timeout=None)
  File "/usr/local/lib/python3.10/asyncio/tasks.py", line 408, in wait_for
    return await fut
  File "/usr/local/lib/python3.10/site-packages/asgiref/current_thread_executor.py", line 22, in run
    result = self.fn(*self.args, **self.kwargs)
  File "/usr/local/lib/python3.10/site-packages/asgiref/sync.py", line 476, in thread_handler
    return func(*args, **kwargs)
  File "/usr/local/lib/python3.10/site-packages/azbankgateways/views/samples.py", line 45, in sample_payment_view
    raise e
  File "/usr/local/lib/python3.10/site-packages/azbankgateways/views/samples.py", line 27, in sample_payment_view
    bank = factory.auto_create()
  File "/usr/local/lib/python3.10/site-packages/azbankgateways/bankfactories.py", line 67, in auto_create
    raise BankGatewayAutoConnectionFailed()
azbankgateways.exceptions.exceptions.BankGatewayAutoConnectionFailed
2022-12-31 05:49:27,335 - [ERROR]    django.channels.server: [35;1mHTTP POST /bankgateways/sample-payment/ 500 [2.22, 172.20.0.1:34876][0m
2022-12-31 05:49:28,910 - [WARNING]    django.request: Not Found: /sw.js
2022-12-31 05:49:28,914 - [WARNING]    django.channels.server: [33mHTTP GET /sw.js 404 [0.22, 172.20.0.1:34876][0m
2022-12-31 05:51:36,854 - [WARNING]    django.request: Not Found: /sw.js
2022-12-31 05:51:37,229 - [WARNING]    django.channels.server: [33mHTTP GET /sw.js 404 [5.16, 172.20.0.1:48516][0m
2022-12-31 05:51:37,813 - [INFO]    django.channels.server: [mHTTP GET / 200 [7.13, 172.20.0.1:48502][0m
2022-12-31 05:51:39,531 - [WARNING]    django.request: Not Found: /sw.js
2022-12-31 05:51:39,537 - [WARNING]    django.channels.server: [33mHTTP GET /sw.js 404 [0.28, 172.20.0.1:59690][0m
2022-12-31 05:51:41,500 - [WARNING]    django.request: Not Found: /sw.js
2022-12-31 05:51:41,505 - [WARNING]    django.channels.server: [33mHTTP GET /sw.js 404 [0.28, 172.20.0.1:59736][0m
2022-12-31 05:51:42,041 - [WARNING]    django.request: Not Found: /sw.js
2022-12-31 05:51:42,045 - [WARNING]    django.channels.server: [33mHTTP GET /sw.js 404 [0.19, 172.20.0.1:59752][0m
2022-12-31 06:00:33,843 - [INFO]    django.utils.autoreload: Watching for file changes with StatReloader
2022-12-31 15:45:59,996 - [INFO]    django.utils.autoreload: Watching for file changes with StatReloader
2023-01-01 01:20:51,647 - [INFO]    django.utils.autoreload: Watching for file changes with StatReloader
2023-01-01 01:21:02,446 - [WARNING]    django.request: Not Found: /sw.js
2023-01-01 01:21:02,452 - [WARNING]    django.channels.server: [33mHTTP GET /sw.js 404 [0.67, 172.20.0.1:60012][0m
2023-01-01 01:21:02,752 - [INFO]    django.channels.server: [mHTTP GET / 200 [2.30, 172.20.0.1:60010][0m
2023-01-01 01:21:03,533 - [INFO]    django.channels.server: [mHTTP GET /static/assets/css/nucleo-icons.css 200 [0.28, 172.20.0.1:60010][0m
2023-01-01 01:21:03,906 - [INFO]    django.channels.server: [mHTTP GET /static/assets/css/nucleo-svg.css 200 [0.01, 172.20.0.1:60022][0m
2023-01-01 01:21:03,955 - [INFO]    django.channels.server: [mHTTP GET /static/assets/css/badge.css 200 [0.04, 172.20.0.1:60022][0m
2023-01-01 01:21:03,995 - [INFO]    django.channels.server: [mHTTP GET /static/assets/css/autocomplete.css 200 [0.07, 172.20.0.1:60010][0m
2023-01-01 01:21:04,018 - [INFO]    django.channels.server: [mHTTP GET /static/assets/js/core/popper.min.js 200 [0.10, 172.20.0.1:60026][0m
2023-01-01 01:21:04,128 - [INFO]    django.channels.server: [mHTTP GET /static/assets/js/core/bootstrap.min.js 200 [0.20, 172.20.0.1:60030][0m
2023-01-01 01:21:04,242 - [INFO]    django.channels.server: [mHTTP GET /static/assets/js/plugins/perfect-scrollbar.min.js 200 [0.32, 172.20.0.1:60040][0m
2023-01-01 01:21:04,268 - [INFO]    django.channels.server: [mHTTP GET /static/assets/js/material-kit.min.js 200 [0.34, 172.20.0.1:60056][0m
2023-01-01 01:21:04,353 - [INFO]    django.channels.server: [mHTTP GET /static/assets/js/plugins/parallax.min.js 200 [0.39, 172.20.0.1:60022][0m
2023-01-01 01:21:04,726 - [INFO]    django.channels.server: [mHTTP GET /static/assets/js/plugins/countup.min.js 200 [0.02, 172.20.0.1:60030][0m
2023-01-01 01:21:04,799 - [INFO]    django.channels.server: [mHTTP GET /static/assets/js/plugins/prism.min.js 200 [0.09, 172.20.0.1:60026][0m
2023-01-01 01:21:04,870 - [INFO]    django.channels.server: [mHTTP GET /static/assets/js/plugins/highlight.min.js 200 [0.15, 172.20.0.1:60040][0m
2023-01-01 01:21:04,916 - [INFO]    django.channels.server: [mHTTP GET /static/assets/js/plugins/rellax.min.js 200 [0.19, 172.20.0.1:60056][0m
2023-01-01 01:21:04,966 - [INFO]    django.channels.server: [mHTTP GET /static/assets/js/plugins/tilt.min.js 200 [0.24, 172.20.0.1:60022][0m
2023-01-01 01:21:04,999 - [INFO]    django.channels.server: [mHTTP GET /static/assets/js/core/jquery.min.js 200 [0.27, 172.20.0.1:60010][0m
2023-01-01 01:21:05,030 - [INFO]    django.channels.server: [mHTTP GET /static/debug_toolbar/css/toolbar.css 200 [0.29, 172.20.0.1:60030][0m
2023-01-01 01:21:05,285 - [INFO]    django.channels.server: [36mHTTP GET /static/debug_toolbar/js/toolbar.js 304 [0.01, 172.20.0.1:60030][0m
2023-01-01 01:21:05,493 - [WARNING]    django.request: Not Found: /sw.js
2023-01-01 01:21:05,499 - [WARNING]    django.channels.server: [33mHTTP GET /sw.js 404 [0.22, 172.20.0.1:60040][0m
2023-01-01 01:21:05,506 - [INFO]    django.channels.server: [36mHTTP GET /static/debug_toolbar/js/utils.js 304 [0.01, 172.20.0.1:60030][0m
2023-01-01 01:21:06,608 - [WARNING]    django.request: Not Found: /sw.js
2023-01-01 01:21:06,612 - [WARNING]    django.channels.server: [33mHTTP GET /sw.js 404 [0.19, 172.20.0.1:60030][0m
2023-01-01 01:21:08,620 - [WARNING]    django.request: Not Found: /sw.js
2023-01-01 01:21:08,625 - [WARNING]    django.channels.server: [33mHTTP GET /sw.js 404 [0.22, 172.20.0.1:60026][0m
2023-01-01 01:21:08,769 - [INFO]    django.channels.server: [mHTTP GET /static/debug_toolbar/css/print.css 200 [0.04, 172.20.0.1:60022][0m
2023-01-01 01:21:09,534 - [WARNING]    django.request: Not Found: /sw.js
2023-01-01 01:21:09,537 - [WARNING]    django.channels.server: [33mHTTP GET /sw.js 404 [0.20, 172.20.0.1:60022][0m
2023-01-01 01:21:10,830 - [INFO]    django.channels.server: [mHTTP GET /static/assets/img/apple-icon.png 200 [0.05, 172.20.0.1:60056][0m
2023-01-01 01:21:10,857 - [INFO]    django.channels.server: [mHTTP GET /static/assets/img/favicon.png 200 [0.08, 172.20.0.1:60010][0m
2023-01-01 01:21:11,154 - [WARNING]    django.request: Not Found: /sw.js
2023-01-01 01:21:11,158 - [WARNING]    django.channels.server: [33mHTTP GET /sw.js 404 [0.28, 172.20.0.1:60056][0m
2023-01-01 01:24:09,542 - [WARNING]    django.request: Not Found: /sw.js
2023-01-01 01:24:09,549 - [WARNING]    django.channels.server: [33mHTTP GET /sw.js 404 [0.25, 172.20.0.1:43662][0m
2023-01-01 01:24:10,442 - [INFO]    django.channels.server: [mHTTP GET /in_place/ 200 [2.17, 172.20.0.1:43658][0m
2023-01-01 01:24:10,701 - [INFO]    django.channels.server: [mHTTP GET /static/dash_assets/css/material-dashboard.css 200 [0.04, 172.20.0.1:43658][0m
2023-01-01 01:24:10,721 - [INFO]    django.channels.server: [mHTTP GET /static/dash_assets/js/core/jquery.min.js 200 [0.04, 172.20.0.1:43670][0m
2023-01-01 01:24:10,869 - [INFO]    django.channels.server: [mHTTP GET /static/dash_assets/img/sidebar-4.jpg 200 [0.16, 172.20.0.1:43692][0m
2023-01-01 01:24:10,948 - [INFO]    django.channels.server: [mHTTP GET /static/dash_assets/img/sidebar-3.jpg 200 [0.24, 172.20.0.1:43680][0m
2023-01-01 01:24:11,023 - [INFO]    django.channels.server: [mHTTP GET /static/dash_assets/img/sidebar-2.jpg 200 [0.31, 172.20.0.1:43674][0m
2023-01-01 01:24:11,085 - [INFO]    django.channels.server: [mHTTP GET /static/dash_assets/img/sidebar-1.jpg 200 [0.38, 172.20.0.1:43698][0m
2023-01-01 01:24:11,095 - [INFO]    django.channels.server: [mHTTP GET /static/dash_assets/js/core/popper.min.js 200 [0.27, 172.20.0.1:43670][0m
2023-01-01 01:24:11,127 - [INFO]    django.channels.server: [mHTTP GET /static/dash_assets/js/core/bootstrap-material-design.min.js 200 [0.30, 172.20.0.1:43658][0m
2023-01-01 01:24:11,138 - [INFO]    django.channels.server: [mHTTP GET /static/dash_assets/js/plugins/perfect-scrollbar.jquery.min.js 200 [0.26, 172.20.0.1:43692][0m
2023-01-01 01:24:11,161 - [INFO]    django.channels.server: [mHTTP GET /static/dash_assets/js/plugins/chartist.min.js 200 [0.20, 172.20.0.1:43680][0m
2023-01-01 01:24:11,177 - [INFO]    django.channels.server: [mHTTP GET /static/dash_assets/js/plugins/bootstrap-notify.js 200 [0.14, 172.20.0.1:43674][0m
2023-01-01 01:24:11,212 - [INFO]    django.channels.server: [mHTTP GET /static/dash_assets/js/material-dashboard.js 200 [0.12, 172.20.0.1:43698][0m
2023-01-01 01:24:11,866 - [WARNING]    django.request: Not Found: /sw.js
2023-01-01 01:24:11,870 - [WARNING]    django.channels.server: [33mHTTP GET /sw.js 404 [0.20, 172.20.0.1:43674][0m
2023-01-01 01:24:15,914 - [WARNING]    django.request: Not Found: /sw.js
2023-01-01 01:24:15,917 - [WARNING]    django.channels.server: [33mHTTP GET /sw.js 404 [0.18, 172.20.0.1:43692][0m
2023-01-01 01:24:24,247 - [WARNING]    django.request: Not Found: /sw.js
2023-01-01 01:24:24,251 - [WARNING]    django.channels.server: [33mHTTP GET /sw.js 404 [0.28, 172.20.0.1:43680][0m
2023-01-01 01:24:25,782 - [INFO]    django.channels.server: WebSocket HANDSHAKING /ws/dinein/delivered/ [172.20.0.1:52438]
2023-01-01 01:24:26,375 - [INFO]    django.channels.server: WebSocket CONNECT /ws/dinein/delivered/ [172.20.0.1:52438]
2023-01-01 01:24:26,426 - [INFO]    django.channels.server: WebSocket HANDSHAKING /ws/dinein/new_item/ [172.20.0.1:52448]
2023-01-01 01:24:26,460 - [INFO]    django.channels.server: WebSocket CONNECT /ws/dinein/new_item/ [172.20.0.1:52448]
2023-01-01 01:24:26,908 - [WARNING]    django.request: Not Found: /sw.js
2023-01-01 01:24:26,911 - [WARNING]    django.channels.server: [33mHTTP GET /sw.js 404 [0.20, 172.20.0.1:43698][0m
2023-01-01 01:24:28,297 - [WARNING]    django.request: Not Found: /sw.js
2023-01-01 01:24:28,300 - [WARNING]    django.channels.server: [33mHTTP GET /sw.js 404 [0.23, 172.20.0.1:43670][0m
2023-01-01 02:14:15,445 - [WARNING]    django.request: Not Found: /v1/request
2023-01-01 02:14:50,551 - [WARNING]    django.request: Not Found: /v1/request
2023-01-01 02:36:39,355 - [INFO]    django.channels.server: WebSocket DISCONNECT /ws/dinein/new_item/ [172.20.0.1:52448]
2023-01-01 02:36:39,465 - [INFO]    django.channels.server: WebSocket DISCONNECT /ws/dinein/delivered/ [172.20.0.1:52438]
2023-01-01 02:36:45,433 - [INFO]    django.channels.server: [mHTTP GET /bankgateways/sample-payment/ 200 [4.78, 172.20.0.1:47952][0m
2023-01-01 02:36:45,460 - [WARNING]    django.request: Not Found: /sw.js
2023-01-01 02:36:45,466 - [WARNING]    django.channels.server: [33mHTTP GET /sw.js 404 [3.05, 172.20.0.1:47962][0m
2023-01-01 02:36:57,860 - [WARNING]    django.request: Not Found: /sw.js
2023-01-01 02:36:57,863 - [WARNING]    django.channels.server: [33mHTTP GET /sw.js 404 [0.20, 172.20.0.1:47952][0m
2023-01-01 02:37:02,320 - [WARNING]    django.request: Not Found: /sw.js
2023-01-01 02:37:02,328 - [WARNING]    django.channels.server: [33mHTTP GET /sw.js 404 [0.23, 172.20.0.1:39486][0m
2023-01-01 02:37:07,511 - [WARNING]    django.request: Not Found: /sw.js
2023-01-01 02:37:07,515 - [WARNING]    django.channels.server: [33mHTTP GET /sw.js 404 [0.20, 172.20.0.1:59686][0m
2023-01-01 02:38:06,538 - [ERROR]    django.request: Internal Server Error: /bankgateways/sample-payment/
Traceback (most recent call last):
  File "/usr/local/lib/python3.10/site-packages/asgiref/sync.py", line 472, in thread_handler
    raise exc_info[1]
  File "/usr/local/lib/python3.10/site-packages/django/core/handlers/exception.py", line 42, in inner
    response = await get_response(request)
  File "/usr/local/lib/python3.10/site-packages/django/core/handlers/base.py", line 253, in _get_response_async
    response = await wrapped_callback(
  File "/usr/local/lib/python3.10/site-packages/asgiref/sync.py", line 435, in __call__
    ret = await asyncio.wait_for(future, timeout=None)
  File "/usr/local/lib/python3.10/asyncio/tasks.py", line 408, in wait_for
    return await fut
  File "/usr/local/lib/python3.10/site-packages/asgiref/current_thread_executor.py", line 22, in run
    result = self.fn(*self.args, **self.kwargs)
  File "/usr/local/lib/python3.10/site-packages/asgiref/sync.py", line 476, in thread_handler
    return func(*args, **kwargs)
  File "/usr/local/lib/python3.10/site-packages/azbankgateways/views/samples.py", line 45, in sample_payment_view
    raise e
  File "/usr/local/lib/python3.10/site-packages/azbankgateways/views/samples.py", line 27, in sample_payment_view
    bank = factory.auto_create()
  File "/usr/local/lib/python3.10/site-packages/azbankgateways/bankfactories.py", line 59, in auto_create
    raise BankGatewayAutoConnectionFailed()
azbankgateways.exceptions.exceptions.BankGatewayAutoConnectionFailed
2023-01-01 02:38:06,896 - [ERROR]    django.channels.server: [35;1mHTTP POST /bankgateways/sample-payment/ 500 [1.53, 172.20.0.1:39092][0m
2023-01-01 02:38:07,047 - [WARNING]    django.request: Not Found: /sw.js
2023-01-01 02:38:07,050 - [WARNING]    django.channels.server: [33mHTTP GET /sw.js 404 [0.60, 172.20.0.1:39094][0m
2023-01-01 02:38:08,339 - [WARNING]    django.request: Not Found: /sw.js
2023-01-01 02:38:08,342 - [WARNING]    django.channels.server: [33mHTTP GET /sw.js 404 [0.25, 172.20.0.1:39092][0m
2023-01-01 02:38:09,810 - [WARNING]    django.request: Not Found: /sw.js
2023-01-01 02:38:09,817 - [WARNING]    django.channels.server: [33mHTTP GET /sw.js 404 [0.22, 172.20.0.1:39096][0m
2023-01-01 02:39:55,245 - [INFO]    django.channels.server: [mHTTP GET /bankgateways/sample-payment/ 200 [0.24, 172.20.0.1:41998][0m
2023-01-01 02:39:58,122 - [ERROR]    django.request: Internal Server Error: /bankgateways/sample-payment/
Traceback (most recent call last):
  File "/usr/local/lib/python3.10/site-packages/asgiref/sync.py", line 472, in thread_handler
    raise exc_info[1]
  File "/usr/local/lib/python3.10/site-packages/django/core/handlers/exception.py", line 42, in inner
    response = await get_response(request)
  File "/usr/local/lib/python3.10/site-packages/django/core/handlers/base.py", line 253, in _get_response_async
    response = await wrapped_callback(
  File "/usr/local/lib/python3.10/site-packages/asgiref/sync.py", line 435, in __call__
    ret = await asyncio.wait_for(future, timeout=None)
  File "/usr/local/lib/python3.10/asyncio/tasks.py", line 408, in wait_for
    return await fut
  File "/usr/local/lib/python3.10/site-packages/asgiref/current_thread_executor.py", line 22, in run
    result = self.fn(*self.args, **self.kwargs)
  File "/usr/local/lib/python3.10/site-packages/asgiref/sync.py", line 476, in thread_handler
    return func(*args, **kwargs)
  File "/usr/local/lib/python3.10/site-packages/azbankgateways/views/samples.py", line 45, in sample_payment_view
    raise e
  File "/usr/local/lib/python3.10/site-packages/azbankgateways/views/samples.py", line 27, in sample_payment_view
    bank = factory.auto_create()
  File "/usr/local/lib/python3.10/site-packages/azbankgateways/bankfactories.py", line 59, in auto_create
    raise BankGatewayAutoConnectionFailed()
azbankgateways.exceptions.exceptions.BankGatewayAutoConnectionFailed
2023-01-01 02:39:58,386 - [ERROR]    django.channels.server: [35;1mHTTP POST /bankgateways/sample-payment/ 500 [0.68, 172.20.0.1:56880][0m
2023-01-01 02:49:37,328 - [INFO]    django.utils.autoreload: Watching for file changes with StatReloader
2023-01-01 03:25:55,957 - [INFO]    django.utils.autoreload: Watching for file changes with StatReloader
2023-01-01 03:27:04,540 - [INFO]    django.utils.autoreload: /usr/local/lib/python3.10/site-packages/azbankgateways/bankfactories.py changed, reloading.
2023-01-01 03:27:07,715 - [INFO]    django.utils.autoreload: Watching for file changes with StatReloader
2023-01-01 03:37:04,779 - [INFO]    django.utils.autoreload: /usr/local/lib/python3.10/site-packages/azbankgateways/bankfactories.py changed, reloading.
2023-01-01 03:37:12,891 - [INFO]    django.utils.autoreload: Watching for file changes with StatReloader
2023-01-01 03:37:52,691 - [INFO]    django.utils.autoreload: /usr/local/lib/python3.10/site-packages/azbankgateways/bankfactories.py changed, reloading.
2023-01-01 03:37:54,751 - [INFO]    django.utils.autoreload: Watching for file changes with StatReloader
2023-01-01 03:38:17,868 - [INFO]    django.channels.server: [32mHTTP POST /bankgateways/sample-payment/ 302 [7.60, 172.25.0.1:47810][0m
2023-01-01 03:38:18,587 - [INFO]    django.channels.server: [mHTTP GET /bankgateways/go-to-bank-gateway/?url=https%3A%2F%2Fgateway.zibal.ir%2Fstart%2F3112340293&method=GET 200 [0.66, 172.25.0.1:33272][0m
2023-01-01 03:39:22,982 - [INFO]    django.channels.server: [32mHTTP GET /bankgateways/callback/?bank_type=ZIBAL&identifier=1&success=1&status=2&trackId=3112340293&orderId=6233908092178938 302 [0.93, 172.25.0.1:36308][0m
2023-01-01 03:39:23,319 - [INFO]    django.channels.server: [mHTTP GET /bankgateways/sample-result/?tc=6233908092178938 200 [0.30, 172.25.0.1:36312][0m
2023-01-01 03:39:28,432 - [INFO]    django.channels.server: [mHTTP GET /bankgateways/sample-payment/ 200 [0.33, 172.25.0.1:34176][0m
2023-01-01 03:39:39,723 - [INFO]    django.channels.server: [32mHTTP GET /bankgateways/callback/?bank_type=ZIBAL&identifier=1&success=1&status=1&trackId=3112340293&orderId=6233908092178938 302 [0.24, 172.25.0.1:49028][0m
2023-01-01 03:39:39,972 - [INFO]    django.channels.server: [mHTTP GET /bankgateways/sample-result/?tc=6233908092178938 200 [0.22, 172.25.0.1:49030][0m
2023-01-01 03:41:15,974 - [INFO]    django.channels.server: [mHTTP GET / 200 [0.73, 172.25.0.1:55926][0m
2023-01-01 11:05:12,286 - [INFO]    django.utils.autoreload: Watching for file changes with StatReloader
2023-01-01 12:38:22,216 - [INFO]    django.utils.autoreload: /usr/src/app/apps/delivery/forms.py changed, reloading.
2023-01-01 12:39:15,446 - [INFO]    django.utils.autoreload: Watching for file changes with StatReloader
2023-01-01 12:39:50,031 - [INFO]    django.utils.autoreload: /usr/src/app/apps/delivery/forms.py changed, reloading.
2023-01-01 12:39:54,269 - [INFO]    django.utils.autoreload: Watching for file changes with StatReloader
2023-01-01 12:40:02,182 - [INFO]    django.utils.autoreload: /usr/src/app/apps/delivery/forms.py changed, reloading.
2023-01-01 12:40:05,212 - [INFO]    django.utils.autoreload: Watching for file changes with StatReloader
2023-01-01 12:41:41,111 - [INFO]    django.utils.autoreload: /usr/src/app/apps/delivery/forms.py changed, reloading.
2023-01-01 12:41:44,208 - [INFO]    django.utils.autoreload: Watching for file changes with StatReloader
2023-01-01 12:57:56,486 - [INFO]    django.utils.autoreload: /usr/src/app/apps/restaurants/models.py changed, reloading.
2023-01-01 12:58:11,419 - [INFO]    django.utils.autoreload: Watching for file changes with StatReloader
2023-01-01 12:58:27,194 - [INFO]    django.utils.autoreload: /usr/src/app/apps/restaurants/models.py changed, reloading.
2023-01-01 12:58:30,514 - [INFO]    django.utils.autoreload: Watching for file changes with StatReloader
2023-01-01 12:58:35,448 - [INFO]    django.utils.autoreload: /usr/src/app/apps/restaurants/models.py changed, reloading.
2023-01-01 12:58:37,934 - [INFO]    django.utils.autoreload: Watching for file changes with StatReloader
2023-01-01 12:59:22,708 - [INFO]    django.utils.autoreload: /usr/src/app/apps/restaurants/models.py changed, reloading.
2023-01-01 12:59:25,762 - [INFO]    django.utils.autoreload: Watching for file changes with StatReloader
2023-01-01 13:04:14,832 - [INFO]    django.channels.server: [mHTTP GET / 200 [3.20, 172.25.0.1:50638][0m
2023-01-01 13:04:51,406 - [INFO]    django.channels.server: [mHTTP GET / 200 [0.23, 172.25.0.1:43324][0m
2023-01-01 13:05:38,103 - [INFO]    django.channels.server: [mHTTP GET / 200 [0.18, 172.25.0.1:41226][0m
2023-01-01 13:05:40,187 - [INFO]    django.channels.server: [mHTTP GET / 200 [0.27, 172.25.0.1:41230][0m
2023-01-01 13:07:04,578 - [INFO]    django.channels.server: [mHTTP GET / 200 [0.61, 172.25.0.1:55366][0m
2023-01-01 13:07:27,704 - [INFO]    django.channels.server: [mHTTP GET /restaurants/?lat=36.3030338&lon=59.6255339 200 [4.00, 172.25.0.1:48204][0m
2023-01-01 13:07:44,480 - [ERROR]    django.request: Internal Server Error: /restaurants/243556bc-a529-40a3-bc7e-7d63f54a4527/
Traceback (most recent call last):
  File "/usr/local/lib/python3.10/site-packages/asgiref/sync.py", line 472, in thread_handler
    raise exc_info[1]
  File "/usr/local/lib/python3.10/site-packages/django/core/handlers/exception.py", line 42, in inner
    response = await get_response(request)
  File "/usr/local/lib/python3.10/site-packages/django/core/handlers/base.py", line 253, in _get_response_async
    response = await wrapped_callback(
  File "/usr/src/app/apps/restaurants/views.py", line 146, in get
    reviews = await sync_to_async(Review.objects.filter)(
  File "/usr/local/lib/python3.10/site-packages/asgiref/sync.py", line 435, in __call__
    ret = await asyncio.wait_for(future, timeout=None)
  File "/usr/local/lib/python3.10/asyncio/tasks.py", line 408, in wait_for
    return await fut
  File "/usr/local/lib/python3.10/site-packages/asgiref/current_thread_executor.py", line 22, in run
    result = self.fn(*self.args, **self.kwargs)
  File "/usr/local/lib/python3.10/site-packages/asgiref/sync.py", line 476, in thread_handler
    return func(*args, **kwargs)
  File "/usr/local/lib/python3.10/site-packages/django/db/models/manager.py", line 85, in manager_method
    return getattr(self.get_queryset(), name)(*args, **kwargs)
  File "/usr/local/lib/python3.10/site-packages/django/db/models/query.py", line 1420, in filter
    return self._filter_or_exclude(False, args, kwargs)
  File "/usr/local/lib/python3.10/site-packages/django/db/models/query.py", line 1438, in _filter_or_exclude
    clone._filter_or_exclude_inplace(negate, args, kwargs)
  File "/usr/local/lib/python3.10/site-packages/django/db/models/query.py", line 1445, in _filter_or_exclude_inplace
    self._query.add_q(Q(*args, **kwargs))
  File "/usr/local/lib/python3.10/site-packages/django/db/models/sql/query.py", line 1532, in add_q
    clause, _ = self._add_q(q_object, self.used_aliases)
  File "/usr/local/lib/python3.10/site-packages/django/db/models/sql/query.py", line 1562, in _add_q
    child_clause, needed_inner = self.build_filter(
  File "/usr/local/lib/python3.10/site-packages/django/db/models/sql/query.py", line 1445, in build_filter
    self.check_related_objects(join_info.final_field, value, join_info.opts)
  File "/usr/local/lib/python3.10/site-packages/django/db/models/sql/query.py", line 1256, in check_related_objects
    self.check_query_object_type(value, opts, field)
  File "/usr/local/lib/python3.10/site-packages/django/db/models/sql/query.py", line 1233, in check_query_object_type
    raise ValueError(
ValueError: Cannot query "Test": Must be "Item" instance.
2023-01-01 13:07:44,727 - [ERROR]    django.channels.server: [35;1mHTTP GET /restaurants/243556bc-a529-40a3-bc7e-7d63f54a4527/ 500 [0.75, 172.25.0.1:35630][0m
2023-01-01 13:10:22,070 - [INFO]    django.utils.autoreload: /usr/src/app/apps/restaurants/views.py changed, reloading.
2023-01-01 13:10:34,179 - [INFO]    django.utils.autoreload: Watching for file changes with StatReloader
2023-01-01 13:10:45,188 - [INFO]    django.channels.server: [mHTTP GET /restaurants/243556bc-a529-40a3-bc7e-7d63f54a4527/ 200 [1.11, 172.25.0.1:60388][0m
2023-01-01 13:11:05,928 - [ERROR]    django.request: Internal Server Error: /delivery/cart/add/
Traceback (most recent call last):
  File "/usr/local/lib/python3.10/site-packages/asgiref/sync.py", line 472, in thread_handler
    raise exc_info[1]
  File "/usr/local/lib/python3.10/site-packages/django/core/handlers/exception.py", line 42, in inner
    response = await get_response(request)
  File "/usr/local/lib/python3.10/site-packages/django/core/handlers/base.py", line 253, in _get_response_async
    response = await wrapped_callback(
  File "/usr/local/lib/python3.10/site-packages/asgiref/sync.py", line 435, in __call__
    ret = await asyncio.wait_for(future, timeout=None)
  File "/usr/local/lib/python3.10/asyncio/tasks.py", line 408, in wait_for
    return await fut
  File "/usr/local/lib/python3.10/site-packages/asgiref/current_thread_executor.py", line 22, in run
    result = self.fn(*self.args, **self.kwargs)
  File "/usr/local/lib/python3.10/site-packages/asgiref/sync.py", line 476, in thread_handler
    return func(*args, **kwargs)
  File "/usr/local/lib/python3.10/site-packages/django/views/generic/base.py", line 103, in view
    return self.dispatch(request, *args, **kwargs)
  File "/usr/local/lib/python3.10/site-packages/django/views/generic/base.py", line 142, in dispatch
    return handler(request, *args, **kwargs)
  File "/usr/src/app/apps/delivery/views.py", line 31, in post
    cart, _ = DeliveryCart.objects.get_or_create(user=self.request.user,
  File "/usr/local/lib/python3.10/site-packages/django/db/models/manager.py", line 85, in manager_method
    return getattr(self.get_queryset(), name)(*args, **kwargs)
  File "/usr/local/lib/python3.10/site-packages/django/db/models/query.py", line 928, in get_or_create
    return self.get(**kwargs), False
  File "/usr/local/lib/python3.10/site-packages/django/db/models/query.py", line 636, in get
    clone = self._chain() if self.query.combinator else self.filter(*args, **kwargs)
  File "/usr/local/lib/python3.10/site-packages/django/db/models/query.py", line 1420, in filter
    return self._filter_or_exclude(False, args, kwargs)
  File "/usr/local/lib/python3.10/site-packages/django/db/models/query.py", line 1438, in _filter_or_exclude
    clone._filter_or_exclude_inplace(negate, args, kwargs)
  File "/usr/local/lib/python3.10/site-packages/django/db/models/query.py", line 1445, in _filter_or_exclude_inplace
    self._query.add_q(Q(*args, **kwargs))
  File "/usr/local/lib/python3.10/site-packages/django/db/models/sql/query.py", line 1532, in add_q
    clause, _ = self._add_q(q_object, self.used_aliases)
  File "/usr/local/lib/python3.10/site-packages/django/db/models/sql/query.py", line 1562, in _add_q
    child_clause, needed_inner = self.build_filter(
  File "/usr/local/lib/python3.10/site-packages/django/db/models/sql/query.py", line 1407, in build_filter
    lookups, parts, reffed_expression = self.solve_lookup_type(arg)
  File "/usr/local/lib/python3.10/site-packages/django/db/models/sql/query.py", line 1217, in solve_lookup_type
    _, field, _, lookup_parts = self.names_to_path(lookup_splitted, self.get_meta())
  File "/usr/local/lib/python3.10/site-packages/django/db/models/sql/query.py", line 1709, in names_to_path
    raise FieldError(
django.core.exceptions.FieldError: Cannot resolve keyword 'paid' into field. Choices are: cart_items, discounts, id, user, user_address, user_address_id, user_id
2023-01-01 13:11:06,149 - [ERROR]    django.channels.server: [35;1mHTTP POST /delivery/cart/add/ 500 [0.34, 172.25.0.1:50232][0m
2023-01-01 13:14:27,646 - [INFO]    django.utils.autoreload: /usr/src/app/apps/delivery/views.py changed, reloading.
2023-01-01 13:14:30,126 - [INFO]    django.utils.autoreload: Watching for file changes with StatReloader
2023-01-01 13:16:32,671 - [INFO]    django.utils.autoreload: /usr/src/app/apps/restaurants/models.py changed, reloading.
2023-01-01 13:16:36,162 - [INFO]    django.utils.autoreload: Watching for file changes with StatReloader
2023-01-01 13:16:53,791 - [INFO]    django.channels.server: [mHTTP POST /delivery/cart/add/ 200 [1.34, 172.25.0.1:43218][0m
2023-01-01 13:17:04,105 - [INFO]    django.channels.server: [mHTTP GET /delivery/cart/ 200 [1.42, 172.25.0.1:47756][0m
2023-01-01 13:17:55,452 - [INFO]    django.channels.server: [mHTTP POST /delivery/cart/ 200 [0.29, 172.25.0.1:54506][0m
2023-01-01 13:45:14,349 - [INFO]    django.channels.server: [mHTTP GET /in_place/menu/ 200 [3.10, 172.25.0.1:45818][0m
2023-01-01 13:45:39,896 - [INFO]    django.channels.server: [32mHTTP POST /in_place/menu/itemvar/create 302 [0.78, 172.25.0.1:43926][0m
2023-01-01 13:45:40,479 - [INFO]    django.channels.server: [mHTTP GET /in_place/menu/ 200 [0.50, 172.25.0.1:43938][0m
2023-01-01 13:46:06,461 - [INFO]    django.channels.server: [mHTTP GET /restaurants/243556bc-a529-40a3-bc7e-7d63f54a4527/ 200 [0.89, 172.25.0.1:59816][0m
2023-01-01 13:46:15,627 - [INFO]    django.channels.server: [mHTTP POST /delivery/cart/add/ 200 [0.35, 172.25.0.1:37218][0m
2023-01-01 14:21:24,188 - [INFO]    django.utils.autoreload: /usr/src/app/apps/delivery/views.py changed, reloading.
2023-01-01 14:22:00,158 - [INFO]    django.utils.autoreload: Watching for file changes with StatReloader
2023-01-01 14:28:25,596 - [INFO]    django.utils.autoreload: /usr/src/app/apps/delivery/views.py changed, reloading.
2023-01-01 14:28:28,209 - [INFO]    django.utils.autoreload: Watching for file changes with StatReloader
2023-01-01 14:31:35,935 - [INFO]    django.utils.autoreload: /usr/src/app/apps/delivery/views.py changed, reloading.
2023-01-01 14:31:39,078 - [INFO]    django.utils.autoreload: Watching for file changes with StatReloader
2023-01-01 14:33:04,798 - [INFO]    django.utils.autoreload: /usr/src/app/apps/delivery/views.py changed, reloading.
2023-01-01 14:33:07,574 - [INFO]    django.utils.autoreload: Watching for file changes with StatReloader
2023-01-01 14:33:30,302 - [INFO]    django.utils.autoreload: /usr/src/app/apps/delivery/urls.py changed, reloading.
2023-01-01 14:33:32,486 - [INFO]    django.utils.autoreload: Watching for file changes with StatReloader
2023-01-01 14:38:25,950 - [INFO]    django.utils.autoreload: /usr/src/app/apps/delivery/urls.py changed, reloading.
2023-01-01 14:38:28,444 - [INFO]    django.utils.autoreload: Watching for file changes with StatReloader
2023-01-01 14:39:08,879 - [INFO]    django.channels.server: [mHTTP GET /delivery/cart/ 200 [8.07, 172.25.0.1:44028][0m
2023-01-01 14:40:29,228 - [ERROR]    django.request: Internal Server Error: /delivery/cart/
Traceback (most recent call last):
  File "/usr/local/lib/python3.10/site-packages/django/template/base.py", line 505, in parse
    compile_func = self.tags[command]
KeyError: 'delivery:purchase'

During handling of the above exception, another exception occurred:

Traceback (most recent call last):
  File "/usr/local/lib/python3.10/site-packages/asgiref/sync.py", line 472, in thread_handler
    raise exc_info[1]
  File "/usr/local/lib/python3.10/site-packages/django/core/handlers/exception.py", line 42, in inner
    response = await get_response(request)
  File "/usr/local/lib/python3.10/site-packages/django/core/handlers/base.py", line 253, in _get_response_async
    response = await wrapped_callback(
  File "/usr/local/lib/python3.10/site-packages/asgiref/sync.py", line 435, in __call__
    ret = await asyncio.wait_for(future, timeout=None)
  File "/usr/local/lib/python3.10/asyncio/tasks.py", line 408, in wait_for
    return await fut
  File "/usr/local/lib/python3.10/site-packages/asgiref/current_thread_executor.py", line 22, in run
    result = self.fn(*self.args, **self.kwargs)
  File "/usr/local/lib/python3.10/site-packages/asgiref/sync.py", line 476, in thread_handler
    return func(*args, **kwargs)
  File "/usr/local/lib/python3.10/site-packages/django/views/generic/base.py", line 103, in view
    return self.dispatch(request, *args, **kwargs)
  File "/usr/local/lib/python3.10/site-packages/django/views/generic/base.py", line 142, in dispatch
    return handler(request, *args, **kwargs)
  File "/usr/src/app/apps/delivery/views.py", line 62, in get
    return render(self.request, self.template_name, self.context)
  File "/usr/local/lib/python3.10/site-packages/django/shortcuts.py", line 24, in render
    content = loader.render_to_string(template_name, context, request, using=using)
  File "/usr/local/lib/python3.10/site-packages/django/template/loader.py", line 61, in render_to_string
    template = get_template(template_name, using=using)
  File "/usr/local/lib/python3.10/site-packages/django/template/loader.py", line 15, in get_template
    return engine.get_template(template_name)
  File "/usr/local/lib/python3.10/site-packages/django/template/backends/django.py", line 34, in get_template
    return Template(self.engine.get_template(template_name), self)
  File "/usr/local/lib/python3.10/site-packages/django/template/engine.py", line 175, in get_template
    template, origin = self.find_template(template_name)
  File "/usr/local/lib/python3.10/site-packages/django/template/engine.py", line 157, in find_template
    template = loader.get_template(name, skip=skip)
  File "/usr/local/lib/python3.10/site-packages/django/template/loaders/cached.py", line 57, in get_template
    template = super().get_template(template_name, skip)
  File "/usr/local/lib/python3.10/site-packages/django/template/loaders/base.py", line 28, in get_template
    return Template(
  File "/usr/local/lib/python3.10/site-packages/django/template/base.py", line 154, in __init__
    self.nodelist = self.compile_nodelist()
  File "/usr/local/lib/python3.10/site-packages/django/template/base.py", line 200, in compile_nodelist
    return parser.parse()
  File "/usr/local/lib/python3.10/site-packages/django/template/base.py", line 513, in parse
    raise self.error(token, e)
  File "/usr/local/lib/python3.10/site-packages/django/template/base.py", line 511, in parse
    compiled_result = compile_func(self, token)
  File "/usr/local/lib/python3.10/site-packages/django/template/loader_tags.py", line 293, in do_extends
    nodelist = parser.parse()
  File "/usr/local/lib/python3.10/site-packages/django/template/base.py", line 513, in parse
    raise self.error(token, e)
  File "/usr/local/lib/python3.10/site-packages/django/template/base.py", line 511, in parse
    compiled_result = compile_func(self, token)
  File "/usr/local/lib/python3.10/site-packages/django/template/loader_tags.py", line 232, in do_block
    nodelist = parser.parse(("endblock",))
  File "/usr/local/lib/python3.10/site-packages/django/template/base.py", line 507, in parse
    self.invalid_block_tag(token, command, parse_until)
  File "/usr/local/lib/python3.10/site-packages/django/template/base.py", line 558, in invalid_block_tag
    raise self.error(
django.template.exceptions.TemplateSyntaxError: Invalid block tag on line 135: 'delivery:purchase', expected 'endblock'. Did you forget to register or load this tag?
2023-01-01 14:40:29,463 - [ERROR]    django.channels.server: [35;1mHTTP GET /delivery/cart/ 500 [0.45, 172.25.0.1:52910][0m
2023-01-01 14:40:41,686 - [INFO]    django.channels.server: [mHTTP GET /delivery/cart/ 200 [0.41, 172.25.0.1:54720][0m
2023-01-01 14:41:00,577 - [ERROR]    django.request: Internal Server Error: /delivery/cart/purchase/
Traceback (most recent call last):
  File "/usr/local/lib/python3.10/site-packages/asgiref/sync.py", line 472, in thread_handler
    raise exc_info[1]
  File "/usr/local/lib/python3.10/site-packages/django/core/handlers/exception.py", line 42, in inner
    response = await get_response(request)
  File "/usr/local/lib/python3.10/site-packages/django/core/handlers/base.py", line 253, in _get_response_async
    response = await wrapped_callback(
  File "/usr/local/lib/python3.10/site-packages/asgiref/sync.py", line 435, in __call__
    ret = await asyncio.wait_for(future, timeout=None)
  File "/usr/local/lib/python3.10/asyncio/tasks.py", line 408, in wait_for
    return await fut
  File "/usr/local/lib/python3.10/site-packages/asgiref/current_thread_executor.py", line 22, in run
    result = self.fn(*self.args, **self.kwargs)
  File "/usr/local/lib/python3.10/site-packages/asgiref/sync.py", line 476, in thread_handler
    return func(*args, **kwargs)
  File "/usr/local/lib/python3.10/site-packages/django/views/generic/base.py", line 103, in view
    return self.dispatch(request, *args, **kwargs)
  File "/usr/local/lib/python3.10/site-packages/django/contrib/auth/mixins.py", line 73, in dispatch
    return super().dispatch(request, *args, **kwargs)
  File "/usr/local/lib/python3.10/site-packages/django/views/generic/base.py", line 142, in dispatch
    return handler(request, *args, **kwargs)
  File "/usr/src/app/apps/delivery/views.py", line 150, in post
    bank.set_client_callback_url(reverse("delivery:home"))
  File "/usr/local/lib/python3.10/site-packages/django/urls/base.py", line 88, in reverse
    return resolver._reverse_with_prefix(view, prefix, *args, **kwargs)
  File "/usr/local/lib/python3.10/site-packages/django/urls/resolvers.py", line 803, in _reverse_with_prefix
    raise NoReverseMatch(msg)
django.urls.exceptions.NoReverseMatch: Reverse for 'home' not found. 'home' is not a valid view function or pattern name.
2023-01-01 14:41:00,787 - [ERROR]    django.channels.server: [35;1mHTTP POST /delivery/cart/purchase/ 500 [1.55, 172.25.0.1:54848][0m
2023-01-01 14:41:44,132 - [INFO]    django.utils.autoreload: /usr/src/app/apps/delivery/views.py changed, reloading.
2023-01-01 14:41:47,515 - [INFO]    django.utils.autoreload: Watching for file changes with StatReloader
2023-01-01 14:41:56,085 - [ERROR]    django.request: Internal Server Error: /delivery/cart/purchase/
Traceback (most recent call last):
  File "/usr/local/lib/python3.10/site-packages/asgiref/sync.py", line 472, in thread_handler
    raise exc_info[1]
  File "/usr/local/lib/python3.10/site-packages/django/core/handlers/exception.py", line 42, in inner
    response = await get_response(request)
  File "/usr/local/lib/python3.10/site-packages/django/core/handlers/base.py", line 253, in _get_response_async
    response = await wrapped_callback(
  File "/usr/local/lib/python3.10/site-packages/asgiref/sync.py", line 435, in __call__
    ret = await asyncio.wait_for(future, timeout=None)
  File "/usr/local/lib/python3.10/asyncio/tasks.py", line 408, in wait_for
    return await fut
  File "/usr/local/lib/python3.10/site-packages/asgiref/current_thread_executor.py", line 22, in run
    result = self.fn(*self.args, **self.kwargs)
  File "/usr/local/lib/python3.10/site-packages/asgiref/sync.py", line 476, in thread_handler
    return func(*args, **kwargs)
  File "/usr/local/lib/python3.10/site-packages/django/views/generic/base.py", line 103, in view
    return self.dispatch(request, *args, **kwargs)
  File "/usr/local/lib/python3.10/site-packages/django/contrib/auth/mixins.py", line 73, in dispatch
    return super().dispatch(request, *args, **kwargs)
  File "/usr/local/lib/python3.10/site-packages/django/views/generic/base.py", line 142, in dispatch
    return handler(request, *args, **kwargs)
  File "/usr/src/app/apps/delivery/views.py", line 150, in post
    bank.set_client_callback_url(reverse("delivery:home"))
  File "/usr/local/lib/python3.10/site-packages/django/urls/base.py", line 88, in reverse
    return resolver._reverse_with_prefix(view, prefix, *args, **kwargs)
  File "/usr/local/lib/python3.10/site-packages/django/urls/resolvers.py", line 803, in _reverse_with_prefix
    raise NoReverseMatch(msg)
django.urls.exceptions.NoReverseMatch: Reverse for 'home' not found. 'home' is not a valid view function or pattern name.
2023-01-01 14:41:56,414 - [ERROR]    django.channels.server: [35;1mHTTP POST /delivery/cart/purchase/ 500 [6.20, 172.25.0.1:57318][0m
2023-01-01 14:43:15,033 - [INFO]    django.utils.autoreload: /usr/src/app/apps/delivery/views.py changed, reloading.
2023-01-01 14:43:17,688 - [INFO]    django.utils.autoreload: Watching for file changes with StatReloader
2023-01-01 14:43:27,833 - [ERROR]    django.request: Internal Server Error: /delivery/cart/purchase/
Traceback (most recent call last):
  File "/usr/local/lib/python3.10/site-packages/asgiref/sync.py", line 472, in thread_handler
    raise exc_info[1]
  File "/usr/local/lib/python3.10/site-packages/django/core/handlers/exception.py", line 42, in inner
    response = await get_response(request)
  File "/usr/local/lib/python3.10/site-packages/django/core/handlers/base.py", line 253, in _get_response_async
    response = await wrapped_callback(
  File "/usr/local/lib/python3.10/site-packages/asgiref/sync.py", line 435, in __call__
    ret = await asyncio.wait_for(future, timeout=None)
  File "/usr/local/lib/python3.10/asyncio/tasks.py", line 408, in wait_for
    return await fut
  File "/usr/local/lib/python3.10/site-packages/asgiref/current_thread_executor.py", line 22, in run
    result = self.fn(*self.args, **self.kwargs)
  File "/usr/local/lib/python3.10/site-packages/asgiref/sync.py", line 476, in thread_handler
    return func(*args, **kwargs)
  File "/usr/local/lib/python3.10/site-packages/django/views/generic/base.py", line 103, in view
    return self.dispatch(request, *args, **kwargs)
  File "/usr/local/lib/python3.10/site-packages/django/contrib/auth/mixins.py", line 73, in dispatch
    return super().dispatch(request, *args, **kwargs)
  File "/usr/local/lib/python3.10/site-packages/django/views/generic/base.py", line 142, in dispatch
    return handler(request, *args, **kwargs)
  File "/usr/src/app/apps/delivery/views.py", line 154, in post
    grouped = group_delivery_items(order_items)
  File "/usr/src/app/apps/delivery/utils.py", line 20, in group_delivery_items
    grouped = [(Restaurant.objects.get(id=k), [*g])
  File "/usr/src/app/apps/delivery/utils.py", line 20, in <listcomp>
    grouped = [(Restaurant.objects.get(id=k), [*g])
AttributeError: 'dict' object has no attribute 'restaurant'
2023-01-01 14:43:28,235 - [ERROR]    django.channels.server: [35;1mHTTP POST /delivery/cart/purchase/ 500 [7.11, 172.25.0.1:37236][0m
2023-01-01 14:43:43,064 - [INFO]    django.utils.autoreload: /usr/src/app/apps/delivery/utils.py changed, reloading.
2023-01-01 14:43:45,627 - [INFO]    django.utils.autoreload: Watching for file changes with StatReloader
2023-01-01 14:43:48,995 - [INFO]    django.utils.autoreload: /usr/src/app/apps/delivery/utils.py changed, reloading.
2023-01-01 14:43:51,393 - [INFO]    django.utils.autoreload: Watching for file changes with StatReloader
2023-01-01 14:44:32,318 - [ERROR]    django.request: Internal Server Error: /delivery/cart/purchase/
Traceback (most recent call last):
  File "/usr/local/lib/python3.10/site-packages/django/db/backends/utils.py", line 89, in _execute
    return self.cursor.execute(sql, params)
psycopg2.errors.UndefinedColumn: column "user_payment_id" of relation "restaurants_order" does not exist
LINE 1: ...e", "restaurant_id", "timestamp", "order_number", "user_paym...
                                                             ^


The above exception was the direct cause of the following exception:

Traceback (most recent call last):
  File "/usr/local/lib/python3.10/site-packages/asgiref/sync.py", line 472, in thread_handler
    raise exc_info[1]
  File "/usr/local/lib/python3.10/site-packages/django/core/handlers/exception.py", line 42, in inner
    response = await get_response(request)
  File "/usr/local/lib/python3.10/site-packages/django/core/handlers/base.py", line 253, in _get_response_async
    response = await wrapped_callback(
  File "/usr/local/lib/python3.10/site-packages/asgiref/sync.py", line 435, in __call__
    ret = await asyncio.wait_for(future, timeout=None)
  File "/usr/local/lib/python3.10/asyncio/tasks.py", line 408, in wait_for
    return await fut
  File "/usr/local/lib/python3.10/site-packages/asgiref/current_thread_executor.py", line 22, in run
    result = self.fn(*self.args, **self.kwargs)
  File "/usr/local/lib/python3.10/site-packages/asgiref/sync.py", line 476, in thread_handler
    return func(*args, **kwargs)
  File "/usr/local/lib/python3.10/site-packages/django/views/generic/base.py", line 103, in view
    return self.dispatch(request, *args, **kwargs)
  File "/usr/local/lib/python3.10/site-packages/django/contrib/auth/mixins.py", line 73, in dispatch
    return super().dispatch(request, *args, **kwargs)
  File "/usr/local/lib/python3.10/site-packages/django/views/generic/base.py", line 142, in dispatch
    return handler(request, *args, **kwargs)
  File "/usr/src/app/apps/delivery/views.py", line 157, in post
    order = Order.objects.create(restaurant=restaurant,
  File "/usr/local/lib/python3.10/site-packages/django/db/models/manager.py", line 85, in manager_method
    return getattr(self.get_queryset(), name)(*args, **kwargs)
  File "/usr/local/lib/python3.10/site-packages/django/db/models/query.py", line 671, in create
    obj.save(force_insert=True, using=self.db)
  File "/usr/src/app/apps/restaurants/models.py", line 474, in save
    super().save(*args, **kwargs)
  File "/usr/local/lib/python3.10/site-packages/django/db/models/base.py", line 831, in save
    self.save_base(
  File "/usr/local/lib/python3.10/site-packages/django/db/models/base.py", line 882, in save_base
    updated = self._save_table(
  File "/usr/local/lib/python3.10/site-packages/django/db/models/base.py", line 1025, in _save_table
    results = self._do_insert(
  File "/usr/local/lib/python3.10/site-packages/django/db/models/base.py", line 1066, in _do_insert
    return manager._insert(
  File "/usr/local/lib/python3.10/site-packages/django/db/models/manager.py", line 85, in manager_method
    return getattr(self.get_queryset(), name)(*args, **kwargs)
  File "/usr/local/lib/python3.10/site-packages/django/db/models/query.py", line 1790, in _insert
    return query.get_compiler(using=using).execute_sql(returning_fields)
  File "/usr/local/lib/python3.10/site-packages/django/db/models/sql/compiler.py", line 1657, in execute_sql
    cursor.execute(sql, params)
  File "/usr/local/lib/python3.10/site-packages/debug_toolbar/panels/sql/tracking.py", line 230, in execute
    return self._record(self.cursor.execute, sql, params)
  File "/usr/local/lib/python3.10/site-packages/debug_toolbar/panels/sql/tracking.py", line 154, in _record
    return method(sql, params)
  File "/usr/local/lib/python3.10/site-packages/django/db/backends/utils.py", line 103, in execute
    return super().execute(sql, params)
  File "/usr/local/lib/python3.10/site-packages/django/db/backends/utils.py", line 67, in execute
    return self._execute_with_wrappers(
  File "/usr/local/lib/python3.10/site-packages/django/db/backends/utils.py", line 80, in _execute_with_wrappers
    return executor(sql, params, many, context)
  File "/usr/local/lib/python3.10/site-packages/django/db/backends/utils.py", line 84, in _execute
    with self.db.wrap_database_errors:
  File "/usr/local/lib/python3.10/site-packages/django/db/utils.py", line 91, in __exit__
    raise dj_exc_value.with_traceback(traceback) from exc_value
  File "/usr/local/lib/python3.10/site-packages/django/db/backends/utils.py", line 89, in _execute
    return self.cursor.execute(sql, params)
django.db.utils.ProgrammingError: column "user_payment_id" of relation "restaurants_order" does not exist
LINE 1: ...e", "restaurant_id", "timestamp", "order_number", "user_paym...
                                                             ^

2023-01-01 14:44:32,684 - [ERROR]    django.channels.server: [35;1mHTTP POST /delivery/cart/purchase/ 500 [2.98, 172.25.0.1:56928][0m
2023-01-01 14:47:37,636 - [WARNING]    django.request: Method Not Allowed (GET): /delivery/cart/purchase/
2023-01-01 14:47:37,819 - [WARNING]    django.request: Method Not Allowed: /delivery/cart/purchase/
2023-01-01 14:47:37,825 - [WARNING]    django.channels.server: [31;1mHTTP GET /delivery/cart/purchase/ 405 [0.22, 172.25.0.1:47790][0m
2023-01-01 14:47:56,598 - [ERROR]    django.request: Internal Server Error: /delivery/cart/purchase/
Traceback (most recent call last):
  File "/usr/local/lib/python3.10/site-packages/urllib3/connection.py", line 174, in _new_conn
    conn = connection.create_connection(
  File "/usr/local/lib/python3.10/site-packages/urllib3/util/connection.py", line 72, in create_connection
    for res in socket.getaddrinfo(host, port, family, socket.SOCK_STREAM):
  File "/usr/local/lib/python3.10/socket.py", line 955, in getaddrinfo
    for res in _socket.getaddrinfo(host, port, family, type, proto, flags):
socket.gaierror: [Errno -2] Name or service not known

During handling of the above exception, another exception occurred:

Traceback (most recent call last):
  File "/usr/local/lib/python3.10/site-packages/elasticsearch/connection/http_urllib3.py", line 255, in perform_request
    response = self.pool.urlopen(
  File "/usr/local/lib/python3.10/site-packages/urllib3/connectionpool.py", line 785, in urlopen
    retries = retries.increment(
  File "/usr/local/lib/python3.10/site-packages/urllib3/util/retry.py", line 525, in increment
    raise six.reraise(type(error), error, _stacktrace)
  File "/usr/local/lib/python3.10/site-packages/urllib3/packages/six.py", line 770, in reraise
    raise value
  File "/usr/local/lib/python3.10/site-packages/urllib3/connectionpool.py", line 703, in urlopen
    httplib_response = self._make_request(
  File "/usr/local/lib/python3.10/site-packages/urllib3/connectionpool.py", line 398, in _make_request
    conn.request(method, url, **httplib_request_kw)
  File "/usr/local/lib/python3.10/site-packages/urllib3/connection.py", line 239, in request
    super(HTTPConnection, self).request(method, url, body=body, headers=headers)
  File "/usr/local/lib/python3.10/http/client.py", line 1282, in request
    self._send_request(method, url, body, headers, encode_chunked)
  File "/usr/local/lib/python3.10/http/client.py", line 1328, in _send_request
    self.endheaders(body, encode_chunked=encode_chunked)
  File "/usr/local/lib/python3.10/http/client.py", line 1277, in endheaders
    self._send_output(message_body, encode_chunked=encode_chunked)
  File "/usr/local/lib/python3.10/http/client.py", line 1037, in _send_output
    self.send(msg)
  File "/usr/local/lib/python3.10/http/client.py", line 975, in send
    self.connect()
  File "/usr/local/lib/python3.10/site-packages/urllib3/connection.py", line 205, in connect
    conn = self._new_conn()
  File "/usr/local/lib/python3.10/site-packages/urllib3/connection.py", line 186, in _new_conn
    raise NewConnectionError(
urllib3.exceptions.NewConnectionError: <urllib3.connection.HTTPConnection object at 0x7f5d344a1e70>: Failed to establish a new connection: [Errno -2] Name or service not known

During handling of the above exception, another exception occurred:

Traceback (most recent call last):
  File "/usr/local/lib/python3.10/site-packages/asgiref/sync.py", line 472, in thread_handler
    raise exc_info[1]
  File "/usr/local/lib/python3.10/site-packages/django/core/handlers/exception.py", line 42, in inner
    response = await get_response(request)
  File "/usr/local/lib/python3.10/site-packages/django/core/handlers/base.py", line 253, in _get_response_async
    response = await wrapped_callback(
  File "/usr/local/lib/python3.10/site-packages/asgiref/sync.py", line 435, in __call__
    ret = await asyncio.wait_for(future, timeout=None)
  File "/usr/local/lib/python3.10/asyncio/tasks.py", line 408, in wait_for
    return await fut
  File "/usr/local/lib/python3.10/site-packages/asgiref/current_thread_executor.py", line 22, in run
    result = self.fn(*self.args, **self.kwargs)
  File "/usr/local/lib/python3.10/site-packages/asgiref/sync.py", line 476, in thread_handler
    return func(*args, **kwargs)
  File "/usr/local/lib/python3.10/site-packages/django/views/generic/base.py", line 103, in view
    return self.dispatch(request, *args, **kwargs)
  File "/usr/local/lib/python3.10/site-packages/django/contrib/auth/mixins.py", line 73, in dispatch
    return super().dispatch(request, *args, **kwargs)
  File "/usr/local/lib/python3.10/site-packages/django/views/generic/base.py", line 142, in dispatch
    return handler(request, *args, **kwargs)
  File "/usr/src/app/apps/delivery/views.py", line 157, in post
    order = Order.objects.create(restaurant=restaurant,
  File "/usr/local/lib/python3.10/site-packages/django/db/models/manager.py", line 85, in manager_method
    return getattr(self.get_queryset(), name)(*args, **kwargs)
  File "/usr/local/lib/python3.10/site-packages/django/db/models/query.py", line 671, in create
    obj.save(force_insert=True, using=self.db)
  File "/usr/src/app/apps/restaurants/models.py", line 474, in save
    super().save(*args, **kwargs)
  File "/usr/local/lib/python3.10/site-packages/django/db/models/base.py", line 831, in save
    self.save_base(
  File "/usr/local/lib/python3.10/site-packages/django/db/models/base.py", line 897, in save_base
    post_save.send(
  File "/usr/local/lib/python3.10/site-packages/django/dispatch/dispatcher.py", line 176, in send
    return [
  File "/usr/local/lib/python3.10/site-packages/django/dispatch/dispatcher.py", line 177, in <listcomp>
    (receiver, receiver(signal=self, sender=sender, **named))
  File "/usr/local/lib/python3.10/site-packages/django_elasticsearch_dsl/signals.py", line 58, in handle_save
    registry.update(instance)
  File "/usr/local/lib/python3.10/site-packages/django_elasticsearch_dsl/registries.py", line 141, in update
    doc().update(instance, **kwargs)
  File "/usr/local/lib/python3.10/site-packages/django_elasticsearch_dsl/documents.py", line 225, in update
    return self._bulk(
  File "/usr/local/lib/python3.10/site-packages/django_elasticsearch_dsl/documents.py", line 202, in _bulk
    return self.bulk(*args, **kwargs)
  File "/usr/local/lib/python3.10/site-packages/django_elasticsearch_dsl/documents.py", line 151, in bulk
    response = bulk(client=self._get_connection(), actions=actions, **kwargs)
  File "/usr/local/lib/python3.10/site-packages/elasticsearch/helpers/actions.py", line 410, in bulk
    for ok, item in streaming_bulk(
  File "/usr/local/lib/python3.10/site-packages/elasticsearch/helpers/actions.py", line 329, in streaming_bulk
    for data, (ok, info) in zip(
  File "/usr/local/lib/python3.10/site-packages/elasticsearch/helpers/actions.py", line 256, in _process_bulk_chunk
    for item in gen:
  File "/usr/local/lib/python3.10/site-packages/elasticsearch/helpers/actions.py", line 195, in _process_bulk_chunk_error
    raise error
  File "/usr/local/lib/python3.10/site-packages/elasticsearch/helpers/actions.py", line 240, in _process_bulk_chunk
    resp = client.bulk(*args, body="\n".join(bulk_actions) + "\n", **kwargs)
  File "/usr/local/lib/python3.10/site-packages/elasticsearch/client/utils.py", line 347, in _wrapped
    return func(*args, params=params, headers=headers, **kwargs)
  File "/usr/local/lib/python3.10/site-packages/elasticsearch/client/__init__.py", line 472, in bulk
    return self.transport.perform_request(
  File "/usr/local/lib/python3.10/site-packages/elasticsearch/transport.py", line 417, in perform_request
    self._do_verify_elasticsearch(headers=headers, timeout=timeout)
  File "/usr/local/lib/python3.10/site-packages/elasticsearch/transport.py", line 606, in _do_verify_elasticsearch
    raise error
  File "/usr/local/lib/python3.10/site-packages/elasticsearch/transport.py", line 569, in _do_verify_elasticsearch
    _, info_headers, info_response = conn.perform_request(
  File "/usr/local/lib/python3.10/site-packages/elasticsearch/connection/http_urllib3.py", line 280, in perform_request
    raise ConnectionError("N/A", str(e), e)
elasticsearch.exceptions.ConnectionError: ConnectionError(<urllib3.connection.HTTPConnection object at 0x7f5d344a1e70>: Failed to establish a new connection: [Errno -2] Name or service not known) caused by: NewConnectionError(<urllib3.connection.HTTPConnection object at 0x7f5d344a1e70>: Failed to establish a new connection: [Errno -2] Name or service not known)
2023-01-01 14:47:57,056 - [ERROR]    django.channels.server: [35;1mHTTP POST /delivery/cart/purchase/ 500 [2.82, 172.25.0.1:58496][0m
2023-01-01 14:49:16,317 - [ERROR]    django.request: Internal Server Error: /delivery/cart/purchase/
Traceback (most recent call last):
  File "/usr/local/lib/python3.10/site-packages/urllib3/connection.py", line 174, in _new_conn
    conn = connection.create_connection(
  File "/usr/local/lib/python3.10/site-packages/urllib3/util/connection.py", line 72, in create_connection
    for res in socket.getaddrinfo(host, port, family, socket.SOCK_STREAM):
  File "/usr/local/lib/python3.10/socket.py", line 955, in getaddrinfo
    for res in _socket.getaddrinfo(host, port, family, type, proto, flags):
socket.gaierror: [Errno -2] Name or service not known

During handling of the above exception, another exception occurred:

Traceback (most recent call last):
  File "/usr/local/lib/python3.10/site-packages/elasticsearch/connection/http_urllib3.py", line 255, in perform_request
    response = self.pool.urlopen(
  File "/usr/local/lib/python3.10/site-packages/urllib3/connectionpool.py", line 785, in urlopen
    retries = retries.increment(
  File "/usr/local/lib/python3.10/site-packages/urllib3/util/retry.py", line 525, in increment
    raise six.reraise(type(error), error, _stacktrace)
  File "/usr/local/lib/python3.10/site-packages/urllib3/packages/six.py", line 770, in reraise
    raise value
  File "/usr/local/lib/python3.10/site-packages/urllib3/connectionpool.py", line 703, in urlopen
    httplib_response = self._make_request(
  File "/usr/local/lib/python3.10/site-packages/urllib3/connectionpool.py", line 398, in _make_request
    conn.request(method, url, **httplib_request_kw)
  File "/usr/local/lib/python3.10/site-packages/urllib3/connection.py", line 239, in request
    super(HTTPConnection, self).request(method, url, body=body, headers=headers)
  File "/usr/local/lib/python3.10/http/client.py", line 1282, in request
    self._send_request(method, url, body, headers, encode_chunked)
  File "/usr/local/lib/python3.10/http/client.py", line 1328, in _send_request
    self.endheaders(body, encode_chunked=encode_chunked)
  File "/usr/local/lib/python3.10/http/client.py", line 1277, in endheaders
    self._send_output(message_body, encode_chunked=encode_chunked)
  File "/usr/local/lib/python3.10/http/client.py", line 1037, in _send_output
    self.send(msg)
  File "/usr/local/lib/python3.10/http/client.py", line 975, in send
    self.connect()
  File "/usr/local/lib/python3.10/site-packages/urllib3/connection.py", line 205, in connect
    conn = self._new_conn()
  File "/usr/local/lib/python3.10/site-packages/urllib3/connection.py", line 186, in _new_conn
    raise NewConnectionError(
urllib3.exceptions.NewConnectionError: <urllib3.connection.HTTPConnection object at 0x7f5d2eee5f90>: Failed to establish a new connection: [Errno -2] Name or service not known

During handling of the above exception, another exception occurred:

Traceback (most recent call last):
  File "/usr/local/lib/python3.10/site-packages/asgiref/sync.py", line 472, in thread_handler
    raise exc_info[1]
  File "/usr/local/lib/python3.10/site-packages/django/core/handlers/exception.py", line 42, in inner
    response = await get_response(request)
  File "/usr/local/lib/python3.10/site-packages/django/core/handlers/base.py", line 253, in _get_response_async
    response = await wrapped_callback(
  File "/usr/local/lib/python3.10/site-packages/asgiref/sync.py", line 435, in __call__
    ret = await asyncio.wait_for(future, timeout=None)
  File "/usr/local/lib/python3.10/asyncio/tasks.py", line 408, in wait_for
    return await fut
  File "/usr/local/lib/python3.10/site-packages/asgiref/current_thread_executor.py", line 22, in run
    result = self.fn(*self.args, **self.kwargs)
  File "/usr/local/lib/python3.10/site-packages/asgiref/sync.py", line 476, in thread_handler
    return func(*args, **kwargs)
  File "/usr/local/lib/python3.10/site-packages/django/views/generic/base.py", line 103, in view
    return self.dispatch(request, *args, **kwargs)
  File "/usr/local/lib/python3.10/site-packages/django/contrib/auth/mixins.py", line 73, in dispatch
    return super().dispatch(request, *args, **kwargs)
  File "/usr/local/lib/python3.10/site-packages/django/views/generic/base.py", line 142, in dispatch
    return handler(request, *args, **kwargs)
  File "/usr/src/app/apps/delivery/views.py", line 157, in post
    order = Order.objects.create(restaurant=restaurant,
  File "/usr/local/lib/python3.10/site-packages/django/db/models/manager.py", line 85, in manager_method
    return getattr(self.get_queryset(), name)(*args, **kwargs)
  File "/usr/local/lib/python3.10/site-packages/django/db/models/query.py", line 671, in create
    obj.save(force_insert=True, using=self.db)
  File "/usr/src/app/apps/restaurants/models.py", line 474, in save
    super().save(*args, **kwargs)
  File "/usr/local/lib/python3.10/site-packages/django/db/models/base.py", line 831, in save
    self.save_base(
  File "/usr/local/lib/python3.10/site-packages/django/db/models/base.py", line 897, in save_base
    post_save.send(
  File "/usr/local/lib/python3.10/site-packages/django/dispatch/dispatcher.py", line 176, in send
    return [
  File "/usr/local/lib/python3.10/site-packages/django/dispatch/dispatcher.py", line 177, in <listcomp>
    (receiver, receiver(signal=self, sender=sender, **named))
  File "/usr/local/lib/python3.10/site-packages/django_elasticsearch_dsl/signals.py", line 58, in handle_save
    registry.update(instance)
  File "/usr/local/lib/python3.10/site-packages/django_elasticsearch_dsl/registries.py", line 141, in update
    doc().update(instance, **kwargs)
  File "/usr/local/lib/python3.10/site-packages/django_elasticsearch_dsl/documents.py", line 225, in update
    return self._bulk(
  File "/usr/local/lib/python3.10/site-packages/django_elasticsearch_dsl/documents.py", line 202, in _bulk
    return self.bulk(*args, **kwargs)
  File "/usr/local/lib/python3.10/site-packages/django_elasticsearch_dsl/documents.py", line 151, in bulk
    response = bulk(client=self._get_connection(), actions=actions, **kwargs)
  File "/usr/local/lib/python3.10/site-packages/elasticsearch/helpers/actions.py", line 410, in bulk
    for ok, item in streaming_bulk(
  File "/usr/local/lib/python3.10/site-packages/elasticsearch/helpers/actions.py", line 329, in streaming_bulk
    for data, (ok, info) in zip(
  File "/usr/local/lib/python3.10/site-packages/elasticsearch/helpers/actions.py", line 256, in _process_bulk_chunk
    for item in gen:
  File "/usr/local/lib/python3.10/site-packages/elasticsearch/helpers/actions.py", line 195, in _process_bulk_chunk_error
    raise error
  File "/usr/local/lib/python3.10/site-packages/elasticsearch/helpers/actions.py", line 240, in _process_bulk_chunk
    resp = client.bulk(*args, body="\n".join(bulk_actions) + "\n", **kwargs)
  File "/usr/local/lib/python3.10/site-packages/elasticsearch/client/utils.py", line 347, in _wrapped
    return func(*args, params=params, headers=headers, **kwargs)
  File "/usr/local/lib/python3.10/site-packages/elasticsearch/client/__init__.py", line 472, in bulk
    return self.transport.perform_request(
  File "/usr/local/lib/python3.10/site-packages/elasticsearch/transport.py", line 417, in perform_request
    self._do_verify_elasticsearch(headers=headers, timeout=timeout)
  File "/usr/local/lib/python3.10/site-packages/elasticsearch/transport.py", line 606, in _do_verify_elasticsearch
    raise error
  File "/usr/local/lib/python3.10/site-packages/elasticsearch/transport.py", line 569, in _do_verify_elasticsearch
    _, info_headers, info_response = conn.perform_request(
  File "/usr/local/lib/python3.10/site-packages/elasticsearch/connection/http_urllib3.py", line 280, in perform_request
    raise ConnectionError("N/A", str(e), e)
elasticsearch.exceptions.ConnectionError: ConnectionError(<urllib3.connection.HTTPConnection object at 0x7f5d2eee5f90>: Failed to establish a new connection: [Errno -2] Name or service not known) caused by: NewConnectionError(<urllib3.connection.HTTPConnection object at 0x7f5d2eee5f90>: Failed to establish a new connection: [Errno -2] Name or service not known)
2023-01-01 14:49:16,640 - [ERROR]    django.channels.server: [35;1mHTTP POST /delivery/cart/purchase/ 500 [2.39, 172.25.0.1:34610][0m
2023-01-03 13:29:59,012 - [INFO]    django.utils.autoreload: Watching for file changes with StatReloader
2023-01-03 13:59:48,190 - [INFO]    django.channels.server: [mHTTP GET / 200 [5.94, 172.25.0.1:41326][0m
2023-01-03 14:03:59,500 - [INFO]    django.channels.server: [mHTTP GET / 200 [1.74, 172.25.0.1:52894][0m
2023-01-03 14:07:26,982 - [INFO]    django.channels.server: [mHTTP GET / 200 [0.27, 172.25.0.1:51506][0m
2023-01-03 14:09:55,677 - [INFO]    django.channels.server: [mHTTP GET /accounts/logout/ 200 [3.87, 172.25.0.1:46680][0m
2023-01-03 14:10:38,010 - [WARNING]    django.request: Not Found: /favicon.ico
2023-01-03 14:10:38,067 - [WARNING]    django.channels.server: [33mHTTP GET /favicon.ico 404 [0.31, 172.25.0.1:56578][0m
2023-01-03 14:10:56,578 - [INFO]    django.channels.server: [mHTTP GET / 200 [0.20, 172.25.0.1:37774][0m
2023-01-03 14:12:49,790 - [INFO]    django.channels.server: [32mHTTP POST /accounts/logout/ 302 [1.05, 172.25.0.1:34430][0m
2023-01-03 14:12:50,279 - [INFO]    django.channels.server: [mHTTP GET / 200 [0.46, 172.25.0.1:34436][0m
2023-01-03 14:30:34,976 - [INFO]    django.channels.server: [mHTTP GET /accounts/login/ 200 [1.58, 172.25.0.1:55950][0m
2023-01-03 14:31:06,918 - [INFO]    django.channels.server: [mHTTP POST /accounts/login/ 200 [1.78, 172.25.0.1:48826][0m
2023-01-03 14:31:34,934 - [INFO]    django.channels.server: [32mHTTP POST /accounts/login/ 302 [1.35, 172.25.0.1:50210][0m
2023-01-03 14:31:43,680 - [INFO]    django.channels.server: [mHTTP GET /accounts/profile/ 200 [8.71, 172.25.0.1:54248][0m
2023-01-03 14:34:58,368 - [INFO]    django.channels.server: [mHTTP GET /accounts/profile/ 200 [0.27, 172.25.0.1:59930][0m
2023-01-03 14:36:25,040 - [INFO]    django.channels.server: [32mHTTP POST /accounts/addresses/delete/ 302 [0.36, 172.25.0.1:47532][0m
2023-01-03 14:36:25,397 - [INFO]    django.channels.server: [mHTTP GET /accounts/profile/ 200 [0.32, 172.25.0.1:47534][0m
2023-01-03 14:51:11,311 - [WARNING]    django.request: Not Found: /Restaurant
2023-01-03 14:51:11,950 - [WARNING]    django.channels.server: [33mHTTP GET /Restaurant 404 [2.70, 172.25.0.1:36920][0m
2023-01-03 14:51:49,369 - [WARNING]    django.request: Not Found: /Restaurant/
2023-01-03 14:51:49,373 - [WARNING]    django.channels.server: [33mHTTP GET /Restaurant/ 404 [0.18, 172.25.0.1:57984][0m
2023-01-03 14:52:00,398 - [WARNING]    django.request: Not Found: /Restaurant/*
2023-01-03 14:52:00,405 - [WARNING]    django.channels.server: [33mHTTP GET /Restaurant/* 404 [0.19, 172.25.0.1:47290][0m
2023-01-05 02:36:18,271 - [INFO]    django.utils.autoreload: Watching for file changes with StatReloader
2023-01-05 02:57:23,131 - [INFO]    django.utils.autoreload: /home/djsadmin/Desktop/Projects/SampleProjects/Restaurant/apps/restaurants/migrations/0017_order_user_order_user_payment.py changed, reloading.
2023-01-05 02:57:27,926 - [INFO]    django.utils.autoreload: Watching for file changes with StatReloader
2023-01-05 03:00:18,941 - [INFO]    django.utils.autoreload: Watching for file changes with StatReloader
2023-01-05 03:01:20,422 - [INFO]    django.utils.autoreload: /home/djsadmin/Desktop/Projects/SampleProjects/Restaurant/conf/settings.py changed, reloading.
2023-01-05 03:01:22,278 - [INFO]    django.utils.autoreload: Watching for file changes with StatReloader
2023-01-05 03:05:01,855 - [INFO]    django.utils.autoreload: Watching for file changes with StatReloader
2023-01-05 03:29:16,938 - [WARNING]    django.request: Not Found: /sw.js
2023-01-05 03:29:17,710 - [WARNING]    django.channels.server: [33mHTTP GET /sw.js 404 [6.38, 127.0.0.1:49520][0m
2023-01-05 03:29:44,177 - [WARNING]    django.request: Not Found: /sw.js
2023-01-05 03:29:44,203 - [WARNING]    django.channels.server: [33mHTTP GET /sw.js 404 [2.93, 127.0.0.1:60378][0m
2023-01-05 03:31:22,881 - [INFO]    django.channels.server: [mHTTP GET / 200 [4.17, 127.0.0.1:44612][0m
2023-01-05 03:31:24,164 - [INFO]    django.channels.server: [mHTTP GET /static/assets/css/nucleo-icons.css 200 [0.40, 127.0.0.1:44612][0m
2023-01-05 03:31:24,291 - [INFO]    django.channels.server: [mHTTP GET /static/assets/css/nucleo-svg.css 200 [0.48, 127.0.0.1:51478][0m
2023-01-05 03:31:24,405 - [INFO]    django.channels.server: [mHTTP GET /static/assets/css/badge.css 200 [0.59, 127.0.0.1:51494][0m
2023-01-05 03:31:24,677 - [ERROR]    django.channels.server: [35;1mHTTP GET /static/assets/js/plugins/countup.min.js 500 [0.39, 127.0.0.1:51478][0m
2023-01-05 03:31:24,716 - [ERROR]    django.channels.server: [35;1mHTTP GET /static/assets/js/plugins/prism.min.js 500 [0.31, 127.0.0.1:51494][0m
2023-01-05 03:31:24,796 - [INFO]    django.channels.server: [mHTTP GET /static/assets/css/autocomplete.css 200 [0.98, 127.0.0.1:51504][0m
2023-01-05 03:31:24,936 - [INFO]    django.channels.server: [mHTTP GET /static/assets/js/core/popper.min.js 200 [1.12, 127.0.0.1:51510][0m
2023-01-05 03:31:25,110 - [INFO]    django.channels.server: [mHTTP GET /static/assets/js/material-kit.min.js 200 [0.89, 127.0.0.1:51526][0m
2023-01-05 03:31:25,180 - [INFO]    django.channels.server: [mHTTP GET /static/assets/js/plugins/highlight.min.js 200 [0.41, 127.0.0.1:51478][0m
2023-01-05 03:31:25,263 - [INFO]    django.channels.server: [mHTTP GET /static/assets/js/plugins/rellax.min.js 200 [0.49, 127.0.0.1:51494][0m
2023-01-05 03:31:25,370 - [INFO]    django.channels.server: [36mHTTP GET /static/debug_toolbar/js/toolbar.js 304 [0.17, 127.0.0.1:51478][0m
2023-01-05 03:31:25,539 - [INFO]    django.channels.server: [36mHTTP GET /static/debug_toolbar/js/utils.js 304 [0.06, 127.0.0.1:51478][0m
2023-01-05 03:31:25,763 - [ERROR]    django.channels.server: [35;1mHTTP GET /static/assets/js/plugins/tilt.min.js 500 [0.97, 127.0.0.1:51504][0m
2023-01-05 03:31:25,799 - [ERROR]    django.channels.server: [35;1mHTTP GET /static/assets/js/core/jquery.min.js 500 [0.86, 127.0.0.1:51510][0m
2023-01-05 03:31:25,849 - [ERROR]    django.channels.server: [35;1mHTTP GET /static/debug_toolbar/css/toolbar.css 500 [0.74, 127.0.0.1:51526][0m
2023-01-05 03:31:26,196 - [WARNING]    django.request: Not Found: /sw.js
2023-01-05 03:31:26,206 - [WARNING]    django.channels.server: [33mHTTP GET /sw.js 404 [6.48, 127.0.0.1:44616][0m
2023-01-05 03:31:28,450 - [INFO]    django.channels.server: [mHTTP GET /static/assets/img/apple-icon.png 200 [0.05, 127.0.0.1:51510][0m
2023-01-05 03:31:28,515 - [INFO]    django.channels.server: [mHTTP GET /static/assets/img/favicon.png 200 [0.12, 127.0.0.1:51494][0m
2023-01-05 03:31:29,273 - [WARNING]    django.request: Not Found: /sw.js
2023-01-05 03:31:29,282 - [INFO]    django.channels.server: [mHTTP GET /static/assets/js/plugins/countup.min.js 200 [0.08, 127.0.0.1:51510][0m
2023-01-05 03:31:29,297 - [WARNING]    django.channels.server: [33mHTTP GET /sw.js 404 [2.84, 127.0.0.1:51478][0m
2023-01-05 03:31:29,886 - [INFO]    django.channels.server: [mHTTP GET /static/assets/js/plugins/prism.min.js 200 [0.10, 127.0.0.1:51494][0m
2023-01-05 03:31:30,189 - [INFO]    django.channels.server: [mHTTP GET /static/assets/js/plugins/tilt.min.js 200 [0.25, 127.0.0.1:51494][0m
2023-01-05 03:31:30,627 - [INFO]    django.channels.server: [mHTTP GET /static/assets/js/core/jquery.min.js 200 [0.20, 127.0.0.1:51494][0m
2023-01-05 03:31:30,892 - [INFO]    django.channels.server: [mHTTP GET /static/debug_toolbar/css/toolbar.css 200 [0.20, 127.0.0.1:51494][0m
2023-01-05 03:31:31,025 - [INFO]    django.channels.server: [mHTTP GET /static/debug_toolbar/css/print.css 200 [0.13, 127.0.0.1:51526][0m
2023-01-05 03:31:32,643 - [WARNING]    django.request: Not Found: /sw.js
2023-01-05 03:31:32,653 - [WARNING]    django.channels.server: [33mHTTP GET /sw.js 404 [3.18, 127.0.0.1:51510][0m
2023-01-05 03:31:36,741 - [WARNING]    django.request: Not Found: /sw.js
2023-01-05 03:31:36,750 - [WARNING]    django.channels.server: [33mHTTP GET /sw.js 404 [3.11, 127.0.0.1:51494][0m
2023-01-05 03:31:46,533 - [WARNING]    django.request: Not Found: /sw.js
2023-01-05 03:31:46,546 - [WARNING]    django.channels.server: [33mHTTP GET /sw.js 404 [2.86, 127.0.0.1:51504][0m
2023-01-05 03:37:39,571 - [INFO]    django.channels.server: [mHTTP GET / 200 [4.02, 127.0.0.1:50662][0m
2023-01-05 03:37:42,802 - [WARNING]    django.request: Not Found: /sw.js
2023-01-05 03:37:42,815 - [WARNING]    django.channels.server: [33mHTTP GET /sw.js 404 [6.17, 127.0.0.1:50670][0m
2023-01-05 03:37:45,541 - [WARNING]    django.request: Not Found: /sw.js
2023-01-05 03:37:45,560 - [WARNING]    django.channels.server: [33mHTTP GET /sw.js 404 [2.63, 127.0.0.1:50682][0m
2023-01-05 03:37:50,112 - [WARNING]    django.request: Not Found: /sw.js
2023-01-05 03:37:50,124 - [WARNING]    django.channels.server: [33mHTTP GET /sw.js 404 [3.16, 127.0.0.1:59590][0m
2023-01-05 03:38:15,009 - [INFO]    django.channels.server: [mHTTP GET / 200 [2.84, 127.0.0.1:44634][0m
2023-01-05 03:38:18,505 - [WARNING]    django.request: Not Found: /sw.js
2023-01-05 03:38:18,519 - [WARNING]    django.channels.server: [33mHTTP GET /sw.js 404 [5.32, 127.0.0.1:53434][0m
2023-01-05 03:38:21,931 - [WARNING]    django.request: Not Found: /sw.js
2023-01-05 03:38:21,944 - [WARNING]    django.channels.server: [33mHTTP GET /sw.js 404 [3.30, 127.0.0.1:44634][0m
2023-01-05 03:59:48,933 - [INFO]    django.channels.server: [mHTTP GET / 200 [4.33, 127.0.0.1:46232][0m
2023-01-05 03:59:51,455 - [INFO]    django.channels.server: [mHTTP GET /static/assets/css/nucleo-icons.css 200 [0.69, 127.0.0.1:46232][0m
2023-01-05 03:59:51,582 - [INFO]    django.channels.server: [mHTTP GET /static/assets/css/nucleo-svg.css 200 [0.79, 127.0.0.1:34590][0m
2023-01-05 03:59:51,682 - [INFO]    django.channels.server: [mHTTP GET /static/assets/css/badge.css 200 [0.89, 127.0.0.1:34602][0m
2023-01-05 03:59:51,816 - [INFO]    django.channels.server: [mHTTP GET /static/assets/css/autocomplete.css 200 [1.02, 127.0.0.1:34614][0m
2023-01-05 03:59:51,871 - [WARNING]    django.request: Not Found: /sw.js
2023-01-05 03:59:51,888 - [WARNING]    django.channels.server: [33mHTTP GET /sw.js 404 [6.17, 127.0.0.1:46244][0m
2023-01-05 03:59:51,901 - [INFO]    django.channels.server: [mHTTP GET /static/assets/js/core/popper.min.js 200 [1.10, 127.0.0.1:34624][0m
2023-01-05 03:59:51,969 - [INFO]    django.channels.server: [mHTTP GET /static/assets/js/plugins/tilt.min.js 200 [0.05, 127.0.0.1:34634][0m
2023-01-05 03:59:52,165 - [ERROR]    django.channels.server: [35;1mHTTP GET /static/assets/js/plugins/countup.min.js 500 [0.58, 127.0.0.1:34590][0m
2023-01-05 03:59:52,191 - [ERROR]    django.channels.server: [35;1mHTTP GET /static/assets/js/plugins/prism.min.js 500 [0.51, 127.0.0.1:34602][0m
2023-01-05 03:59:52,205 - [ERROR]    django.channels.server: [35;1mHTTP GET /static/assets/js/plugins/highlight.min.js 500 [0.39, 127.0.0.1:34614][0m
2023-01-05 03:59:52,218 - [ERROR]    django.channels.server: [35;1mHTTP GET /static/assets/js/plugins/rellax.min.js 500 [0.32, 127.0.0.1:34624][0m
2023-01-05 03:59:52,232 - [ERROR]    django.channels.server: [35;1mHTTP GET /static/assets/js/core/jquery.min.js 500 [0.27, 127.0.0.1:34634][0m
2023-01-05 03:59:52,251 - [INFO]    django.channels.server: [mHTTP GET /static/debug_toolbar/css/toolbar.css 200 [0.21, 127.0.0.1:34638][0m
2023-01-05 03:59:53,894 - [INFO]    django.channels.server: [mHTTP GET /static/assets/js/plugins/countup.min.js 200 [0.12, 127.0.0.1:34624][0m
2023-01-05 03:59:55,755 - [INFO]    django.channels.server: [mHTTP GET /static/assets/js/plugins/prism.min.js 200 [0.24, 127.0.0.1:34634][0m
2023-01-05 03:59:55,979 - [INFO]    django.channels.server: [mHTTP GET /static/assets/js/plugins/highlight.min.js 200 [0.18, 127.0.0.1:34634][0m
2023-01-05 03:59:56,253 - [INFO]    django.channels.server: [mHTTP GET /static/assets/js/plugins/rellax.min.js 200 [0.21, 127.0.0.1:34634][0m
2023-01-05 03:59:56,441 - [INFO]    django.channels.server: [mHTTP GET /static/assets/js/core/jquery.min.js 200 [0.12, 127.0.0.1:34634][0m
2023-01-05 03:59:57,038 - [WARNING]    django.request: Not Found: /sw.js
2023-01-05 03:59:57,049 - [WARNING]    django.channels.server: [33mHTTP GET /sw.js 404 [2.95, 127.0.0.1:34624][0m
2023-01-05 04:00:02,327 - [WARNING]    django.request: Not Found: /sw.js
2023-01-05 04:00:02,340 - [WARNING]    django.channels.server: [33mHTTP GET /sw.js 404 [3.38, 127.0.0.1:34634][0m
2023-01-05 04:00:10,137 - [WARNING]    django.request: Not Found: /bankgateways/
2023-01-05 04:00:10,169 - [WARNING]    django.channels.server: [33mHTTP GET /bankgateways/ 404 [2.91, 127.0.0.1:34638][0m
2023-01-05 04:00:13,301 - [WARNING]    django.request: Not Found: /sw.js
2023-01-05 04:00:13,315 - [WARNING]    django.channels.server: [33mHTTP GET /sw.js 404 [4.81, 127.0.0.1:34602][0m
2023-01-05 04:00:20,549 - [WARNING]    django.request: Not Found: /sw.js
2023-01-05 04:00:20,569 - [WARNING]    django.channels.server: [33mHTTP GET /sw.js 404 [2.81, 127.0.0.1:34590][0m
2023-01-05 04:00:35,775 - [WARNING]    django.request: Not Found: /sw.js
2023-01-05 04:00:35,806 - [WARNING]    django.channels.server: [33mHTTP GET /sw.js 404 [2.91, 127.0.0.1:40532][0m
2023-01-05 04:00:53,844 - [INFO]    django.channels.server: [mHTTP GET /bankgateways/sample-payment/ 200 [22.06, 127.0.0.1:34614][0m
2023-01-05 04:00:59,448 - [WARNING]    django.request: Not Found: /sw.js
2023-01-05 04:00:59,477 - [WARNING]    django.channels.server: [33mHTTP GET /sw.js 404 [4.17, 127.0.0.1:34614][0m
2023-01-05 04:00:59,594 - [ERROR]    django.request: Internal Server Error: /bankgateways/sample-payment/
Traceback (most recent call last):
  File "/home/djsadmin/.virtualenvs/rstrnt/lib/python3.10/site-packages/asgiref/sync.py", line 472, in thread_handler
    raise exc_info[1]
  File "/home/djsadmin/.virtualenvs/rstrnt/lib/python3.10/site-packages/django/core/handlers/exception.py", line 42, in inner
    response = await get_response(request)
  File "/home/djsadmin/.virtualenvs/rstrnt/lib/python3.10/site-packages/django/core/handlers/base.py", line 253, in _get_response_async
    response = await wrapped_callback(
  File "/home/djsadmin/.virtualenvs/rstrnt/lib/python3.10/site-packages/asgiref/sync.py", line 435, in __call__
    ret = await asyncio.wait_for(future, timeout=None)
  File "/usr/lib/python3.10/asyncio/tasks.py", line 408, in wait_for
    return await fut
  File "/home/djsadmin/.virtualenvs/rstrnt/lib/python3.10/site-packages/asgiref/current_thread_executor.py", line 22, in run
    result = self.fn(*self.args, **self.kwargs)
  File "/home/djsadmin/.virtualenvs/rstrnt/lib/python3.10/site-packages/asgiref/sync.py", line 476, in thread_handler
    return func(*args, **kwargs)
  File "/home/djsadmin/.virtualenvs/rstrnt/lib/python3.10/site-packages/azbankgateways/views/samples.py", line 45, in sample_payment_view
    raise e
  File "/home/djsadmin/.virtualenvs/rstrnt/lib/python3.10/site-packages/azbankgateways/views/samples.py", line 27, in sample_payment_view
    bank = factory.auto_create()
  File "/home/djsadmin/.virtualenvs/rstrnt/lib/python3.10/site-packages/azbankgateways/bankfactories.py", line 60, in auto_create
    raise BankGatewayAutoConnectionFailed()
azbankgateways.exceptions.exceptions.BankGatewayAutoConnectionFailed
2023-01-05 04:01:02,144 - [ERROR]    django.channels.server: [35;1mHTTP POST /bankgateways/sample-payment/ 500 [5.81, 127.0.0.1:59036][0m
2023-01-05 04:01:07,041 - [WARNING]    django.request: Not Found: /sw.js
2023-01-05 04:01:07,058 - [WARNING]    django.channels.server: [33mHTTP GET /sw.js 404 [3.65, 127.0.0.1:59036][0m
2023-01-05 04:01:29,509 - [ERROR]    django.request: Internal Server Error: /bankgateways/sample-payment/
Traceback (most recent call last):
  File "/home/djsadmin/.virtualenvs/rstrnt/lib/python3.10/site-packages/asgiref/sync.py", line 472, in thread_handler
    raise exc_info[1]
  File "/home/djsadmin/.virtualenvs/rstrnt/lib/python3.10/site-packages/django/core/handlers/exception.py", line 42, in inner
    response = await get_response(request)
  File "/home/djsadmin/.virtualenvs/rstrnt/lib/python3.10/site-packages/django/core/handlers/base.py", line 253, in _get_response_async
    response = await wrapped_callback(
  File "/home/djsadmin/.virtualenvs/rstrnt/lib/python3.10/site-packages/asgiref/sync.py", line 435, in __call__
    ret = await asyncio.wait_for(future, timeout=None)
  File "/usr/lib/python3.10/asyncio/tasks.py", line 408, in wait_for
    return await fut
  File "/home/djsadmin/.virtualenvs/rstrnt/lib/python3.10/site-packages/asgiref/current_thread_executor.py", line 22, in run
    result = self.fn(*self.args, **self.kwargs)
  File "/home/djsadmin/.virtualenvs/rstrnt/lib/python3.10/site-packages/asgiref/sync.py", line 476, in thread_handler
    return func(*args, **kwargs)
  File "/home/djsadmin/.virtualenvs/rstrnt/lib/python3.10/site-packages/azbankgateways/views/samples.py", line 45, in sample_payment_view
    raise e
  File "/home/djsadmin/.virtualenvs/rstrnt/lib/python3.10/site-packages/azbankgateways/views/samples.py", line 27, in sample_payment_view
    bank = factory.auto_create()
  File "/home/djsadmin/.virtualenvs/rstrnt/lib/python3.10/site-packages/azbankgateways/bankfactories.py", line 60, in auto_create
    raise BankGatewayAutoConnectionFailed()
azbankgateways.exceptions.exceptions.BankGatewayAutoConnectionFailed
2023-01-05 04:01:33,628 - [ERROR]    django.channels.server: [35;1mHTTP POST /bankgateways/sample-payment/ 500 [5.40, 127.0.0.1:56982][0m
2023-01-05 04:01:36,333 - [WARNING]    django.request: Not Found: /sw.js
2023-01-05 04:01:36,344 - [WARNING]    django.channels.server: [33mHTTP GET /sw.js 404 [7.06, 127.0.0.1:56994][0m
2023-01-05 04:02:17,384 - [WARNING]    django.request: Not Found: /sw.js
2023-01-05 04:02:17,395 - [WARNING]    django.channels.server: [33mHTTP GET /sw.js 404 [3.43, 127.0.0.1:43168][0m
2023-01-05 04:02:19,068 - [ERROR]    django.request: Internal Server Error: /bankgateways/sample-payment/
Traceback (most recent call last):
  File "/home/djsadmin/.virtualenvs/rstrnt/lib/python3.10/site-packages/asgiref/sync.py", line 472, in thread_handler
    raise exc_info[1]
  File "/home/djsadmin/.virtualenvs/rstrnt/lib/python3.10/site-packages/django/core/handlers/exception.py", line 42, in inner
    response = await get_response(request)
  File "/home/djsadmin/.virtualenvs/rstrnt/lib/python3.10/site-packages/django/core/handlers/base.py", line 253, in _get_response_async
    response = await wrapped_callback(
  File "/home/djsadmin/.virtualenvs/rstrnt/lib/python3.10/site-packages/asgiref/sync.py", line 435, in __call__
    ret = await asyncio.wait_for(future, timeout=None)
  File "/usr/lib/python3.10/asyncio/tasks.py", line 408, in wait_for
    return await fut
  File "/home/djsadmin/.virtualenvs/rstrnt/lib/python3.10/site-packages/asgiref/current_thread_executor.py", line 22, in run
    result = self.fn(*self.args, **self.kwargs)
  File "/home/djsadmin/.virtualenvs/rstrnt/lib/python3.10/site-packages/asgiref/sync.py", line 476, in thread_handler
    return func(*args, **kwargs)
  File "/home/djsadmin/.virtualenvs/rstrnt/lib/python3.10/site-packages/azbankgateways/views/samples.py", line 45, in sample_payment_view
    raise e
  File "/home/djsadmin/.virtualenvs/rstrnt/lib/python3.10/site-packages/azbankgateways/views/samples.py", line 27, in sample_payment_view
    bank = factory.auto_create()
  File "/home/djsadmin/.virtualenvs/rstrnt/lib/python3.10/site-packages/azbankgateways/bankfactories.py", line 60, in auto_create
    raise BankGatewayAutoConnectionFailed()
azbankgateways.exceptions.exceptions.BankGatewayAutoConnectionFailed
2023-01-05 04:02:22,147 - [ERROR]    django.channels.server: [35;1mHTTP POST /bankgateways/sample-payment/ 500 [9.43, 127.0.0.1:56982][0m
2023-01-05 04:02:29,787 - [WARNING]    django.request: Not Found: /sw.js
2023-01-05 04:02:29,798 - [WARNING]    django.channels.server: [33mHTTP GET /sw.js 404 [5.37, 127.0.0.1:56982][0m
2023-01-05 04:03:37,599 - [ERROR]    django.request: Internal Server Error: /bankgateways/sample-payment/
Traceback (most recent call last):
  File "/home/djsadmin/.virtualenvs/rstrnt/lib/python3.10/site-packages/asgiref/sync.py", line 472, in thread_handler
    raise exc_info[1]
  File "/home/djsadmin/.virtualenvs/rstrnt/lib/python3.10/site-packages/django/core/handlers/exception.py", line 42, in inner
    response = await get_response(request)
  File "/home/djsadmin/.virtualenvs/rstrnt/lib/python3.10/site-packages/django/core/handlers/base.py", line 253, in _get_response_async
    response = await wrapped_callback(
  File "/home/djsadmin/.virtualenvs/rstrnt/lib/python3.10/site-packages/asgiref/sync.py", line 435, in __call__
    ret = await asyncio.wait_for(future, timeout=None)
  File "/usr/lib/python3.10/asyncio/tasks.py", line 408, in wait_for
    return await fut
  File "/home/djsadmin/.virtualenvs/rstrnt/lib/python3.10/site-packages/asgiref/current_thread_executor.py", line 22, in run
    result = self.fn(*self.args, **self.kwargs)
  File "/home/djsadmin/.virtualenvs/rstrnt/lib/python3.10/site-packages/asgiref/sync.py", line 476, in thread_handler
    return func(*args, **kwargs)
  File "/home/djsadmin/.virtualenvs/rstrnt/lib/python3.10/site-packages/azbankgateways/views/samples.py", line 45, in sample_payment_view
    raise e
  File "/home/djsadmin/.virtualenvs/rstrnt/lib/python3.10/site-packages/azbankgateways/views/samples.py", line 27, in sample_payment_view
    bank = factory.auto_create()
  File "/home/djsadmin/.virtualenvs/rstrnt/lib/python3.10/site-packages/azbankgateways/bankfactories.py", line 60, in auto_create
    raise BankGatewayAutoConnectionFailed()
azbankgateways.exceptions.exceptions.BankGatewayAutoConnectionFailed
2023-01-05 04:03:41,684 - [WARNING]    django.request: Not Found: /sw.js
2023-01-05 04:03:41,723 - [WARNING]    django.channels.server: [33mHTTP GET /sw.js 404 [6.17, 127.0.0.1:57022][0m
2023-01-05 04:03:43,881 - [ERROR]    django.channels.server: [35;1mHTTP POST /bankgateways/sample-payment/ 500 [9.42, 127.0.0.1:57012][0m
2023-01-05 04:03:48,715 - [WARNING]    django.request: Not Found: /sw.js
2023-01-05 04:03:48,737 - [WARNING]    django.channels.server: [33mHTTP GET /sw.js 404 [3.57, 127.0.0.1:57012][0m
2023-01-05 04:04:28,588 - [ERROR]    django.request: Internal Server Error: /bankgateways/sample-payment/
Traceback (most recent call last):
  File "/home/djsadmin/.virtualenvs/rstrnt/lib/python3.10/site-packages/asgiref/sync.py", line 472, in thread_handler
    raise exc_info[1]
  File "/home/djsadmin/.virtualenvs/rstrnt/lib/python3.10/site-packages/django/core/handlers/exception.py", line 42, in inner
    response = await get_response(request)
  File "/home/djsadmin/.virtualenvs/rstrnt/lib/python3.10/site-packages/django/core/handlers/base.py", line 253, in _get_response_async
    response = await wrapped_callback(
  File "/home/djsadmin/.virtualenvs/rstrnt/lib/python3.10/site-packages/asgiref/sync.py", line 435, in __call__
    ret = await asyncio.wait_for(future, timeout=None)
  File "/usr/lib/python3.10/asyncio/tasks.py", line 408, in wait_for
    return await fut
  File "/home/djsadmin/.virtualenvs/rstrnt/lib/python3.10/site-packages/asgiref/current_thread_executor.py", line 22, in run
    result = self.fn(*self.args, **self.kwargs)
  File "/home/djsadmin/.virtualenvs/rstrnt/lib/python3.10/site-packages/asgiref/sync.py", line 476, in thread_handler
    return func(*args, **kwargs)
  File "/home/djsadmin/.virtualenvs/rstrnt/lib/python3.10/site-packages/azbankgateways/views/samples.py", line 45, in sample_payment_view
    raise e
  File "/home/djsadmin/.virtualenvs/rstrnt/lib/python3.10/site-packages/azbankgateways/views/samples.py", line 27, in sample_payment_view
    bank = factory.auto_create()
  File "/home/djsadmin/.virtualenvs/rstrnt/lib/python3.10/site-packages/azbankgateways/bankfactories.py", line 53, in auto_create
    bank.check_gateway(amount)
  File "/home/djsadmin/.virtualenvs/rstrnt/lib/python3.10/site-packages/azbankgateways/banks/banks.py", line 283, in check_gateway
    self.pay()
  File "/home/djsadmin/.virtualenvs/rstrnt/lib/python3.10/site-packages/azbankgateways/banks/zibal.py", line 72, in pay
    raise BankGatewayRejectPayment(self.get_transaction_status_text())
azbankgateways.exceptions.exceptions.BankGatewayRejectPayment: callbackUrl is not valid
2023-01-05 04:04:36,391 - [WARNING]    django.request: Not Found: /sw.js
2023-01-05 04:04:36,405 - [WARNING]    django.channels.server: [33mHTTP GET /sw.js 404 [8.19, 127.0.0.1:36082][0m
2023-01-05 04:04:36,419 - [ERROR]    django.channels.server: [35;1mHTTP POST /bankgateways/sample-payment/ 500 [9.28, 127.0.0.1:36080][0m
2023-01-05 04:04:41,193 - [WARNING]    django.request: Not Found: /sw.js
2023-01-05 04:04:41,205 - [WARNING]    django.channels.server: [33mHTTP GET /sw.js 404 [3.54, 127.0.0.1:36080][0m
2023-01-05 04:12:14,725 - [ERROR]    django.request: Internal Server Error: /bankgateways/sample-payment/
Traceback (most recent call last):
  File "/home/djsadmin/.virtualenvs/rstrnt/lib/python3.10/site-packages/asgiref/sync.py", line 472, in thread_handler
    raise exc_info[1]
  File "/home/djsadmin/.virtualenvs/rstrnt/lib/python3.10/site-packages/django/core/handlers/exception.py", line 42, in inner
    response = await get_response(request)
  File "/home/djsadmin/.virtualenvs/rstrnt/lib/python3.10/site-packages/django/core/handlers/base.py", line 253, in _get_response_async
    response = await wrapped_callback(
  File "/home/djsadmin/.virtualenvs/rstrnt/lib/python3.10/site-packages/asgiref/sync.py", line 435, in __call__
    ret = await asyncio.wait_for(future, timeout=None)
  File "/usr/lib/python3.10/asyncio/tasks.py", line 408, in wait_for
    return await fut
  File "/home/djsadmin/.virtualenvs/rstrnt/lib/python3.10/site-packages/asgiref/current_thread_executor.py", line 22, in run
    result = self.fn(*self.args, **self.kwargs)
  File "/home/djsadmin/.virtualenvs/rstrnt/lib/python3.10/site-packages/asgiref/sync.py", line 476, in thread_handler
    return func(*args, **kwargs)
  File "/home/djsadmin/.virtualenvs/rstrnt/lib/python3.10/site-packages/azbankgateways/views/samples.py", line 45, in sample_payment_view
    raise e
  File "/home/djsadmin/.virtualenvs/rstrnt/lib/python3.10/site-packages/azbankgateways/views/samples.py", line 27, in sample_payment_view
    bank = factory.auto_create()
  File "/home/djsadmin/.virtualenvs/rstrnt/lib/python3.10/site-packages/azbankgateways/bankfactories.py", line 53, in auto_create
    bank.check_gateway(amount)
  File "/home/djsadmin/.virtualenvs/rstrnt/lib/python3.10/site-packages/azbankgateways/banks/banks.py", line 283, in check_gateway
    self.pay()
  File "/home/djsadmin/.virtualenvs/rstrnt/lib/python3.10/site-packages/azbankgateways/banks/zibal.py", line 72, in pay
    raise BankGatewayRejectPayment(self.get_transaction_status_text())
azbankgateways.exceptions.exceptions.BankGatewayRejectPayment: callbackUrl is not valid
2023-01-05 04:12:18,089 - [WARNING]    django.request: Not Found: /sw.js
2023-01-05 04:12:18,113 - [WARNING]    django.channels.server: [33mHTTP GET /sw.js 404 [3.39, 127.0.0.1:36932][0m
2023-01-05 04:12:18,148 - [ERROR]    django.channels.server: [35;1mHTTP POST /bankgateways/sample-payment/ 500 [4.48, 127.0.0.1:36926][0m
2023-01-05 04:12:20,721 - [WARNING]    django.request: Not Found: /sw.js
2023-01-05 04:12:20,741 - [WARNING]    django.channels.server: [33mHTTP GET /sw.js 404 [1.19, 127.0.0.1:36926][0m
2023-01-05 04:14:28,669 - [ERROR]    django.request: Internal Server Error: /bankgateways/sample-payment/
Traceback (most recent call last):
  File "/home/djsadmin/.virtualenvs/rstrnt/lib/python3.10/site-packages/asgiref/sync.py", line 472, in thread_handler
    raise exc_info[1]
  File "/home/djsadmin/.virtualenvs/rstrnt/lib/python3.10/site-packages/django/core/handlers/exception.py", line 42, in inner
    response = await get_response(request)
  File "/home/djsadmin/.virtualenvs/rstrnt/lib/python3.10/site-packages/django/core/handlers/base.py", line 253, in _get_response_async
    response = await wrapped_callback(
  File "/home/djsadmin/.virtualenvs/rstrnt/lib/python3.10/site-packages/asgiref/sync.py", line 435, in __call__
    ret = await asyncio.wait_for(future, timeout=None)
  File "/usr/lib/python3.10/asyncio/tasks.py", line 408, in wait_for
    return await fut
  File "/home/djsadmin/.virtualenvs/rstrnt/lib/python3.10/site-packages/asgiref/current_thread_executor.py", line 22, in run
    result = self.fn(*self.args, **self.kwargs)
  File "/home/djsadmin/.virtualenvs/rstrnt/lib/python3.10/site-packages/asgiref/sync.py", line 476, in thread_handler
    return func(*args, **kwargs)
  File "/home/djsadmin/.virtualenvs/rstrnt/lib/python3.10/site-packages/azbankgateways/views/samples.py", line 45, in sample_payment_view
    raise e
  File "/home/djsadmin/.virtualenvs/rstrnt/lib/python3.10/site-packages/azbankgateways/views/samples.py", line 27, in sample_payment_view
    bank = factory.auto_create()
  File "/home/djsadmin/.virtualenvs/rstrnt/lib/python3.10/site-packages/azbankgateways/bankfactories.py", line 53, in auto_create
    bank.check_gateway(amount)
  File "/home/djsadmin/.virtualenvs/rstrnt/lib/python3.10/site-packages/azbankgateways/banks/banks.py", line 283, in check_gateway
    self.pay()
  File "/home/djsadmin/.virtualenvs/rstrnt/lib/python3.10/site-packages/azbankgateways/banks/zibal.py", line 72, in pay
    raise BankGatewayRejectPayment(self.get_transaction_status_text())
azbankgateways.exceptions.exceptions.BankGatewayRejectPayment: callbackUrl is not valid
2023-01-05 04:15:11,819 - [WARNING]    django.request: Not Found: /sw.js
2023-01-05 04:15:11,836 - [WARNING]    django.channels.server: [33mHTTP GET /sw.js 404 [95.16, 127.0.0.1:36040][0m
2023-01-05 04:15:12,858 - [ERROR]    django.channels.server: [35;1mHTTP POST /bankgateways/sample-payment/ 500 [119.74, 127.0.0.1:36032][0m
2023-01-05 04:15:57,604 - [WARNING]    django.request: Not Found: /sw.js
2023-01-05 04:15:57,641 - [WARNING]    django.channels.server: [33mHTTP GET /sw.js 404 [43.03, 127.0.0.1:36032][0m
2023-01-05 04:20:27,098 - [ERROR]    django.request: Internal Server Error: /bankgateways/sample-payment/
Traceback (most recent call last):
  File "/home/djsadmin/.virtualenvs/rstrnt/lib/python3.10/site-packages/asgiref/sync.py", line 472, in thread_handler
    raise exc_info[1]
  File "/home/djsadmin/.virtualenvs/rstrnt/lib/python3.10/site-packages/django/core/handlers/exception.py", line 42, in inner
    response = await get_response(request)
  File "/home/djsadmin/.virtualenvs/rstrnt/lib/python3.10/site-packages/django/core/handlers/base.py", line 253, in _get_response_async
    response = await wrapped_callback(
  File "/home/djsadmin/.virtualenvs/rstrnt/lib/python3.10/site-packages/asgiref/sync.py", line 435, in __call__
    ret = await asyncio.wait_for(future, timeout=None)
  File "/usr/lib/python3.10/asyncio/tasks.py", line 408, in wait_for
    return await fut
  File "/home/djsadmin/.virtualenvs/rstrnt/lib/python3.10/site-packages/asgiref/current_thread_executor.py", line 22, in run
    result = self.fn(*self.args, **self.kwargs)
  File "/home/djsadmin/.virtualenvs/rstrnt/lib/python3.10/site-packages/asgiref/sync.py", line 476, in thread_handler
    return func(*args, **kwargs)
  File "/home/djsadmin/.virtualenvs/rstrnt/lib/python3.10/site-packages/azbankgateways/views/samples.py", line 45, in sample_payment_view
    raise e
  File "/home/djsadmin/.virtualenvs/rstrnt/lib/python3.10/site-packages/azbankgateways/views/samples.py", line 27, in sample_payment_view
    bank = factory.auto_create()
  File "/home/djsadmin/.virtualenvs/rstrnt/lib/python3.10/site-packages/azbankgateways/bankfactories.py", line 53, in auto_create
    bank.check_gateway(amount)
  File "/home/djsadmin/.virtualenvs/rstrnt/lib/python3.10/site-packages/azbankgateways/banks/banks.py", line 283, in check_gateway
    self.pay()
  File "/home/djsadmin/.virtualenvs/rstrnt/lib/python3.10/site-packages/azbankgateways/banks/zibal.py", line 72, in pay
    raise BankGatewayRejectPayment(self.get_transaction_status_text())
azbankgateways.exceptions.exceptions.BankGatewayRejectPayment: callbackUrl is not valid
2023-01-05 04:20:28,642 - [WARNING]    django.request: Not Found: /sw.js
2023-01-05 04:20:28,666 - [WARNING]    django.channels.server: [33mHTTP GET /sw.js 404 [241.42, 127.0.0.1:48040][0m
2023-01-05 04:20:29,480 - [ERROR]    django.channels.server: [35;1mHTTP POST /bankgateways/sample-payment/ 500 [245.06, 127.0.0.1:56460][0m
2023-01-05 04:20:39,694 - [WARNING]    django.request: Not Found: /sw.js
2023-01-05 04:20:39,715 - [WARNING]    django.channels.server: [33mHTTP GET /sw.js 404 [9.03, 127.0.0.1:56460][0m
2023-01-05 04:25:49,969 - [WARNING]    django.request: Not Found: /sw.js
2023-01-05 04:25:50,018 - [WARNING]    django.channels.server: [33mHTTP GET /sw.js 404 [42.53, 127.0.0.1:42598][0m
2023-01-05 04:31:09,258 - [ERROR]    django.request: Internal Server Error: /bankgateways/sample-payment/
Traceback (most recent call last):
  File "/home/djsadmin/.virtualenvs/rstrnt/lib/python3.10/site-packages/asgiref/sync.py", line 472, in thread_handler
    raise exc_info[1]
  File "/home/djsadmin/.virtualenvs/rstrnt/lib/python3.10/site-packages/django/core/handlers/exception.py", line 42, in inner
    response = await get_response(request)
  File "/home/djsadmin/.virtualenvs/rstrnt/lib/python3.10/site-packages/django/core/handlers/base.py", line 253, in _get_response_async
    response = await wrapped_callback(
  File "/home/djsadmin/.virtualenvs/rstrnt/lib/python3.10/site-packages/asgiref/sync.py", line 435, in __call__
    ret = await asyncio.wait_for(future, timeout=None)
  File "/usr/lib/python3.10/asyncio/tasks.py", line 408, in wait_for
    return await fut
  File "/home/djsadmin/.virtualenvs/rstrnt/lib/python3.10/site-packages/asgiref/current_thread_executor.py", line 22, in run
    result = self.fn(*self.args, **self.kwargs)
  File "/home/djsadmin/.virtualenvs/rstrnt/lib/python3.10/site-packages/asgiref/sync.py", line 476, in thread_handler
    return func(*args, **kwargs)
  File "/home/djsadmin/.virtualenvs/rstrnt/lib/python3.10/site-packages/azbankgateways/views/samples.py", line 45, in sample_payment_view
    raise e
  File "/home/djsadmin/.virtualenvs/rstrnt/lib/python3.10/site-packages/azbankgateways/views/samples.py", line 27, in sample_payment_view
    bank = factory.auto_create()
  File "/home/djsadmin/.virtualenvs/rstrnt/lib/python3.10/site-packages/azbankgateways/bankfactories.py", line 53, in auto_create
    bank.check_gateway(amount)
  File "/home/djsadmin/.virtualenvs/rstrnt/lib/python3.10/site-packages/azbankgateways/banks/banks.py", line 283, in check_gateway
    self.pay()
  File "/home/djsadmin/.virtualenvs/rstrnt/lib/python3.10/site-packages/azbankgateways/banks/zibal.py", line 72, in pay
    raise BankGatewayRejectPayment(self.get_transaction_status_text())
azbankgateways.exceptions.exceptions.BankGatewayRejectPayment: callbackUrl is not valid
2023-01-05 04:31:10,446 - [ERROR]    django.channels.server: [35;1mHTTP POST /bankgateways/sample-payment/ 500 [365.70, 127.0.0.1:42584][0m
2023-01-05 04:31:13,457 - [WARNING]    django.request: Not Found: /sw.js
2023-01-05 04:31:13,475 - [WARNING]    django.channels.server: [33mHTTP GET /sw.js 404 [1.20, 127.0.0.1:42584][0m
2023-01-05 04:58:23,451 - [ERROR]    django.request: Internal Server Error: /bankgateways/sample-payment/
Traceback (most recent call last):
  File "/home/djsadmin/.virtualenvs/rstrnt/lib/python3.10/site-packages/asgiref/sync.py", line 472, in thread_handler
    raise exc_info[1]
  File "/home/djsadmin/.virtualenvs/rstrnt/lib/python3.10/site-packages/django/core/handlers/exception.py", line 42, in inner
    response = await get_response(request)
  File "/home/djsadmin/.virtualenvs/rstrnt/lib/python3.10/site-packages/django/core/handlers/base.py", line 253, in _get_response_async
    response = await wrapped_callback(
  File "/home/djsadmin/.virtualenvs/rstrnt/lib/python3.10/site-packages/asgiref/sync.py", line 435, in __call__
    ret = await asyncio.wait_for(future, timeout=None)
  File "/usr/lib/python3.10/asyncio/tasks.py", line 408, in wait_for
    return await fut
  File "/home/djsadmin/.virtualenvs/rstrnt/lib/python3.10/site-packages/asgiref/current_thread_executor.py", line 22, in run
    result = self.fn(*self.args, **self.kwargs)
  File "/home/djsadmin/.virtualenvs/rstrnt/lib/python3.10/site-packages/asgiref/sync.py", line 476, in thread_handler
    return func(*args, **kwargs)
  File "/home/djsadmin/.virtualenvs/rstrnt/lib/python3.10/site-packages/azbankgateways/views/samples.py", line 45, in sample_payment_view
    raise e
  File "/home/djsadmin/.virtualenvs/rstrnt/lib/python3.10/site-packages/azbankgateways/views/samples.py", line 27, in sample_payment_view
    bank = factory.auto_create()
  File "/home/djsadmin/.virtualenvs/rstrnt/lib/python3.10/site-packages/azbankgateways/bankfactories.py", line 53, in auto_create
    bank.check_gateway(amount)
  File "/home/djsadmin/.virtualenvs/rstrnt/lib/python3.10/site-packages/azbankgateways/banks/banks.py", line 283, in check_gateway
    self.pay()
  File "/home/djsadmin/.virtualenvs/rstrnt/lib/python3.10/site-packages/azbankgateways/banks/zibal.py", line 72, in pay
    raise BankGatewayRejectPayment(self.get_transaction_status_text())
azbankgateways.exceptions.exceptions.BankGatewayRejectPayment: callbackUrl is not valid
2023-01-05 04:58:24,745 - [WARNING]    django.request: Not Found: /sw.js
2023-01-05 04:58:24,775 - [WARNING]    django.channels.server: [33mHTTP GET /sw.js 404 [821.66, 127.0.0.1:48734][0m
2023-01-05 04:58:25,666 - [ERROR]    django.channels.server: [35;1mHTTP POST /bankgateways/sample-payment/ 500 [837.12, 127.0.0.1:48722][0m
2023-01-05 04:58:29,128 - [WARNING]    django.request: Not Found: /sw.js
2023-01-05 04:58:29,157 - [WARNING]    django.channels.server: [33mHTTP GET /sw.js 404 [1.39, 127.0.0.1:48722][0m
2023-01-05 04:58:30,509 - [INFO]    django.channels.server: [mHTTP GET /static/debug_toolbar/css/print.css 200 [0.41, 127.0.0.1:58896][0m
2023-01-05 04:58:33,254 - [WARNING]    django.request: Not Found: /sw.js
2023-01-05 04:58:33,276 - [WARNING]    django.channels.server: [33mHTTP GET /sw.js 404 [1.28, 127.0.0.1:58896][0m
2023-01-05 04:58:45,002 - [ERROR]    django.request: Internal Server Error: /bankgateways/sample-payment/
Traceback (most recent call last):
  File "/home/djsadmin/.virtualenvs/rstrnt/lib/python3.10/site-packages/asgiref/sync.py", line 472, in thread_handler
    raise exc_info[1]
  File "/home/djsadmin/.virtualenvs/rstrnt/lib/python3.10/site-packages/django/core/handlers/exception.py", line 42, in inner
    response = await get_response(request)
  File "/home/djsadmin/.virtualenvs/rstrnt/lib/python3.10/site-packages/django/core/handlers/base.py", line 253, in _get_response_async
    response = await wrapped_callback(
  File "/home/djsadmin/.virtualenvs/rstrnt/lib/python3.10/site-packages/asgiref/sync.py", line 435, in __call__
    ret = await asyncio.wait_for(future, timeout=None)
  File "/usr/lib/python3.10/asyncio/tasks.py", line 408, in wait_for
    return await fut
  File "/home/djsadmin/.virtualenvs/rstrnt/lib/python3.10/site-packages/asgiref/current_thread_executor.py", line 22, in run
    result = self.fn(*self.args, **self.kwargs)
  File "/home/djsadmin/.virtualenvs/rstrnt/lib/python3.10/site-packages/asgiref/sync.py", line 476, in thread_handler
    return func(*args, **kwargs)
  File "/home/djsadmin/.virtualenvs/rstrnt/lib/python3.10/site-packages/azbankgateways/views/samples.py", line 45, in sample_payment_view
    raise e
  File "/home/djsadmin/.virtualenvs/rstrnt/lib/python3.10/site-packages/azbankgateways/views/samples.py", line 27, in sample_payment_view
    bank = factory.auto_create()
  File "/home/djsadmin/.virtualenvs/rstrnt/lib/python3.10/site-packages/azbankgateways/bankfactories.py", line 53, in auto_create
    bank.check_gateway(amount)
  File "/home/djsadmin/.virtualenvs/rstrnt/lib/python3.10/site-packages/azbankgateways/banks/banks.py", line 283, in check_gateway
    self.pay()
  File "/home/djsadmin/.virtualenvs/rstrnt/lib/python3.10/site-packages/azbankgateways/banks/zibal.py", line 72, in pay
    raise BankGatewayRejectPayment(self.get_transaction_status_text())
azbankgateways.exceptions.exceptions.BankGatewayRejectPayment: callbackUrl is not valid
2023-01-05 04:58:45,989 - [WARNING]    django.request: Not Found: /sw.js
2023-01-05 04:58:46,009 - [WARNING]    django.channels.server: [33mHTTP GET /sw.js 404 [3.06, 127.0.0.1:58926][0m
2023-01-05 04:58:46,822 - [ERROR]    django.channels.server: [35;1mHTTP POST /bankgateways/sample-payment/ 500 [12.36, 127.0.0.1:58912][0m
2023-01-05 04:58:49,375 - [WARNING]    django.request: Not Found: /sw.js
2023-01-05 04:58:49,400 - [WARNING]    django.channels.server: [33mHTTP GET /sw.js 404 [1.22, 127.0.0.1:58912][0m
2023-01-05 05:18:55,167 - [INFO]    django.utils.autoreload: Watching for file changes with StatReloader
2023-01-05 05:22:59,224 - [INFO]    django.utils.autoreload: Watching for file changes with StatReloader
2023-01-05 05:26:32,797 - [INFO]    django.utils.autoreload: Watching for file changes with StatReloader
2023-01-05 05:31:38,501 - [INFO]    django.utils.autoreload: Watching for file changes with StatReloader
2023-01-05 05:32:34,904 - [INFO]    django.utils.autoreload: Watching for file changes with StatReloader
2023-01-05 05:34:40,567 - [INFO]    django.utils.autoreload: Watching for file changes with StatReloader
2023-01-05 05:42:16,038 - [INFO]    django.utils.autoreload: Watching for file changes with StatReloader
2023-01-05 05:42:56,438 - [INFO]    django.channels.server: [mHTTP GET / 200 [1.69, 172.20.0.1:42948][0m
2023-01-05 05:43:24,261 - [INFO]    django.channels.server: [mHTTP GET /accounts/login/ 200 [0.85, 172.20.0.1:45200][0m
2023-01-05 05:44:10,937 - [INFO]    django.channels.server: [32mHTTP POST /accounts/login/ 302 [1.31, 172.20.0.1:37876][0m
2023-01-05 05:44:13,564 - [INFO]    django.channels.server: [mHTTP GET /accounts/profile/ 200 [2.33, 172.20.0.1:47726][0m
2023-01-05 05:46:15,996 - [ERROR]    django.security.SuspiciousFileOperation: The joined path (/empty-profile.jpg) is located outside of the base path component (/usr/src/app/static)
Traceback (most recent call last):
  File "/usr/local/lib/python3.10/site-packages/django/template/base.py", line 880, in _resolve_lookup
    current = current[bit]
TypeError: 'StaticFilesPanel' object is not subscriptable

During handling of the above exception, another exception occurred:

Traceback (most recent call last):
  File "/usr/local/lib/python3.10/site-packages/django/core/handlers/exception.py", line 55, in inner
    response = get_response(request)
  File "/usr/local/lib/python3.10/site-packages/debug_toolbar/middleware.py", line 74, in __call__
    rendered = toolbar.render_toolbar()
  File "/usr/local/lib/python3.10/site-packages/debug_toolbar/toolbar.py", line 79, in render_toolbar
    return render_to_string("debug_toolbar/base.html", context)
  File "/usr/local/lib/python3.10/site-packages/django/template/loader.py", line 62, in render_to_string
    return template.render(context, request)
  File "/usr/local/lib/python3.10/site-packages/django/template/backends/django.py", line 62, in render
    return self.template.render(context)
  File "/usr/local/lib/python3.10/site-packages/django/template/base.py", line 175, in render
    return self._render(context)
  File "/usr/local/lib/python3.10/site-packages/django/test/utils.py", line 111, in instrumented_test_render
    return self.nodelist.render(context)
  File "/usr/local/lib/python3.10/site-packages/django/template/base.py", line 1005, in render
    return SafeString("".join([node.render_annotated(context) for node in self]))
  File "/usr/local/lib/python3.10/site-packages/django/template/base.py", line 1005, in <listcomp>
    return SafeString("".join([node.render_annotated(context) for node in self]))
  File "/usr/local/lib/python3.10/site-packages/django/template/base.py", line 966, in render_annotated
    return self.render(context)
  File "/usr/local/lib/python3.10/site-packages/django/template/defaulttags.py", line 238, in render
    nodelist.append(node.render_annotated(context))
  File "/usr/local/lib/python3.10/site-packages/django/template/base.py", line 966, in render_annotated
    return self.render(context)
  File "/usr/local/lib/python3.10/site-packages/django/template/loader_tags.py", line 208, in render
    return template.render(context)
  File "/usr/local/lib/python3.10/site-packages/django/template/base.py", line 177, in render
    return self._render(context)
  File "/usr/local/lib/python3.10/site-packages/django/test/utils.py", line 111, in instrumented_test_render
    return self.nodelist.render(context)
  File "/usr/local/lib/python3.10/site-packages/django/template/base.py", line 1005, in render
    return SafeString("".join([node.render_annotated(context) for node in self]))
  File "/usr/local/lib/python3.10/site-packages/django/template/base.py", line 1005, in <listcomp>
    return SafeString("".join([node.render_annotated(context) for node in self]))
  File "/usr/local/lib/python3.10/site-packages/django/template/base.py", line 966, in render_annotated
    return self.render(context)
  File "/usr/local/lib/python3.10/site-packages/django/template/defaulttags.py", line 322, in render
    return nodelist.render(context)
  File "/usr/local/lib/python3.10/site-packages/django/template/base.py", line 1005, in render
    return SafeString("".join([node.render_annotated(context) for node in self]))
  File "/usr/local/lib/python3.10/site-packages/django/template/base.py", line 1005, in <listcomp>
    return SafeString("".join([node.render_annotated(context) for node in self]))
  File "/usr/local/lib/python3.10/site-packages/django/template/base.py", line 966, in render_annotated
    return self.render(context)
  File "/usr/local/lib/python3.10/site-packages/django/template/defaulttags.py", line 322, in render
    return nodelist.render(context)
  File "/usr/local/lib/python3.10/site-packages/django/template/base.py", line 1005, in render
    return SafeString("".join([node.render_annotated(context) for node in self]))
  File "/usr/local/lib/python3.10/site-packages/django/template/base.py", line 1005, in <listcomp>
    return SafeString("".join([node.render_annotated(context) for node in self]))
  File "/usr/local/lib/python3.10/site-packages/django/template/base.py", line 966, in render_annotated
    return self.render(context)
  File "/usr/local/lib/python3.10/site-packages/django/template/base.py", line 1064, in render
    output = self.filter_expression.resolve(context)
  File "/usr/local/lib/python3.10/site-packages/django/template/base.py", line 715, in resolve
    obj = self.var.resolve(context)
  File "/usr/local/lib/python3.10/site-packages/django/template/base.py", line 847, in resolve
    value = self._resolve_lookup(context)
  File "/usr/local/lib/python3.10/site-packages/django/template/base.py", line 890, in _resolve_lookup
    current = getattr(current, bit)
  File "/usr/local/lib/python3.10/site-packages/debug_toolbar/panels/__init__.py", line 104, in content
    return render_to_string(self.template, self.get_stats())
  File "/usr/local/lib/python3.10/site-packages/django/template/loader.py", line 62, in render_to_string
    return template.render(context, request)
  File "/usr/local/lib/python3.10/site-packages/django/template/backends/django.py", line 62, in render
    return self.template.render(context)
  File "/usr/local/lib/python3.10/site-packages/django/template/base.py", line 175, in render
    return self._render(context)
  File "/usr/local/lib/python3.10/site-packages/django/test/utils.py", line 111, in instrumented_test_render
    return self.nodelist.render(context)
  File "/usr/local/lib/python3.10/site-packages/django/template/base.py", line 1005, in render
    return SafeString("".join([node.render_annotated(context) for node in self]))
  File "/usr/local/lib/python3.10/site-packages/django/template/base.py", line 1005, in <listcomp>
    return SafeString("".join([node.render_annotated(context) for node in self]))
  File "/usr/local/lib/python3.10/site-packages/django/template/base.py", line 966, in render_annotated
    return self.render(context)
  File "/usr/local/lib/python3.10/site-packages/django/template/defaulttags.py", line 322, in render
    return nodelist.render(context)
  File "/usr/local/lib/python3.10/site-packages/django/template/base.py", line 1005, in render
    return SafeString("".join([node.render_annotated(context) for node in self]))
  File "/usr/local/lib/python3.10/site-packages/django/template/base.py", line 1005, in <listcomp>
    return SafeString("".join([node.render_annotated(context) for node in self]))
  File "/usr/local/lib/python3.10/site-packages/django/template/base.py", line 966, in render_annotated
    return self.render(context)
  File "/usr/local/lib/python3.10/site-packages/django/template/defaulttags.py", line 238, in render
    nodelist.append(node.render_annotated(context))
  File "/usr/local/lib/python3.10/site-packages/django/template/base.py", line 966, in render_annotated
    return self.render(context)
  File "/usr/local/lib/python3.10/site-packages/django/template/base.py", line 1064, in render
    output = self.filter_expression.resolve(context)
  File "/usr/local/lib/python3.10/site-packages/django/template/base.py", line 715, in resolve
    obj = self.var.resolve(context)
  File "/usr/local/lib/python3.10/site-packages/django/template/base.py", line 847, in resolve
    value = self._resolve_lookup(context)
  File "/usr/local/lib/python3.10/site-packages/django/template/base.py", line 914, in _resolve_lookup
    current = current()
  File "/usr/local/lib/python3.10/site-packages/debug_toolbar/panels/staticfiles.py", line 31, in real_path
    return finders.find(self.path)
  File "/usr/local/lib/python3.10/site-packages/django/contrib/staticfiles/finders.py", line 298, in find
    result = finder.find(path, all=all)
  File "/usr/local/lib/python3.10/site-packages/django/contrib/staticfiles/finders.py", line 124, in find
    matched_path = self.find_location(root, path, prefix)
  File "/usr/local/lib/python3.10/site-packages/django/contrib/staticfiles/finders.py", line 141, in find_location
    path = safe_join(root, path)
  File "/usr/local/lib/python3.10/site-packages/django/utils/_os.py", line 31, in safe_join
    raise SuspiciousFileOperation(
django.core.exceptions.SuspiciousFileOperation: The joined path (/empty-profile.jpg) is located outside of the base path component (/usr/src/app/static)
2023-01-05 05:46:16,391 - [WARNING]    django.request: Bad Request: /accounts/profile/
2023-01-05 05:46:16,395 - [WARNING]    django.channels.server: [31;1mHTTP GET /accounts/profile/ 400 [0.59, 172.20.0.1:39266][0m
2023-01-05 05:47:55,766 - [INFO]    django.utils.autoreload: /usr/src/app/apps/users/models.py changed, reloading.
2023-01-05 05:47:58,259 - [INFO]    django.utils.autoreload: Watching for file changes with StatReloader
2023-01-05 05:48:01,755 - [ERROR]    django.security.SuspiciousFileOperation: The joined path (/static/assets/img/no_image_available.png) is located outside of the base path component (/usr/src/app/static)
Traceback (most recent call last):
  File "/usr/local/lib/python3.10/site-packages/django/template/base.py", line 880, in _resolve_lookup
    current = current[bit]
TypeError: 'StaticFilesPanel' object is not subscriptable

During handling of the above exception, another exception occurred:

Traceback (most recent call last):
  File "/usr/local/lib/python3.10/site-packages/django/core/handlers/exception.py", line 55, in inner
    response = get_response(request)
  File "/usr/local/lib/python3.10/site-packages/debug_toolbar/middleware.py", line 74, in __call__
    rendered = toolbar.render_toolbar()
  File "/usr/local/lib/python3.10/site-packages/debug_toolbar/toolbar.py", line 79, in render_toolbar
    return render_to_string("debug_toolbar/base.html", context)
  File "/usr/local/lib/python3.10/site-packages/django/template/loader.py", line 62, in render_to_string
    return template.render(context, request)
  File "/usr/local/lib/python3.10/site-packages/django/template/backends/django.py", line 62, in render
    return self.template.render(context)
  File "/usr/local/lib/python3.10/site-packages/django/template/base.py", line 175, in render
    return self._render(context)
  File "/usr/local/lib/python3.10/site-packages/django/test/utils.py", line 111, in instrumented_test_render
    return self.nodelist.render(context)
  File "/usr/local/lib/python3.10/site-packages/django/template/base.py", line 1005, in render
    return SafeString("".join([node.render_annotated(context) for node in self]))
  File "/usr/local/lib/python3.10/site-packages/django/template/base.py", line 1005, in <listcomp>
    return SafeString("".join([node.render_annotated(context) for node in self]))
  File "/usr/local/lib/python3.10/site-packages/django/template/base.py", line 966, in render_annotated
    return self.render(context)
  File "/usr/local/lib/python3.10/site-packages/django/template/defaulttags.py", line 238, in render
    nodelist.append(node.render_annotated(context))
  File "/usr/local/lib/python3.10/site-packages/django/template/base.py", line 966, in render_annotated
    return self.render(context)
  File "/usr/local/lib/python3.10/site-packages/django/template/loader_tags.py", line 208, in render
    return template.render(context)
  File "/usr/local/lib/python3.10/site-packages/django/template/base.py", line 177, in render
    return self._render(context)
  File "/usr/local/lib/python3.10/site-packages/django/test/utils.py", line 111, in instrumented_test_render
    return self.nodelist.render(context)
  File "/usr/local/lib/python3.10/site-packages/django/template/base.py", line 1005, in render
    return SafeString("".join([node.render_annotated(context) for node in self]))
  File "/usr/local/lib/python3.10/site-packages/django/template/base.py", line 1005, in <listcomp>
    return SafeString("".join([node.render_annotated(context) for node in self]))
  File "/usr/local/lib/python3.10/site-packages/django/template/base.py", line 966, in render_annotated
    return self.render(context)
  File "/usr/local/lib/python3.10/site-packages/django/template/defaulttags.py", line 322, in render
    return nodelist.render(context)
  File "/usr/local/lib/python3.10/site-packages/django/template/base.py", line 1005, in render
    return SafeString("".join([node.render_annotated(context) for node in self]))
  File "/usr/local/lib/python3.10/site-packages/django/template/base.py", line 1005, in <listcomp>
    return SafeString("".join([node.render_annotated(context) for node in self]))
  File "/usr/local/lib/python3.10/site-packages/django/template/base.py", line 966, in render_annotated
    return self.render(context)
  File "/usr/local/lib/python3.10/site-packages/django/template/defaulttags.py", line 322, in render
    return nodelist.render(context)
  File "/usr/local/lib/python3.10/site-packages/django/template/base.py", line 1005, in render
    return SafeString("".join([node.render_annotated(context) for node in self]))
  File "/usr/local/lib/python3.10/site-packages/django/template/base.py", line 1005, in <listcomp>
    return SafeString("".join([node.render_annotated(context) for node in self]))
  File "/usr/local/lib/python3.10/site-packages/django/template/base.py", line 966, in render_annotated
    return self.render(context)
  File "/usr/local/lib/python3.10/site-packages/django/template/base.py", line 1064, in render
    output = self.filter_expression.resolve(context)
  File "/usr/local/lib/python3.10/site-packages/django/template/base.py", line 715, in resolve
    obj = self.var.resolve(context)
  File "/usr/local/lib/python3.10/site-packages/django/template/base.py", line 847, in resolve
    value = self._resolve_lookup(context)
  File "/usr/local/lib/python3.10/site-packages/django/template/base.py", line 890, in _resolve_lookup
    current = getattr(current, bit)
  File "/usr/local/lib/python3.10/site-packages/debug_toolbar/panels/__init__.py", line 104, in content
    return render_to_string(self.template, self.get_stats())
  File "/usr/local/lib/python3.10/site-packages/django/template/loader.py", line 62, in render_to_string
    return template.render(context, request)
  File "/usr/local/lib/python3.10/site-packages/django/template/backends/django.py", line 62, in render
    return self.template.render(context)
  File "/usr/local/lib/python3.10/site-packages/django/template/base.py", line 175, in render
    return self._render(context)
  File "/usr/local/lib/python3.10/site-packages/django/test/utils.py", line 111, in instrumented_test_render
    return self.nodelist.render(context)
  File "/usr/local/lib/python3.10/site-packages/django/template/base.py", line 1005, in render
    return SafeString("".join([node.render_annotated(context) for node in self]))
  File "/usr/local/lib/python3.10/site-packages/django/template/base.py", line 1005, in <listcomp>
    return SafeString("".join([node.render_annotated(context) for node in self]))
  File "/usr/local/lib/python3.10/site-packages/django/template/base.py", line 966, in render_annotated
    return self.render(context)
  File "/usr/local/lib/python3.10/site-packages/django/template/defaulttags.py", line 322, in render
    return nodelist.render(context)
  File "/usr/local/lib/python3.10/site-packages/django/template/base.py", line 1005, in render
    return SafeString("".join([node.render_annotated(context) for node in self]))
  File "/usr/local/lib/python3.10/site-packages/django/template/base.py", line 1005, in <listcomp>
    return SafeString("".join([node.render_annotated(context) for node in self]))
  File "/usr/local/lib/python3.10/site-packages/django/template/base.py", line 966, in render_annotated
    return self.render(context)
  File "/usr/local/lib/python3.10/site-packages/django/template/defaulttags.py", line 238, in render
    nodelist.append(node.render_annotated(context))
  File "/usr/local/lib/python3.10/site-packages/django/template/base.py", line 966, in render_annotated
    return self.render(context)
  File "/usr/local/lib/python3.10/site-packages/django/template/base.py", line 1064, in render
    output = self.filter_expression.resolve(context)
  File "/usr/local/lib/python3.10/site-packages/django/template/base.py", line 715, in resolve
    obj = self.var.resolve(context)
  File "/usr/local/lib/python3.10/site-packages/django/template/base.py", line 847, in resolve
    value = self._resolve_lookup(context)
  File "/usr/local/lib/python3.10/site-packages/django/template/base.py", line 914, in _resolve_lookup
    current = current()
  File "/usr/local/lib/python3.10/site-packages/debug_toolbar/panels/staticfiles.py", line 31, in real_path
    return finders.find(self.path)
  File "/usr/local/lib/python3.10/site-packages/django/contrib/staticfiles/finders.py", line 298, in find
    result = finder.find(path, all=all)
  File "/usr/local/lib/python3.10/site-packages/django/contrib/staticfiles/finders.py", line 124, in find
    matched_path = self.find_location(root, path, prefix)
  File "/usr/local/lib/python3.10/site-packages/django/contrib/staticfiles/finders.py", line 141, in find_location
    path = safe_join(root, path)
  File "/usr/local/lib/python3.10/site-packages/django/utils/_os.py", line 31, in safe_join
    raise SuspiciousFileOperation(
django.core.exceptions.SuspiciousFileOperation: The joined path (/static/assets/img/no_image_available.png) is located outside of the base path component (/usr/src/app/static)
2023-01-05 05:48:02,095 - [WARNING]    django.request: Bad Request: /accounts/profile/
2023-01-05 05:48:02,099 - [WARNING]    django.channels.server: [31;1mHTTP GET /accounts/profile/ 400 [1.32, 172.20.0.1:46288][0m
2023-01-05 05:48:13,423 - [INFO]    django.utils.autoreload: /usr/src/app/apps/users/models.py changed, reloading.
2023-01-05 05:48:15,998 - [INFO]    django.utils.autoreload: Watching for file changes with StatReloader
2023-01-05 05:48:34,475 - [INFO]    django.utils.autoreload: /usr/src/app/apps/users/models.py changed, reloading.
2023-01-05 05:48:37,110 - [INFO]    django.utils.autoreload: Watching for file changes with StatReloader
2023-01-05 05:48:39,932 - [INFO]    django.channels.server: [mHTTP GET /accounts/profile/ 200 [0.66, 172.20.0.1:41276][0m
2023-01-05 05:48:58,616 - [INFO]    django.channels.server: [mHTTP GET /accounts/profile/ 200 [0.35, 172.20.0.1:59076][0m
2023-01-05 05:49:33,092 - [INFO]    django.channels.server: [mHTTP GET /accounts/profile/ 200 [0.32, 172.20.0.1:47616][0m
2023-01-05 05:50:06,721 - [INFO]    django.channels.server: [mHTTP GET /accounts/profile/ 200 [0.31, 172.20.0.1:32936][0m
2023-01-05 05:50:14,699 - [INFO]    django.channels.server: [mHTTP GET /accounts/profile/ 200 [0.35, 172.20.0.1:33162][0m
2023-01-05 05:50:22,419 - [INFO]    django.channels.server: [mHTTP GET /accounts/profile/ 200 [0.38, 172.20.0.1:43556][0m
2023-01-05 05:50:28,540 - [INFO]    django.channels.server: [mHTTP GET /accounts/profile/ 200 [0.29, 172.20.0.1:43572][0m
2023-01-05 05:50:37,608 - [INFO]    django.channels.server: [mHTTP GET /accounts/profile/ 200 [0.85, 172.20.0.1:46646][0m
2023-01-05 05:50:47,497 - [INFO]    django.channels.server: [mHTTP GET /accounts/profile/? 200 [0.24, 172.20.0.1:53032][0m
2023-01-05 05:50:59,635 - [INFO]    django.channels.server: [32mHTTP GET /accounts/profile 301 [0.25, 172.20.0.1:42904][0m
2023-01-05 05:50:59,992 - [INFO]    django.channels.server: [mHTTP GET /accounts/profile/ 200 [0.31, 172.20.0.1:42908][0m
2023-01-05 05:51:33,905 - [INFO]    django.channels.server: [mHTTP GET /accounts/profile/ 200 [0.35, 172.20.0.1:52766][0m
2023-01-05 05:51:45,414 - [INFO]    django.channels.server: [mHTTP GET /accounts/profile/ 200 [0.30, 172.20.0.1:60392][0m
2023-01-05 05:52:02,459 - [INFO]    django.channels.server: [mHTTP GET /accounts/profile/ 200 [9.56, 172.20.0.1:60332][0m
2023-01-05 05:55:13,378 - [INFO]    django.channels.server: [mHTTP GET /accounts/profile/ 200 [0.40, 172.20.0.1:34706][0m
2023-01-05 05:55:23,703 - [INFO]    django.channels.server: [mHTTP GET /accounts/profile/ 200 [0.67, 172.20.0.1:58118][0m
2023-01-05 05:57:25,262 - [INFO]    django.channels.server: [mHTTP GET /accounts/profile/ 200 [0.32, 172.20.0.1:37040][0m
2023-01-05 06:02:07,262 - [INFO]    django.channels.server: [mHTTP GET /accounts/ 200 [0.55, 172.20.0.1:48370][0m
2023-01-05 06:04:14,924 - [INFO]    django.utils.autoreload: /usr/src/app/apps/users/models.py changed, reloading.
2023-01-05 06:04:37,456 - [INFO]    django.utils.autoreload: Watching for file changes with StatReloader
2023-01-05 06:06:13,805 - [INFO]    django.utils.autoreload: /usr/src/app/apps/users/views.py changed, reloading.
2023-01-05 06:06:16,574 - [INFO]    django.utils.autoreload: Watching for file changes with StatReloader
2023-01-05 06:06:19,765 - [INFO]    django.utils.autoreload: /usr/src/app/apps/users/views.py changed, reloading.
2023-01-05 06:06:22,226 - [INFO]    django.utils.autoreload: Watching for file changes with StatReloader
2023-01-05 06:07:25,162 - [INFO]    django.utils.autoreload: /usr/src/app/apps/users/views.py changed, reloading.
2023-01-05 06:07:27,720 - [INFO]    django.utils.autoreload: Watching for file changes with StatReloader
2023-01-05 06:28:13,464 - [INFO]    django.utils.autoreload: /usr/src/app/apps/users/forms.py changed, reloading.
2023-01-05 06:28:28,686 - [INFO]    django.utils.autoreload: Watching for file changes with StatReloader
2023-01-05 06:29:07,267 - [INFO]    django.utils.autoreload: /usr/src/app/apps/users/forms.py changed, reloading.
2023-01-05 06:29:10,325 - [INFO]    django.utils.autoreload: Watching for file changes with StatReloader
2023-01-05 06:29:18,987 - [INFO]    django.utils.autoreload: /usr/src/app/apps/users/forms.py changed, reloading.
2023-01-05 06:29:21,533 - [INFO]    django.utils.autoreload: Watching for file changes with StatReloader
2023-01-05 06:40:25,128 - [INFO]    django.utils.autoreload: /usr/src/app/apps/users/views.py changed, reloading.
2023-01-05 06:40:27,690 - [INFO]    django.utils.autoreload: Watching for file changes with StatReloader
2023-01-05 06:40:40,688 - [INFO]    django.utils.autoreload: /usr/src/app/apps/users/views.py changed, reloading.
2023-01-05 06:40:42,868 - [INFO]    django.utils.autoreload: Watching for file changes with StatReloader
2023-01-05 06:42:03,851 - [INFO]    django.utils.autoreload: /usr/src/app/apps/users/views.py changed, reloading.
2023-01-05 06:42:06,360 - [INFO]    django.utils.autoreload: Watching for file changes with StatReloader
2023-01-05 06:44:38,774 - [INFO]    django.utils.autoreload: /usr/src/app/apps/users/views.py changed, reloading.
2023-01-05 06:44:41,689 - [INFO]    django.utils.autoreload: Watching for file changes with StatReloader
2023-01-05 06:44:52,704 - [INFO]    django.utils.autoreload: /usr/src/app/apps/users/views.py changed, reloading.
2023-01-05 06:44:55,271 - [INFO]    django.utils.autoreload: Watching for file changes with StatReloader
2023-01-05 06:45:45,892 - [INFO]    django.utils.autoreload: /usr/src/app/apps/users/views.py changed, reloading.
2023-01-05 06:45:48,680 - [INFO]    django.utils.autoreload: Watching for file changes with StatReloader
2023-01-05 06:46:54,874 - [INFO]    django.utils.autoreload: /usr/src/app/apps/users/forms.py changed, reloading.
2023-01-05 06:46:57,232 - [INFO]    django.utils.autoreload: Watching for file changes with StatReloader
2023-01-05 06:50:30,498 - [INFO]    django.utils.autoreload: /usr/src/app/apps/users/views.py changed, reloading.
2023-01-05 06:50:33,637 - [INFO]    django.utils.autoreload: Watching for file changes with StatReloader
2023-01-05 06:52:43,685 - [INFO]    django.utils.autoreload: /usr/src/app/apps/users/views.py changed, reloading.
2023-01-05 06:52:46,263 - [INFO]    django.utils.autoreload: Watching for file changes with StatReloader
2023-01-05 06:52:50,055 - [ERROR]    django.request: Internal Server Error: /accounts/profile/
Traceback (most recent call last):
  File "/usr/local/lib/python3.10/site-packages/asgiref/sync.py", line 472, in thread_handler
    raise exc_info[1]
  File "/usr/local/lib/python3.10/site-packages/django/core/handlers/exception.py", line 42, in inner
    response = await get_response(request)
  File "/usr/local/lib/python3.10/site-packages/django/core/handlers/base.py", line 253, in _get_response_async
    response = await wrapped_callback(
  File "/usr/local/lib/python3.10/site-packages/asgiref/sync.py", line 435, in __call__
    ret = await asyncio.wait_for(future, timeout=None)
  File "/usr/local/lib/python3.10/asyncio/tasks.py", line 408, in wait_for
    return await fut
  File "/usr/local/lib/python3.10/site-packages/asgiref/current_thread_executor.py", line 22, in run
    result = self.fn(*self.args, **self.kwargs)
  File "/usr/local/lib/python3.10/site-packages/asgiref/sync.py", line 476, in thread_handler
    return func(*args, **kwargs)
  File "/usr/local/lib/python3.10/site-packages/django/views/generic/base.py", line 103, in view
    return self.dispatch(request, *args, **kwargs)
  File "/usr/local/lib/python3.10/site-packages/django/views/generic/base.py", line 142, in dispatch
    return handler(request, *args, **kwargs)
  File "/usr/src/app/apps/users/views.py", line 26, in get
    "change_user_form": ChangeUserForm(self.request),
  File "/usr/src/app/apps/users/forms.py", line 134, in __init__
    self.fields["last_name"].initial = last_name
KeyError: 'last_name'
2023-01-05 06:52:50,392 - [ERROR]    django.channels.server: [35;1mHTTP GET /accounts/profile/ 500 [1.38, 172.20.0.1:39912][0m
2023-01-05 06:53:16,039 - [INFO]    django.utils.autoreload: /usr/src/app/apps/users/forms.py changed, reloading.
2023-01-05 06:53:18,811 - [INFO]    django.utils.autoreload: Watching for file changes with StatReloader
2023-01-05 06:53:21,541 - [ERROR]    django.request: Internal Server Error: /accounts/profile/
Traceback (most recent call last):
  File "/usr/local/lib/python3.10/site-packages/asgiref/sync.py", line 472, in thread_handler
    raise exc_info[1]
  File "/usr/local/lib/python3.10/site-packages/django/core/handlers/exception.py", line 42, in inner
    response = await get_response(request)
  File "/usr/local/lib/python3.10/site-packages/django/core/handlers/base.py", line 253, in _get_response_async
    response = await wrapped_callback(
  File "/usr/local/lib/python3.10/site-packages/asgiref/sync.py", line 435, in __call__
    ret = await asyncio.wait_for(future, timeout=None)
  File "/usr/local/lib/python3.10/asyncio/tasks.py", line 408, in wait_for
    return await fut
  File "/usr/local/lib/python3.10/site-packages/asgiref/current_thread_executor.py", line 22, in run
    result = self.fn(*self.args, **self.kwargs)
  File "/usr/local/lib/python3.10/site-packages/asgiref/sync.py", line 476, in thread_handler
    return func(*args, **kwargs)
  File "/usr/local/lib/python3.10/site-packages/django/views/generic/base.py", line 103, in view
    return self.dispatch(request, *args, **kwargs)
  File "/usr/local/lib/python3.10/site-packages/django/views/generic/base.py", line 142, in dispatch
    return handler(request, *args, **kwargs)
  File "/usr/src/app/apps/users/views.py", line 26, in get
    "change_user_form": ChangeUserForm(self.request),
  File "/usr/src/app/apps/users/forms.py", line 137, in __init__
    if (form_errors:=request.sessions.get("auth_form_errors")) is not None:
AttributeError: 'ASGIRequest' object has no attribute 'sessions'
2023-01-05 06:53:21,960 - [ERROR]    django.channels.server: [35;1mHTTP GET /accounts/profile/ 500 [0.92, 172.20.0.1:49882][0m
2023-01-05 06:54:35,670 - [INFO]    django.utils.autoreload: /usr/src/app/apps/users/forms.py changed, reloading.
2023-01-05 06:54:39,667 - [INFO]    django.utils.autoreload: Watching for file changes with StatReloader
2023-01-05 06:54:47,986 - [INFO]    django.channels.server: [mHTTP GET /accounts/profile/ 200 [4.03, 172.20.0.1:45596][0m
2023-01-05 06:55:09,010 - [INFO]    django.channels.server: [mHTTP GET /accounts/profile/ 200 [0.29, 172.20.0.1:55348][0m
2023-01-05 06:55:19,608 - [INFO]    django.channels.server: [mHTTP GET /accounts/profile/ 200 [0.31, 172.20.0.1:57042][0m
2023-01-05 06:55:55,519 - [INFO]    django.channels.server: [mHTTP GET /accounts/profile/ 200 [0.30, 172.20.0.1:37676][0m
2023-01-05 06:56:02,051 - [ERROR]    django.request: Internal Server Error: /accounts/change-user/
Traceback (most recent call last):
  File "/usr/local/lib/python3.10/site-packages/asgiref/sync.py", line 472, in thread_handler
    raise exc_info[1]
  File "/usr/local/lib/python3.10/site-packages/django/core/handlers/exception.py", line 42, in inner
    response = await get_response(request)
  File "/usr/local/lib/python3.10/site-packages/django/core/handlers/base.py", line 253, in _get_response_async
    response = await wrapped_callback(
  File "/usr/local/lib/python3.10/site-packages/asgiref/sync.py", line 435, in __call__
    ret = await asyncio.wait_for(future, timeout=None)
  File "/usr/local/lib/python3.10/asyncio/tasks.py", line 408, in wait_for
    return await fut
  File "/usr/local/lib/python3.10/site-packages/asgiref/current_thread_executor.py", line 22, in run
    result = self.fn(*self.args, **self.kwargs)
  File "/usr/local/lib/python3.10/site-packages/asgiref/sync.py", line 476, in thread_handler
    return func(*args, **kwargs)
  File "/usr/local/lib/python3.10/site-packages/django/views/generic/base.py", line 103, in view
    return self.dispatch(request, *args, **kwargs)
  File "/usr/local/lib/python3.10/site-packages/django/contrib/auth/mixins.py", line 73, in dispatch
    return super().dispatch(request, *args, **kwargs)
  File "/usr/local/lib/python3.10/site-packages/django/views/generic/base.py", line 142, in dispatch
    return handler(request, *args, **kwargs)
  File "/usr/src/app/apps/users/views.py", line 147, in post
    self.request.sessions["auth_form_errors"] = form_data.errors
AttributeError: 'ASGIRequest' object has no attribute 'sessions'
2023-01-05 06:56:02,284 - [ERROR]    django.channels.server: [35;1mHTTP POST /accounts/change-user/ 500 [0.34, 172.20.0.1:45146][0m
2023-01-05 06:58:05,528 - [INFO]    django.utils.autoreload: /usr/src/app/apps/users/forms.py changed, reloading.
2023-01-05 06:58:33,687 - [INFO]    django.utils.autoreload: Watching for file changes with StatReloader
2023-01-05 06:58:52,051 - [INFO]    django.channels.server: [32mHTTP POST /accounts/change-user/ 302 [0.55, 172.20.0.1:40078][0m
2023-01-05 06:58:52,211 - [ERROR]    django.request: Internal Server Error: /accounts/profile/
Traceback (most recent call last):
  File "/usr/local/lib/python3.10/site-packages/asgiref/sync.py", line 472, in thread_handler
    raise exc_info[1]
  File "/usr/local/lib/python3.10/site-packages/django/core/handlers/exception.py", line 42, in inner
    response = await get_response(request)
  File "/usr/local/lib/python3.10/site-packages/django/core/handlers/base.py", line 253, in _get_response_async
    response = await wrapped_callback(
  File "/usr/local/lib/python3.10/site-packages/asgiref/sync.py", line 435, in __call__
    ret = await asyncio.wait_for(future, timeout=None)
  File "/usr/local/lib/python3.10/asyncio/tasks.py", line 408, in wait_for
    return await fut
  File "/usr/local/lib/python3.10/site-packages/asgiref/current_thread_executor.py", line 22, in run
    result = self.fn(*self.args, **self.kwargs)
  File "/usr/local/lib/python3.10/site-packages/asgiref/sync.py", line 476, in thread_handler
    return func(*args, **kwargs)
  File "/usr/local/lib/python3.10/site-packages/django/views/generic/base.py", line 103, in view
    return self.dispatch(request, *args, **kwargs)
  File "/usr/local/lib/python3.10/site-packages/django/views/generic/base.py", line 142, in dispatch
    return handler(request, *args, **kwargs)
  File "/usr/src/app/apps/users/views.py", line 26, in get
    "change_user_form": ChangeUserForm(self.request),
  File "/usr/src/app/apps/users/forms.py", line 138, in __init__
    self.add_error(**form_errors)
TypeError: BaseForm.add_error() missing 2 required positional arguments: 'field' and 'error'
2023-01-05 06:58:52,514 - [ERROR]    django.channels.server: [35;1mHTTP GET /accounts/profile/ 500 [0.38, 172.20.0.1:40090][0m
2023-01-05 06:59:15,511 - [INFO]    django.utils.autoreload: /usr/src/app/apps/users/forms.py changed, reloading.
2023-01-05 06:59:18,530 - [INFO]    django.utils.autoreload: Watching for file changes with StatReloader
2023-01-05 06:59:22,169 - [ERROR]    django.request: Internal Server Error: /accounts/profile/
Traceback (most recent call last):
  File "/usr/local/lib/python3.10/site-packages/asgiref/sync.py", line 472, in thread_handler
    raise exc_info[1]
  File "/usr/local/lib/python3.10/site-packages/django/core/handlers/exception.py", line 42, in inner
    response = await get_response(request)
  File "/usr/local/lib/python3.10/site-packages/django/core/handlers/base.py", line 253, in _get_response_async
    response = await wrapped_callback(
  File "/usr/local/lib/python3.10/site-packages/asgiref/sync.py", line 435, in __call__
    ret = await asyncio.wait_for(future, timeout=None)
  File "/usr/local/lib/python3.10/asyncio/tasks.py", line 408, in wait_for
    return await fut
  File "/usr/local/lib/python3.10/site-packages/asgiref/current_thread_executor.py", line 22, in run
    result = self.fn(*self.args, **self.kwargs)
  File "/usr/local/lib/python3.10/site-packages/asgiref/sync.py", line 476, in thread_handler
    return func(*args, **kwargs)
  File "/usr/local/lib/python3.10/site-packages/django/views/generic/base.py", line 103, in view
    return self.dispatch(request, *args, **kwargs)
  File "/usr/local/lib/python3.10/site-packages/django/views/generic/base.py", line 142, in dispatch
    return handler(request, *args, **kwargs)
  File "/usr/src/app/apps/users/views.py", line 26, in get
    "change_user_form": ChangeUserForm(self.request),
  File "/usr/src/app/apps/users/forms.py", line 139, in __init__
    self.add_error(**form_errors)
TypeError: BaseForm.add_error() missing 2 required positional arguments: 'field' and 'error'
2023-01-05 06:59:22,508 - [ERROR]    django.channels.server: [35;1mHTTP GET /accounts/profile/ 500 [1.16, 172.20.0.1:40260][0m
2023-01-05 07:00:39,370 - [INFO]    django.utils.autoreload: /usr/src/app/apps/users/forms.py changed, reloading.
2023-01-05 07:00:42,028 - [INFO]    django.utils.autoreload: Watching for file changes with StatReloader
2023-01-05 07:00:54,887 - [ERROR]    django.request: Internal Server Error: /accounts/profile/
Traceback (most recent call last):
  File "/usr/local/lib/python3.10/site-packages/asgiref/sync.py", line 472, in thread_handler
    raise exc_info[1]
  File "/usr/local/lib/python3.10/site-packages/django/core/handlers/exception.py", line 42, in inner
    response = await get_response(request)
  File "/usr/local/lib/python3.10/site-packages/django/core/handlers/base.py", line 253, in _get_response_async
    response = await wrapped_callback(
  File "/usr/local/lib/python3.10/site-packages/asgiref/sync.py", line 435, in __call__
    ret = await asyncio.wait_for(future, timeout=None)
  File "/usr/local/lib/python3.10/asyncio/tasks.py", line 408, in wait_for
    return await fut
  File "/usr/local/lib/python3.10/site-packages/asgiref/current_thread_executor.py", line 22, in run
    result = self.fn(*self.args, **self.kwargs)
  File "/usr/local/lib/python3.10/site-packages/asgiref/sync.py", line 476, in thread_handler
    return func(*args, **kwargs)
  File "/usr/local/lib/python3.10/site-packages/django/views/generic/base.py", line 103, in view
    return self.dispatch(request, *args, **kwargs)
  File "/usr/local/lib/python3.10/site-packages/django/views/generic/base.py", line 142, in dispatch
    return handler(request, *args, **kwargs)
  File "/usr/src/app/apps/users/views.py", line 26, in get
    "change_user_form": ChangeUserForm(self.request),
  File "/usr/src/app/apps/users/forms.py", line 139, in __init__
    self.add_error(**form_errors)
TypeError: BaseForm.add_error() missing 2 required positional arguments: 'field' and 'error'
2023-01-05 07:00:55,142 - [ERROR]    django.channels.server: [35;1mHTTP GET /accounts/profile/ 500 [0.76, 172.20.0.1:54126][0m
2023-01-05 07:01:15,066 - [INFO]    django.utils.autoreload: /usr/src/app/apps/users/forms.py changed, reloading.
2023-01-05 07:01:17,878 - [INFO]    django.utils.autoreload: Watching for file changes with StatReloader
2023-01-05 07:01:20,841 - [ERROR]    django.request: Internal Server Error: /accounts/profile/
Traceback (most recent call last):
  File "/usr/local/lib/python3.10/site-packages/asgiref/sync.py", line 472, in thread_handler
    raise exc_info[1]
  File "/usr/local/lib/python3.10/site-packages/django/core/handlers/exception.py", line 42, in inner
    response = await get_response(request)
  File "/usr/local/lib/python3.10/site-packages/django/core/handlers/base.py", line 253, in _get_response_async
    response = await wrapped_callback(
  File "/usr/local/lib/python3.10/site-packages/asgiref/sync.py", line 435, in __call__
    ret = await asyncio.wait_for(future, timeout=None)
  File "/usr/local/lib/python3.10/asyncio/tasks.py", line 408, in wait_for
    return await fut
  File "/usr/local/lib/python3.10/site-packages/asgiref/current_thread_executor.py", line 22, in run
    result = self.fn(*self.args, **self.kwargs)
  File "/usr/local/lib/python3.10/site-packages/asgiref/sync.py", line 476, in thread_handler
    return func(*args, **kwargs)
  File "/usr/local/lib/python3.10/site-packages/django/views/generic/base.py", line 103, in view
    return self.dispatch(request, *args, **kwargs)
  File "/usr/local/lib/python3.10/site-packages/django/views/generic/base.py", line 142, in dispatch
    return handler(request, *args, **kwargs)
  File "/usr/src/app/apps/users/views.py", line 26, in get
    "change_user_form": ChangeUserForm(self.request),
  File "/usr/src/app/apps/users/forms.py", line 139, in __init__
    self.add_error(**form_errors)
TypeError: BaseForm.add_error() missing 2 required positional arguments: 'field' and 'error'
2023-01-05 07:01:21,209 - [ERROR]    django.channels.server: [35;1mHTTP GET /accounts/profile/ 500 [0.73, 172.20.0.1:60080][0m
2023-01-05 07:03:19,461 - [INFO]    django.utils.autoreload: /usr/src/app/apps/users/forms.py changed, reloading.
2023-01-05 07:03:22,097 - [INFO]    django.utils.autoreload: Watching for file changes with StatReloader
2023-01-05 07:03:28,354 - [INFO]    django.channels.server: [mHTTP GET /accounts/profile/ 200 [0.76, 172.20.0.1:56138][0m
2023-01-05 07:03:37,820 - [INFO]    django.channels.server: [32mHTTP POST /accounts/change-user/ 302 [0.29, 172.20.0.1:36450][0m
2023-01-05 07:03:38,209 - [INFO]    django.channels.server: [mHTTP GET /accounts/profile/ 200 [0.36, 172.20.0.1:36460][0m
2023-01-05 07:03:47,177 - [INFO]    django.channels.server: [32mHTTP POST /accounts/change-user/ 302 [0.30, 172.20.0.1:47558][0m
2023-01-05 07:03:47,501 - [INFO]    django.channels.server: [mHTTP GET /accounts/profile/ 200 [0.30, 172.20.0.1:47564][0m
2023-01-05 07:04:03,195 - [INFO]    django.utils.autoreload: /usr/src/app/apps/users/forms.py changed, reloading.
2023-01-05 07:04:07,986 - [INFO]    django.utils.autoreload: Watching for file changes with StatReloader
2023-01-05 07:04:11,252 - [INFO]    django.channels.server: [mHTTP GET /accounts/profile/ 200 [0.65, 172.20.0.1:42298][0m
2023-01-05 07:04:18,801 - [INFO]    django.channels.server: [32mHTTP POST /accounts/change-user/ 302 [0.35, 172.20.0.1:42310][0m
2023-01-05 07:04:19,144 - [INFO]    django.channels.server: [mHTTP GET /accounts/profile/ 200 [0.31, 172.20.0.1:42314][0m
2023-01-05 07:04:49,553 - [INFO]    django.utils.autoreload: /usr/src/app/apps/users/views.py changed, reloading.
2023-01-05 07:04:52,244 - [INFO]    django.utils.autoreload: Watching for file changes with StatReloader
2023-01-05 07:04:57,809 - [INFO]    django.channels.server: [32mHTTP POST /accounts/change-user/ 302 [1.47, 172.20.0.1:46216][0m
2023-01-05 07:04:58,369 - [INFO]    django.channels.server: [mHTTP GET /accounts/profile/ 200 [0.52, 172.20.0.1:46218][0m
2023-01-05 07:53:08,518 - [INFO]    django.channels.server: [32mHTTP POST /accounts/change-user/ 302 [0.47, 172.20.0.1:38318][0m
2023-01-05 07:53:08,852 - [INFO]    django.channels.server: [mHTTP GET /accounts/profile/ 200 [0.29, 172.20.0.1:38326][0m
2023-01-05 07:54:26,585 - [INFO]    django.utils.autoreload: /usr/src/app/apps/users/views.py changed, reloading.
2023-01-05 07:54:29,054 - [INFO]    django.utils.autoreload: Watching for file changes with StatReloader
2023-01-05 07:54:46,201 - [INFO]    django.channels.server: [32mHTTP POST /accounts/change-user/ 302 [0.82, 172.20.0.1:55320][0m
2023-01-05 07:54:46,802 - [INFO]    django.channels.server: [mHTTP GET /accounts/profile/ 200 [0.57, 172.20.0.1:55324][0m
2023-01-05 07:55:25,125 - [INFO]    django.utils.autoreload: /usr/src/app/apps/users/views.py changed, reloading.
2023-01-05 07:55:27,408 - [INFO]    django.utils.autoreload: Watching for file changes with StatReloader
2023-01-05 07:55:37,429 - [INFO]    django.channels.server: [32mHTTP POST /accounts/change-user/ 302 [0.56, 172.20.0.1:36206][0m
2023-01-05 07:55:37,888 - [INFO]    django.channels.server: [mHTTP GET /accounts/profile/ 200 [0.43, 172.20.0.1:36218][0m
2023-01-05 07:56:22,281 - [INFO]    django.utils.autoreload: /usr/src/app/apps/users/views.py changed, reloading.
2023-01-05 07:56:24,876 - [INFO]    django.utils.autoreload: Watching for file changes with StatReloader
2023-01-05 07:56:29,670 - [INFO]    django.channels.server: [32mHTTP POST /accounts/change-user/ 302 [0.65, 172.20.0.1:33950][0m
2023-01-05 07:56:30,213 - [INFO]    django.channels.server: [mHTTP GET /accounts/profile/ 200 [0.51, 172.20.0.1:33960][0m
2023-01-05 07:56:47,141 - [INFO]    django.utils.autoreload: /usr/src/app/apps/users/views.py changed, reloading.
2023-01-05 07:56:49,661 - [INFO]    django.utils.autoreload: Watching for file changes with StatReloader
2023-01-05 07:56:54,546 - [INFO]    django.channels.server: [32mHTTP POST /accounts/change-user/ 302 [0.60, 172.20.0.1:58368][0m
2023-01-05 07:56:55,058 - [INFO]    django.channels.server: [mHTTP GET /accounts/profile/ 200 [0.48, 172.20.0.1:58380][0m
2023-01-05 07:59:04,690 - [INFO]    django.utils.autoreload: /usr/src/app/apps/users/views.py changed, reloading.
2023-01-05 07:59:07,269 - [INFO]    django.utils.autoreload: Watching for file changes with StatReloader
2023-01-05 07:59:11,514 - [INFO]    django.channels.server: [32mHTTP POST /accounts/change-user/ 302 [0.71, 172.20.0.1:51552][0m
2023-01-05 07:59:12,000 - [INFO]    django.channels.server: [mHTTP GET /accounts/profile/ 200 [0.45, 172.20.0.1:51568][0m
2023-01-05 07:59:29,127 - [INFO]    django.utils.autoreload: /usr/src/app/apps/users/forms.py changed, reloading.
2023-01-05 07:59:31,930 - [INFO]    django.utils.autoreload: Watching for file changes with StatReloader
2023-01-05 07:59:38,413 - [INFO]    django.channels.server: [32mHTTP POST /accounts/change-user/ 302 [0.64, 172.20.0.1:45426][0m
2023-01-05 07:59:38,986 - [INFO]    django.channels.server: [mHTTP GET /accounts/profile/ 200 [0.54, 172.20.0.1:45430][0m
2023-01-05 07:59:52,765 - [INFO]    django.utils.autoreload: /usr/src/app/apps/users/forms.py changed, reloading.
2023-01-05 07:59:55,128 - [INFO]    django.utils.autoreload: Watching for file changes with StatReloader
2023-01-05 07:59:59,563 - [INFO]    django.utils.autoreload: /usr/src/app/apps/users/forms.py changed, reloading.
2023-01-05 08:00:02,087 - [INFO]    django.utils.autoreload: Watching for file changes with StatReloader
2023-01-05 08:00:08,293 - [INFO]    django.channels.server: [32mHTTP POST /accounts/change-user/ 302 [0.67, 172.20.0.1:42552][0m
2023-01-05 08:00:08,799 - [INFO]    django.channels.server: [mHTTP GET /accounts/profile/ 200 [0.47, 172.20.0.1:42562][0m
2023-01-05 08:00:21,277 - [INFO]    django.utils.autoreload: /usr/src/app/apps/users/forms.py changed, reloading.
2023-01-05 08:00:24,071 - [INFO]    django.utils.autoreload: Watching for file changes with StatReloader
2023-01-05 08:04:48,070 - [INFO]    django.channels.server: [32mHTTP POST /accounts/change-user/ 302 [0.59, 172.20.0.1:47116][0m
2023-01-05 08:04:48,629 - [INFO]    django.channels.server: [mHTTP GET /accounts/profile/ 200 [0.52, 172.20.0.1:47120][0m
2023-01-05 08:05:06,812 - [INFO]    django.utils.autoreload: /usr/src/app/apps/users/forms.py changed, reloading.
2023-01-05 08:05:14,786 - [INFO]    django.utils.autoreload: Watching for file changes with StatReloader
2023-01-05 08:05:23,406 - [INFO]    django.channels.server: [32mHTTP POST /accounts/change-user/ 302 [0.66, 172.20.0.1:37194][0m
2023-01-05 08:05:23,930 - [INFO]    django.channels.server: [mHTTP GET /accounts/profile/ 200 [0.45, 172.20.0.1:37206][0m
2023-01-05 08:05:45,193 - [INFO]    django.utils.autoreload: /usr/src/app/apps/users/forms.py changed, reloading.
2023-01-05 08:05:47,889 - [INFO]    django.utils.autoreload: Watching for file changes with StatReloader
2023-01-05 08:05:51,161 - [INFO]    django.channels.server: [32mHTTP POST /accounts/change-user/ 302 [0.89, 172.20.0.1:48852][0m
2023-01-05 08:05:51,691 - [INFO]    django.channels.server: [mHTTP GET /accounts/profile/ 200 [0.50, 172.20.0.1:48854][0m
2023-01-05 08:06:55,734 - [INFO]    django.utils.autoreload: /usr/src/app/apps/users/views.py changed, reloading.
2023-01-05 08:06:58,527 - [INFO]    django.utils.autoreload: Watching for file changes with StatReloader
2023-01-05 08:07:03,306 - [INFO]    django.channels.server: [32mHTTP POST /accounts/change-user/ 302 [0.82, 172.20.0.1:46024][0m
2023-01-05 08:07:03,780 - [INFO]    django.channels.server: [mHTTP GET /accounts/profile/ 200 [0.44, 172.20.0.1:46026][0m
